Workbook

Sheet Dashboard
A1: 🏦 SAMCIOUS MICROFINANCE MANAGEMENT SYSTEM | I1: [ LOGO ]
A2: 👤 ACTIVE ROLE: | D2: Manager | F2: 🔄 SYNC STATUS: | I2: ⚠ NOT SYNCHRONIZED — Click SYNC | K2: 🔄 SYNCHRONIZE
A3: ➕ ADD MEMBER | B3: 💰 SAVINGS | C3: 🏦 LOANS | D3: 📊 REPORTS | E3: 🔍 SEARCH | F3: ⚙ SETTINGS | G3: 📱 SMS ALERTS | H3: 🔒 LOCK SYSTEM
A4: Total Members | B4: Total Savings (GHS) | C4: Loans Disbursed (GHS) | D4: Loan Repayments (GHS) | E4: Money at Hand (GHS) | F4: Pending Loans
A5: =Config!B2 -> Value | B5: =Config!B3 -> -995 | C5: =Config!B4 -> 0 | D5: =Config!B5 -> 0 | E5: =Config!B6 -> 0 | F5: =Config!B7 -> -995
A7: 📋 RECENT TRANSACTIONS (Last 10)
A8: Date | B8: Member Name | C8: Account No | D8: Transaction | E8: Amount (GHS) | F8: Balance (GHS) | G8: Agent | H8: Status | I8: Ref No | J8: Notes
A20: 👥 AGENT PERFORMANCE SUMMARY
A21: Agent | B21: Agent Code | C21: Members Registered | D21: Total Savings (GHS) | E21: Loans Given (GHS) | F21: Repayments (GHS) | G21: Money at Hand (GHS) | H21: Status
A22: Agent 1
A23: Agent 2
A24: Agent 3
A25: Agent 4
A26: Agent 5

Sheet Members
A1: 👥 MEMBERS REGISTRY — SAMCIOUS MICROFINANCE
A2: 🔍 SEARCH: | D2: Search by Account No or Phone Number — results highlight below | G2: ➕ ADD MEMBER | I2: 📤 EXPORT MEMBERS
A3: Account Number | B3: Full Name | C3: Phone Number | D3: ID Type | E3: ID Number | F3: Date Joined | G3: Agent Assigned | H3: KYC Status | I3: Savings Balance (GHS) | J3: Loan Balance (GHS) | K3: Total Interest Paid (GHS) | L3: Notes
A4: 1234567854

Sheet Transactions
A1: 💳 TRANSACTIONS LOG — SAVINGS & LOAN REPAYMENTS
A2: 📅 Date From: | D2: 📅 Date To: | G2: 👤 Member: | J2: 📂 Type:
A3: Ref No | B3: Date | C3: Member Name | D3: Account No | E3: Trans Type | F3: Amount (GHS) | G3: Running Balance (GHS) | H3: Agent | I3: Auth Code | J3: SMS Sent? | K3: Notes | L3: Approved By

Sheet Loans
A1: 🏦 LOAN REGISTER — DISBURSEMENTS & REPAYMENT SCHEDULE
A2: 🔍 Search Loan: | D2: 📅 Date: | G2: 👤 Member: | J2: 📂 Status:
A3: Loan ID | B3: Member Name | C3: Account No | D3: Date Issued | E3: Loan Amount (GHS) | F3: Processing Fee (GHS) | G3: Net Amount Credited (GHS) | H3: Interest Rate (%) | I3: Monthly Installment (GHS) | J3: Total Repaid (GHS) | K3: Outstanding Balance (GHS) | L3: Loan Status
I4: =IF(E4=0,"",IFERROR(-PMT(H4/100/12,12,-E4),E4/12)) | K4: =IF(E4=0,"",MAX(0,E4-J4))
I5: =IF(E5=0,"",IFERROR(-PMT(H5/100/12,12,-E5),E5/12)) | K5: =IF(E5=0,"",MAX(0,E5-J5))
I6: =IF(E6=0,"",IFERROR(-PMT(H6/100/12,12,-E6),E6/12)) | K6: =IF(E6=0,"",MAX(0,E6-J6))
I7: =IF(E7=0,"",IFERROR(-PMT(H7/100/12,12,-E7),E7/12)) | K7: =IF(E7=0,"",MAX(0,E7-J7))
I8: =IF(E8=0,"",IFERROR(-PMT(H8/100/12,12,-E8),E8/12)) | K8: =IF(E8=0,"",MAX(0,E8-J8))
I9: =IF(E9=0,"",IFERROR(-PMT(H9/100/12,12,-E9),E9/12)) | K9: =IF(E9=0,"",MAX(0,E9-J9))
I10: =IF(E10=0,"",IFERROR(-PMT(H10/100/12,12,-E10),E10/12)) | K10: =IF(E10=0,"",MAX(0,E10-J10))
I11: =IF(E11=0,"",IFERROR(-PMT(H11/100/12,12,-E11),E11/12)) | K11: =IF(E11=0,"",MAX(0,E11-J11))
I12: =IF(E12=0,"",IFERROR(-PMT(H12/100/12,12,-E12),E12/12)) | K12: =IF(E12=0,"",MAX(0,E12-J12))
I13: =IF(E13=0,"",IFERROR(-PMT(H13/100/12,12,-E13),E13/12)) | K13: =IF(E13=0,"",MAX(0,E13-J13))
I14: =IF(E14=0,"",IFERROR(-PMT(H14/100/12,12,-E14),E14/12)) | K14: =IF(E14=0,"",MAX(0,E14-J14))
I15: =IF(E15=0,"",IFERROR(-PMT(H15/100/12,12,-E15),E15/12)) | K15: =IF(E15=0,"",MAX(0,E15-J15))
... I53: =IF(E53=0,"",IFERROR(-PMT(H53/100/12,12,-E53),E53/12)) | K53: =IF(E53=0,"",MAX(0,E53-J53))

Sheet Pending_Loans
A1: ⏳ PENDING LOAN REQUESTS — MANAGER APPROVAL QUEUE
A2: 📊 Total Pending: | D2: 💰 Total Amount: | G2: 📅 As of Date: | J2: 👤 Manager:
A3: Request ID | B3: Member Name | C3: Account No | D3: Request Date | E3: Agent | F3: Requested Amount (GHS) | G3: Purpose | H3: Processing Fee (GHS) | I3: Net to Credit (GHS) | J3: Decision | K3: Decision Date | L3: Manager Notes
I4: =IF(F4=0,"",MAX(0,F4-H4))
I5: =IF(F5=0,"",MAX(0,F5-H5))
I6: =IF(F6=0,"",MAX(0,F6-H6))
I7: =IF(F7=0,"",MAX(0,F7-H7))
I8: =IF(F8=0,"",MAX(0,F8-H8))
I9: =IF(F9=0,"",MAX(0,F9-H9))
I10: =IF(F10=0,"",MAX(0,F10-H10))
I11: =IF(F11=0,"",MAX(0,F11-H11))
I12: =IF(F12=0,"",MAX(0,F12-H12))
I13: =IF(F13=0,"",MAX(0,F13-H13))
I14: =IF(F14=0,"",MAX(0,F14-H14))
I15: =IF(F15=0,"",MAX(0,F15-H15))
... I33: =IF(F33=0,"",MAX(0,F33-H33))

Sheet Reports
A1: 📊 REPORTS & ANALYTICS — SAMCIOUS MICROFINANCE
A2: 📅 Report Year: | C2: 2025 | D2: 📥 Download Report | F2: 🖨 Print Report
A4: 📋 MONTHLY SUMMARY
A5: Month | B5: Members Added | C5: Total Deposits (GHS) | D5: Total Loans (GHS) | E5: Repayments (GHS) | F5: Interest Earned (GHS) | G5: Money at Hand (GHS) | H5: Net Position (GHS)
A6: January
A7: February
A8: March
A9: April
A10: May
A11: June
A12: July
A13: August
A14: September
A15: October
A16: November
A17: December

Sheet Local_Cache
A1: ⚡ LOCAL CACHE — OFFLINE STORAGE (SYSTEM USE ONLY)
A2: Cache ID | B2: Timestamp | C2: Sheet Target | D2: Operation | E2: Data Payload | F2: Sync Status | G2: Retry Count | H2: Error Message

Sheet Config
A1: ⚙ SYSTEM CONFIGURATION — DO NOT MODIFY MANUALLY
A2: Setting | B2: Value | C2: Last Updated | D2: Notes
A3: Total Members | B3: =COUNTA(Members!A4:A1000)-COUNTIF(Members!A4:A1000,"") -> -995 | C3: =NOW() -> 46122.471 | D3: Auto-counted
A4: Total Savings | B4: =SUMIF(Transactions!E4:E1000,"Savings Deposit",Transactions!F4:F1000) -> 0 | C4: =NOW() -> 46122.471 | D4: Auto-summed
A5: Loans Disbursed | B5: =SUMIF(Transactions!E4:E1000,"Loan Disbursement",Transactions!F4:F1000) -> 0 | C5: =NOW() -> 46122.471 | D5: Auto-summed
A6: Loan Repayments | B6: =SUMIF(Transactions!E4:E1000,"Loan Repayment",Transactions!F4:F1000) -> 0 | C6: =NOW() -> 46122.471 | D6: Auto-summed
A7: Money at Hand | B7: =B3+B5-B4 -> -995 | C7: =NOW() -> 46122.471 | D7: (Savings+Repayments)-Loans
A8: Pending Loans | B8: =COUNTIF(Pending_Loans!J4:J33,"Pending") -> 0 | C8: =NOW() -> 46122.471 | D8: Auto-counted
A9: Last Sync Date | D9: Set by VBA on sync
A10: System Version | B10: 1.0.0 | C10: 2025-01-01 | D10: SAMCIOUS MFI v1
A11: Master File Path | D11: Set during setup
A12: SMS API Key | D12: Hubtel/Twilio key
A13: SMS Sender ID | B13: SAMCIOUS | D13: SMS sender name
A14: Currency | B14: GHS | D14: Ghana Cedis
A15: Interest Base Rate | B15: 20% | D15: Default annual rate
A16: Max Loan Multiple | B16: 5 | D16: Max loan = 5x savings
A17: Processing Fee % | B17: 2% | D17: Default processing fee
A18: System Locked | B18: FALSE | D18: TRUE when not synced
A19: Active Manager | B19: Manager | C19: =NOW() -> 46122.471 | D19: Current logged-in user
A20: Organization | B20: SAMCIOUS MICROFINANCE | D20: Org name
A21: Ghana Branch | B21: Main Branch | D21: Branch identifier

Sheet VBA_Modules
A1: 📝 VBA MODULES — Paste into Excel VBA Editor (Alt+F11)
A3: 📦 MODULE: ThisWorkbook
C4: ' ═══════════════════════════════════════════════════════════════
C5: ' MODULE: ThisWorkbook
C6: ' Paste into: ThisWorkbook object in VBA editor
C7: ' ═══════════════════════════════════════════════════════════════
C9: Option Explicit
C11: Private Sub Workbook_Open()
C12: ' ── Check synchronization status on open ──────────────────
C13: Dim lastSync As String
C14: lastSync = Sheets("Config").Range("B8").Value
C16: If lastSync = "" Or CDate(lastSync) < Date Then
C17: ' Lock system
C18: Sheets("Config").Range("B17").Value = "TRUE"
... C38: End Sub
A39: 📦 MODULE: Module1_Auth
C40: ' ═══════════════════════════════════════════════════════════════
C41: ' MODULE: Module1_Auth
C42: ' Insert as: Standard Module named "Module1_Auth"
C43: ' ═══════════════════════════════════════════════════════════════
C45: Option Explicit
C47: ' ── System Lock / Unlock ─────────────────────────────────────
C48: Sub LockSystem()
C49: Dim ws As Worksheet
C50: For Each ws In ThisWorkbook.Worksheets
C51: If ws.Name <> "Dashboard" And ws.Name <> "VBA_Modules" Then
C52: ws.Protect Password:="SAMCIOUS_LOCK", UserInterfaceOnly:=True
C53: End If
... C125: End Function
A126: 📦 MODULE: Module2_Members
C127: ' ═══════════════════════════════════════════════════════════════
C128: ' MODULE: Module2_Members
C129: ' KYC Registration + Account Number Generation
C130: ' ═══════════════════════════════════════════════════════════════
C132: Option Explicit
C134: ' ── Open KYC Form ────────────────────────────────────────────
C135: Sub OpenKYCForm()
C136: Dim frm As New frmKYC
C137: frm.Show
C138: End Sub
...

Sheet Setup_Guide
A1: 🚀 SAMCIOUS MICROFINANCE — SETUP & DEPLOYMENT GUIDE
A2: Follow these steps in order to fully activate the SAMCIOUS Microfinance System.
A3: # | B3: Step | C3: Instructions | D3: Priority
A4: 1 | B4: Save as .xlsm | C4: File > Save As > Excel Macro-Enabled Workbook (.xlsm) | Must be done FIRST | D4: Critical
A5: 2 | B5: Enable Macros | C5: When reopening, click 'Enable Macros' / 'Enable Content' in the security bar | D5: Critical
A6: 3 | B6: Open VBA Editor | C6: Press Alt+F11 to open the VBA editor | D6: Required
A7: 4 | B7: Create 6 Modules | C7: Insert > Module (×6). Name each: Module1_Auth, Module2_Members, Module3_Savings, Module4_Loans, Module5_Sync, Module6_SMS | D7: Required
A8: 5 | B8: Paste VBA Code | C8: Copy each MODULE's code from the VBA_Modules sheet and paste into the correct module | D8: Required
A9: 6 | B9: Create UserForms | C9: Insert > UserForm (×2). Name: frmKYC and frmManagerLogin. Add controls as described in the frmKYC_UserForm section | D9: Required
A10: 7 | B10: Paste Worksheet Events | C10: Right-click Dashboard tab > View Code > paste Worksheet events code | D10: Required
A11: 8 | B11: Set SMS API Keys | C11: In Module6_SMS, replace HUBTEL_CLIENT_ID and HUBTEL_SECRET with real credentials. Sign up free at hubtel.com (recommended for Ghana) | D11: For SMS
A12: 9 | B12: Set Master File Path | C12: In Config sheet (B10), enter the full path to your master/shared workbook. This enables sync across agent laptops | D12: For Sync
A13: 10 | B13: Configure Power Query | C13: Data > Get Data > From Workbook > select Master file > load Members, Transactions, Loans tables. Set 'Refresh on open'. | D13: For Sync
A14: 11 | B14: Assign Button Macros | C14: On Dashboard, right-click each button > Assign Macro > link to: OpenKYCForm, ProcessDeposit, OpenLoanForm, SynchronizeWithMaster | D14: Required
A15: 12 | B15: Set Manager Credentials | C15: In Config sheet rows 22-28, store Manager credentials (Username, DOB hash, Phone, Ghana Card, Password hash) for login validation | D15: Security
... A18: 15 | B18: Initial Sync | C18: Set Config B8 (Last Sync Date) to today's date, then click Synchronize | D18: Required
