Workbook

Sheet Manager_Dashboard
A1: 🏦 SAMICIOUS MICROFINANCE — MANAGER COMMAND CENTER
A2: =UPPER(TEXT(TODAY(),"DDDD, DD MMMM YYYY"))&" | Live data from centralized DB — All 10 agents unified" -> TUESDAY, 14 APRIL 2026 | Live data from centralized DB — All 10 agents unified
A4: 💰 Today Savings | C4: 🏧 Today Withdrawals | E4: 📈 Net Today | G4: 👥 Active Customers | I4: 🔔 Pending Loans | K4: 🏦 Loan Portfolio
A5: =Daily_Balancing!B14 -> 0 | C5: =Daily_Balancing!C14 -> 0 | E5: =Daily_Balancing!D14 -> 0 | G5: =COUNTIF(DB_Customers!K2:K500,"Active") -> 20 | I5: =COUNTIF(DB_Loans!K2:K500,"Pending") -> 3 | K5: =SUMIF(DB_Loans!K2:K500,"Approved",DB_Loans!E2:E500) -> 7000
A7: 📊 REAL-TIME AGENT PERFORMANCE — Linked to Centralized DB
A8: Agent | B8: Today Savings | C8: Today Withdrawals | D8: Net | E8: Transactions | F8: Target | G8: % of Target | H8: MTD Savings | I8: Active Cust.
A9: Agent 01 | B9: =Daily_Balancing!B4 -> 0 | C9: =Daily_Balancing!C4 -> 0 | D9: =B9-C9 -> 0 | E9: =Daily_Balancing!E4 -> 0 | F9: 5000 | G9: =IFERROR(B9/F9,0) -> 0 | H9: =SUMIF(DB_Savings!$G:$G,"Agent 01",DB_Savings!$F:$F) -> 1866.21 | I9: =COUNTIF(DB_Customers!$H:$H,"Agent 01") -> 2
A10: Agent 02 | B10: =Daily_Balancing!B5 -> 0 | C10: =Daily_Balancing!C5 -> 0 | D10: =B10-C10 -> 0 | E10: =Daily_Balancing!E5 -> 0 | F10: 5000 | G10: =IFERROR(B10/F10,0) -> 0 | H10: =SUMIF(DB_Savings!$G:$G,"Agent 02",DB_Savings!$F:$F) -> 3578.15 | I10: =COUNTIF(DB_Customers!$H:$H,"Agent 02") -> 2
A11: Agent 03 | B11: =Daily_Balancing!B6 -> 0 | C11: =Daily_Balancing!C6 -> 0 | D11: =B11-C11 -> 0 | E11: =Daily_Balancing!E6 -> 0 | F11: 5000 | G11: =IFERROR(B11/F11,0) -> 0 | H11: =SUMIF(DB_Savings!$G:$G,"Agent 03",DB_Savings!$F:$F) -> 2342.86 | I11: =COUNTIF(DB_Customers!$H:$H,"Agent 03") -> 2
A12: Agent 04 | B12: =Daily_Balancing!B7 -> 0 | C12: =Daily_Balancing!C7 -> 0 | D12: =B12-C12 -> 0 | E12: =Daily_Balancing!E7 -> 0 | F12: 5000 | G12: =IFERROR(B12/F12,0) -> 0 | H12: =SUMIF(DB_Savings!$G:$G,"Agent 04",DB_Savings!$F:$F) -> 3827.62 | I12: =COUNTIF(DB_Customers!$H:$H,"Agent 04") -> 2
A13: Agent 05 | B13: =Daily_Balancing!B8 -> 0 | C13: =Daily_Balancing!C8 -> 0 | D13: =B13-C13 -> 0 | E13: =Daily_Balancing!E8 -> 0 | F13: 5000 | G13: =IFERROR(B13/F13,0) -> 0 | H13: =SUMIF(DB_Savings!$G:$G,"Agent 05",DB_Savings!$F:$F) -> 3793.7 | I13: =COUNTIF(DB_Customers!$H:$H,"Agent 05") -> 2
A14: Agent 06 | B14: =Daily_Balancing!B9 -> 0 | C14: =Daily_Balancing!C9 -> 0 | D14: =B14-C14 -> 0 | E14: =Daily_Balancing!E9 -> 0 | F14: 5000 | G14: =IFERROR(B14/F14,0) -> 0 | H14: =SUMIF(DB_Savings!$G:$G,"Agent 06",DB_Savings!$F:$F) -> 3283.91 | I14: =COUNTIF(DB_Customers!$H:$H,"Agent 06") -> 2
A15: Agent 07 | B15: =Daily_Balancing!B10 -> 0 | C15: =Daily_Balancing!C10 -> 0 | D15: =B15-C15 -> 0 | E15: =Daily_Balancing!E10 -> 0 | F15: 5000 | G15: =IFERROR(B15/F15,0) -> 0 | H15: =SUMIF(DB_Savings!$G:$G,"Agent 07",DB_Savings!$F:$F) -> 2915.75 | I15: =COUNTIF(DB_Customers!$H:$H,"Agent 07") -> 2
A16: Agent 08 | B16: =Daily_Balancing!B11 -> 0 | C16: =Daily_Balancing!C11 -> 0 | D16: =B16-C16 -> 0 | E16: =Daily_Balancing!E11 -> 0 | F16: 5000 | G16: =IFERROR(B16/F16,0) -> 0 | H16: =SUMIF(DB_Savings!$G:$G,"Agent 08",DB_Savings!$F:$F) -> 1347.43 | I16: =COUNTIF(DB_Customers!$H:$H,"Agent 08") -> 2
A17: Agent 09 | B17: =Daily_Balancing!B12 -> 0 | C17: =Daily_Balancing!C12 -> 0 | D17: =B17-C17 -> 0 | E17: =Daily_Balancing!E12 -> 0 | F17: 5000 | G17: =IFERROR(B17/F17,0) -> 0 | H17: =SUMIF(DB_Savings!$G:$G,"Agent 09",DB_Savings!$F:$F) -> 3361.83 | I17: =COUNTIF(DB_Customers!$H:$H,"Agent 09") -> 2
A18: Agent 10 | B18: =Daily_Balancing!B13 -> 0 | C18: =Daily_Balancing!C13 -> 0 | D18: =B18-C18 -> 0 | E18: =Daily_Balancing!E13 -> 0 | F18: 5000 | G18: =IFERROR(B18/F18,0) -> 0 | H18: =SUMIF(DB_Savings!$G:$G,"Agent 10",DB_Savings!$F:$F) -> 3698.8 | I18: =COUNTIF(DB_Customers!$H:$H,"Agent 10") -> 2
A19: TOTALS | B19: =SUM(B9:B18) -> 0 | C19: =SUM(C9:C18) -> 0 | D19: =SUM(D9:D18) -> 0 | E19: =SUM(E9:E18) -> 0 | F19: =SUM(F9:F18) -> 50000 | G19: =IFERROR(B19/F19,0) -> 0 | H19: =SUM(H9:H18) -> 30016.26 | I19: =SUM(I9:I18) -> 20
A21: 📋 CUSTOMER & LOAN SUMMARY | G21: 🔗 NAVIGATION GUIDE • Account_Opening → Create new customers • Agent01-10_Savings → Record savings • Agent01-10_Withdrawals → Process withdrawals • Agent01-10_Loans → Submit loan requests • DB_Customers → Master customer database • DB_Savings / DB_Withdrawals / DB_Loans → Central records • Daily/Weekly/Monthly_Balancing → Reports
A22: Total Customers | D22: =COUNTA(DB_Customers!A2:A500) -> 22
A23: Total Savings Portfolio | D23: =SUM(DB_Customers!L2:L500) -> 30016.26
A24: Total Withdrawals | D24: =SUM(DB_Customers!M2:M500) -> 6859.27
A25: Pending KYC | D25: =COUNTIF(DB_Customers!K2:K500,"Pending") -> 0
A26: Pending Loan Requests | D26: =COUNTIF(DB_Loans!K2:K500,"Pending") -> 3
A27: Approved Loans | D27: =COUNTIF(DB_Loans!K2:K500,"Approved") -> 2

Sheet Account_Opening
A1: 👤 NEW CUSTOMER ACCOUNT OPENING
A2: SAMICIOUS MICROFINANCE | Fill all fields → Click GENERATE ACCOUNT
A3: ⚡ Account Number is auto-generated by the system. No manual entry required.
A5: * First Name:
A6: * Last Name:
A7: * ID Card Type: | C7: Ghana Card
A8: * ID Number: | C8: 718982195-0
A9: * Occupation:
A10: * Assign Agent:
A11: Opening Balance (GHC): | C11: 0
A13: ✅ GENERATED ACCOUNT NUMBER
A14: =IF(C5="","⬆ Complete the form above, then click GENERATE ACCOUNT","Account will be: SAM"&TEXT(TODAY(),"YYYY")&TEXT(TODAY(),"MM")&"XXXXX (click Generate)") -> ⬆ Complete the form above, then click GENERATE ACCOUNT
A16: 📌 HOW TO CREATE AN ACCOUNT:
A17: Step 1: | B17: Enter First Name, Last Name, ID Card Type, ID Number, Occupation, Agent
A18: Step 2: | B18: Click GENERATE ACCOUNT button (VBA macro: CreateNewAccount)
A19: Step 3: | B19: System auto-generates Account Number and saves to DB_Customers
A20: Step 4: | B20: Account is immediately available for Savings / Withdrawal / Loans
A22: 📋 RECENTLY CREATED ACCOUNTS (from DB_Customers)
A23: Account No | B23: Customer Name | C23: ID Type | D23: Agent | E23: Date Created
A24: SAM20240600020 | B24: Kwame Baffour | C24: Voter's ID | D24: Agent 10 | E24: 2024-06-20
A25: SAM20240600019 | B25: Yaa Opoku | C25: Ghana Card | D25: Agent 10 | E25: 2024-06-15
A26: SAM20240600018 | B26: Esi Quaye | C26: Voter's ID | D26: Agent 09 | E26: 2024-06-08
A27: SAM20240600017 | B27: Kwasi Adusei | C27: Ghana Card | D27: Agent 09 | E27: 2024-06-01
A28: SAM20240500016 | B28: Akua Bonsu | C28: Voter's ID | D28: Agent 08 | E28: 2024-05-25

Sheet Agent01_Savings
A1: 💰 SAMICIOUS MICROFINANCE — AGENT01 SAVINGS
A2: Agent: Agent 01 | Enter Account # → All fields auto-populate | Status auto-sets to "Saved"
A3: 💰 Total Collected Today | D3: 📊 Transactions Today | G3: 📅 Date | J3: 🎯 Daily Target
A4: 4000 | D4: =COUNTIFS(DB_Savings!$G:$G,"Agent 01",DB_Savings!$E:$E,TODAY()) -> 0 | G4: =TEXT(TODAY(),"DDDD, DD MMMM YYYY") -> Tuesday, 14 April 2026 | J4: 5000
A5: =IF(SUMIFS(DB_Savings!$F:$F,DB_Savings!$G:$G,"Agent 01",DB_Savings!$E:$E,TODAY())>=J4,"✅ DAILY TARGET ACHIEVED! Well done Agent 01!","⏳ Collection in progress — Keep going! Remaining: GHC "&TEXT(J4-SUMIFS(DB_Savings!$F:$F,DB_Savings!$G:$G,"Agent 01",DB_Savings!$E:$E,TODAY()),"#,##0.00")) -> ⏳ Collection in progress — Keep going! Remaining: GHC 5,000.00
A7: 📝 ENTRY FORM — Enter Account Number in column A. All other fields auto-populate. Enter Savings Amount in column E then Tab to complete.
A8: Account # | B8: Customer Name | C8: Current Balance | D8: Date | E8: Savings Amount | F8: New Balance | G8: Agent | H8: Status | I8: Saved At | J8: Notes
A9: SAM20240100001 | B9: =IF(A9="","",IFERROR(VLOOKUP(A9,DB_Customers!$A:$D,4,0),"❌ Account Not Found")) -> Kwame Asare | C9: =IF(A9="","",IFERROR(VLOOKUP(A9,DB_Customers!$A:$N,14,0),"")) -> 1078.82 | D9: =IF(A9="","",TODAY()) -> 46126 | E9: 283.3 | F9: =IF(OR(A9="",E9=""),"",IF(C9="","",C9+E9)) -> 1362.12 | G9: Agent 01 | H9: =IF(AND(A9<>"",E9<>"",G9<>""),"Saved","Pending") -> Saved | I9: =IF(H9="Saved",TEXT(TODAY(),"YYYY-MM-DD")&" Auto","—") -> 2026-04-14 Auto
A10: SAM20240100002 | B10: =IF(A10="","",IFERROR(VLOOKUP(A10,DB_Customers!$A:$D,4,0),"❌ Account Not Found")) -> Ama Mensah | C10: =IF(A10="","",IFERROR(VLOOKUP(A10,DB_Customers!$A:$N,14,0),"")) -> 1868.51 | D10: =IF(A10="","",TODAY()) -> 46126 | E10: 234.55 | F10: =IF(OR(A10="",E10=""),"",IF(C10="","",C10+E10)) -> 2103.06 | G10: Agent 01 | H10: =IF(AND(A10<>"",E10<>"",G10<>""),"Saved","Pending") -> Saved | I10: =IF(H10="Saved",TEXT(TODAY(),"YYYY-MM-DD")&" Auto","—") -> 2026-04-14 Auto
B11: =IF(A11="","",IFERROR(VLOOKUP(A11,DB_Customers!$A:$D,4,0),"❌ Account Not Found")) | C11: =IF(A11="","",IFERROR(VLOOKUP(A11,DB_Customers!$A:$N,14,0),"")) | D11: =IF(A11="","",TODAY()) | F11: =IF(OR(A11="",E11=""),"",IF(C11="","",C11+E11)) | G11: Agent 01 | H11: =IF(AND(A11<>"",E11<>"",G11<>""),"Saved","Pending") -> Pending | I11: =IF(H11="Saved",TEXT(TODAY(),"YYYY-MM-DD")&" Auto","—") -> —
B12: =IF(A12="","",IFERROR(VLOOKUP(A12,DB_Customers!$A:$D,4,0),"❌ Account Not Found")) | C12: =IF(A12="","",IFERROR(VLOOKUP(A12,DB_Customers!$A:$N,14,0),"")) | D12: =IF(A12="","",TODAY()) | F12: =IF(OR(A12="",E12=""),"",IF(C12="","",C12+E12)) | G12: Agent 01 | H12: =IF(AND(A12<>"",E12<>"",G12<>""),"Saved","Pending") -> Pending | I12: =IF(H12="Saved",TEXT(TODAY(),"YYYY-MM-DD")&" Auto","—") -> —
B13: =IF(A13="","",IFERROR(VLOOKUP(A13,DB_Customers!$A:$D,4,0),"❌ Account Not Found")) | C13: =IF(A13="","",IFERROR(VLOOKUP(A13,DB_Customers!$A:$N,14,0),"")) | D13: =IF(A13="","",TODAY()) | F13: =IF(OR(A13="",E13=""),"",IF(C13="","",C13+E13)) | G13: Agent 01 | H13: =IF(AND(A13<>"",E13<>"",G13<>""),"Saved","Pending") -> Pending | I13: =IF(H13="Saved",TEXT(TODAY(),"YYYY-MM-DD")&" Auto","—") -> —
B14: =IF(A14="","",IFERROR(VLOOKUP(A14,DB_Customers!$A:$D,4,0),"❌ Account Not Found")) | C14: =IF(A14="","",IFERROR(VLOOKUP(A14,DB_Customers!$A:$N,14,0),"")) | D14: =IF(A14="","",TODAY()) | F14: =IF(OR(A14="",E14=""),"",IF(C14="","",C14+E14)) | H14: =IF(AND(A14<>"",E14<>"",G14<>""),"Saved","Pending") -> Pending | I14: =IF(H14="Saved",TEXT(TODAY(),"YYYY-MM-DD")&" Auto","—") -> —
B15: =IF(A15="","",IFERROR(VLOOKUP(A15,DB_Customers!$A:$D,4,0),"❌ Account Not Found")) | C15: =IF(A15="","",IFERROR(VLOOKUP(A15,DB_Customers!$A:$N,14,0),"")) | D15: =IF(A15="","",TODAY()) | F15: =IF(OR(A15="",E15=""),"",IF(C15="","",C15+E15)) | H15: =IF(AND(A15<>"",E15<>"",G15<>""),"Saved","Pending") -> Pending | I15: =IF(H15="Saved",TEXT(TODAY(),"YYYY-MM-DD")&" Auto","—") -> —
B16: =IF(A16="","",IFERROR(VLOOKUP(A16,DB_Customers!$A:$D,4,0),"❌ Account Not Found")) | C16: =IF(A16="","",IFERROR(VLOOKUP(A16,DB_Customers!$A:$N,14,0),"")) | D16: =IF(A16="","",TODAY()) | F16: =IF(OR(A16="",E16=""),"",IF(C16="","",C16+E16)) | H16: =IF(AND(A16<>"",E16<>"",G16<>""),"Saved","Pending") -> Pending | I16: =IF(H16="Saved",TEXT(TODAY(),"YYYY-MM-DD")&" Auto","—") -> —
B17: =IF(A17="","",IFERROR(VLOOKUP(A17,DB_Customers!$A:$D,4,0),"❌ Account Not Found")) | C17: =IF(A17="","",IFERROR(VLOOKUP(A17,DB_Customers!$A:$N,14,0),"")) | D17: =IF(A17="","",TODAY()) | F17: =IF(OR(A17="",E17=""),"",IF(C17="","",C17+E17)) | H17: =IF(AND(A17<>"",E17<>"",G17<>""),"Saved","Pending") -> Pending | I17: =IF(H17="Saved",TEXT(TODAY(),"YYYY-MM-DD")&" Auto","—") -> —
B18: =IF(A18="","",IFERROR(VLOOKUP(A18,DB_Customers!$A:$D,4,0),"❌ Account Not Found")) | C18: =IF(A18="","",IFERROR(VLOOKUP(A18,DB_Customers!$A:$N,14,0),"")) | D18: =IF(A18="","",TODAY()) | F18: =IF(OR(A18="",E18=""),"",IF(C18="","",C18+E18)) | H18: =IF(AND(A18<>"",E18<>"",G18<>""),"Saved","Pending") -> Pending | I18: =IF(H18="Saved",TEXT(TODAY(),"YYYY-MM-DD")&" Auto","—") -> —
B19: =IF(A19="","",IFERROR(VLOOKUP(A19,DB_Customers!$A:$D,4,0),"❌ Account Not Found")) | C19: =IF(A19="","",IFERROR(VLOOKUP(A19,DB_Customers!$A:$N,14,0),"")) | D19: =IF(A19="","",TODAY()) | F19: =IF(OR(A19="",E19=""),"",IF(C19="","",C19+E19)) | H19: =IF(AND(A19<>"",E19<>"",G19<>""),"Saved","Pending") -> Pending | I19: =IF(H19="Saved",TEXT(TODAY(),"YYYY-MM-DD")&" Auto","—") -> —
B20: =IF(A20="","",IFERROR(VLOOKUP(A20,DB_Customers!$A:$D,4,0),"❌ Account Not Found")) | C20: =IF(A20="","",IFERROR(VLOOKUP(A20,DB_Customers!$A:$N,14,0),"")) | D20: =IF(A20="","",TODAY()) | F20: =IF(OR(A20="",E20=""),"",IF(C20="","",C20+E20)) | H20: =IF(AND(A20<>"",E20<>"",G20<>""),"Saved","Pending") -> Pending | I20: =IF(H20="Saved",TEXT(TODAY(),"YYYY-MM-DD")&" Auto","—") -> —
B21: =IF(A21="","",IFERROR(VLOOKUP(A21,DB_Customers!$A:$D,4,0),"❌ Account Not Found")) | C21: =IF(A21="","",IFERROR(VLOOKUP(A21,DB_Customers!$A:$N,14,0),"")) | D21: =IF(A21="","",TODAY()) | F21: =IF(OR(A21="",E21=""),"",IF(C21="","",C21+E21)) | H21: =IF(AND(A21<>"",E21<>"",G21<>""),"Saved","Pending") -> Pending | I21: =IF(H21="Saved",TEXT(TODAY(),"YYYY-MM-DD")&" Auto","—") -> —
B22: =IF(A22="","",IFERROR(VLOOKUP(A22,DB_Customers!$A:$D,4,0),"❌ Account Not Found")) | C22: =IF(A22="","",IFERROR(VLOOKUP(A22,DB_Customers!$A:$N,14,0),"")) | D22: =IF(A22="","",TODAY()) | F22: =IF(OR(A22="",E22=""),"",IF(C22="","",C22+E22)) | H22: =IF(AND(A22<>"",E22<>"",G22<>""),"Saved","Pending") -> Pending | I22: =IF(H22="Saved",TEXT(TODAY(),"YYYY-MM-DD")&" Auto","—") -> —
B23: =IF(A23="","",IFERROR(VLOOKUP(A23,DB_Customers!$A:$D,4,0),"❌ Account Not Found")) | C23: =IF(A23="","",IFERROR(VLOOKUP(A23,DB_Customers!$A:$N,14,0),"")) | D23: =IF(A23="","",TODAY()) | F23: =IF(OR(A23="",E23=""),"",IF(C23="","",C23+E23)) | H23: =IF(AND(A23<>"",E23<>"",G23<>""),"Saved","Pending") -> Pending | I23: =IF(H23="Saved",TEXT(TODAY(),"YYYY-MM-DD")&" Auto","—") -> —
B24: =IF(A24="","",IFERROR(VLOOKUP(A24,DB_Customers!$A:$D,4,0),"❌ Account Not Found")) | C24: =IF(A24="","",IFERROR(VLOOKUP(A24,DB_Customers!$A:$N,14,0),"")) | D24: =IF(A24="","",TODAY()) | F24: =IF(OR(A24="",E24=""),"",IF(C24="","",C24+E24)) | H24: =IF(AND(A24<>"",E24<>"",G24<>""),"Saved","Pending") -> Pending | I24: =IF(H24="Saved",TEXT(TODAY(),"YYYY-MM-DD")&" Auto","—") -> —
B25: =IF(A25="","",IFERROR(VLOOKUP(A25,DB_Customers!$A:$D,4,0),"❌ Account Not Found")) | C25: =IF(A25="","",IFERROR(VLOOKUP(A25,DB_Customers!$A:$N,14,0),"")) | D25: =IF(A25="","",TODAY()) | F25: =IF(OR(A25="",E25=""),"",IF(C25="","",C25+E25)) | H25: =IF(AND(A25<>"",E25<>"",G25<>""),"Saved","Pending") -> Pending | I25: =IF(H25="Saved",TEXT(TODAY(),"YYYY-MM-DD")&" Auto","—") -> —
... B208: =IF(A208="","",IFERROR(VLOOKUP(A208,DB_Customers!$A:$D,4,0),"❌ Account Not Found")) | C208: =IF(A208="","",IFERROR(VLOOKUP(A208,DB_Customers!$A:$N,14,0),"")) | D208: =IF(A208="","",TODAY()) | F208: =IF(OR(A208="",E208=""),"",IF(C208="","",C208+E208)) | H208: =IF(AND(A208<>"",E208<>"",G208<>""),"Saved","Pending") -> Pending | I208: =IF(H208="Saved",TEXT(TODAY(),"YYYY-MM-DD")&" Auto","—") -> —

Sheet Agent01_Withdrawals
A1: 🏧 SAMICIOUS MICROFINANCE — AGENT01 WITHDRAWALS
A2: Agent: Agent 01 | Status auto: "Successful" or "Unsuccessful" based on balance check
A3: 🏧 Total Withdrawn Today | D3: ✅ Successful | G3: ❌ Unsuccessful | J3: 📅 Date
A4: =SUMIFS(DB_Withdrawals!$G:$G,DB_Withdrawals!$J:$J,"Agent 01",DB_Withdrawals!$F:$F,TODAY()) -> 0 | D4: =COUNTIFS(DB_Withdrawals!$J:$J,"Agent 01",DB_Withdrawals!$K:$K,"Successful",DB_Withdrawals!$F:$F,TODAY()) -> 0 | G4: =COUNTIFS(DB_Withdrawals!$J:$J,"Agent 01",DB_Withdrawals!$K:$K,"Unsuccessful",DB_Withdrawals!$F:$F,TODAY()) -> 0 | J4: =TEXT(TODAY(),"DD MMM YYYY") -> 14 Apr 2026
A5: ⚠️ WITHDRAWALS — System auto-validates balance. Insufficient funds will show "Unsuccessful" status.
A7: 📝 ENTRY FORM — Enter Account # → Name, Balance, Date auto-populate. Enter Withdrawal Amount & Authorized By.
A8: Account # | B8: Customer Name | C8: Available Balance | D8: Date | E8: Withdrawal Amt | F8: Authorized By | G8: New Balance | H8: Agent | I8: Status | J8: Saved At | K8: Notes
A9: SAM20240100001 | B9: =IF(A9="","",IFERROR(VLOOKUP(A9,DB_Customers!$A:$D,4,0),"❌ Account Not Found")) -> Kwame Asare | C9: =IF(A9="","",IFERROR(VLOOKUP(A9,DB_Customers!$A:$N,14,0),"")) -> 1078.82 | D9: =IF(A9="","",TODAY()) -> 46126 | E9: 52.97 | F9: Manager | G9: =IF(OR(A9="",E9=""),"",IF(C9="","",C9-E9)) -> 1025.85 | H9: Agent 01 | I9: =IF(AND(A9<>"",E9<>""),IF(C9>=E9,"Successful","Unsuccessful"),"—") -> Successful | J9: =IF(I9="Successful",TEXT(TODAY(),"YYYY-MM-DD")&" Auto","—") -> 2026-04-14 Auto
A10: SAM20240100002 | B10: =IF(A10="","",IFERROR(VLOOKUP(A10,DB_Customers!$A:$D,4,0),"❌ Account Not Found")) -> Ama Mensah | C10: =IF(A10="","",IFERROR(VLOOKUP(A10,DB_Customers!$A:$N,14,0),"")) -> 1868.51 | D10: =IF(A10="","",TODAY()) -> 46126 | E10: 83.06 | F10: Manager | G10: =IF(OR(A10="",E10=""),"",IF(C10="","",C10-E10)) -> 1785.45 | H10: Agent 01 | I10: =IF(AND(A10<>"",E10<>""),IF(C10>=E10,"Successful","Unsuccessful"),"—") -> Successful | J10: =IF(I10="Successful",TEXT(TODAY(),"YYYY-MM-DD")&" Auto","—") -> 2026-04-14 Auto
B11: =IF(A11="","",IFERROR(VLOOKUP(A11,DB_Customers!$A:$D,4,0),"❌ Account Not Found")) | C11: =IF(A11="","",IFERROR(VLOOKUP(A11,DB_Customers!$A:$N,14,0),"")) | D11: =IF(A11="","",TODAY()) | F11: Manager | G11: =IF(OR(A11="",E11=""),"",IF(C11="","",C11-E11)) | H11: Agent 01 | I11: =IF(AND(A11<>"",E11<>""),IF(C11>=E11,"Successful","Unsuccessful"),"—") -> — | J11: =IF(I11="Successful",TEXT(TODAY(),"YYYY-MM-DD")&" Auto","—") -> —
B12: =IF(A12="","",IFERROR(VLOOKUP(A12,DB_Customers!$A:$D,4,0),"❌ Account Not Found")) | C12: =IF(A12="","",IFERROR(VLOOKUP(A12,DB_Customers!$A:$N,14,0),"")) | D12: =IF(A12="","",TODAY()) | G12: =IF(OR(A12="",E12=""),"",IF(C12="","",C12-E12)) | H12: Agent 01 | I12: =IF(AND(A12<>"",E12<>""),IF(C12>=E12,"Successful","Unsuccessful"),"—") -> — | J12: =IF(I12="Successful",TEXT(TODAY(),"YYYY-MM-DD")&" Auto","—") -> —
B13: =IF(A13="","",IFERROR(VLOOKUP(A13,DB_Customers!$A:$D,4,0),"❌ Account Not Found")) | C13: =IF(A13="","",IFERROR(VLOOKUP(A13,DB_Customers!$A:$N,14,0),"")) | D13: =IF(A13="","",TODAY()) | G13: =IF(OR(A13="",E13=""),"",IF(C13="","",C13-E13)) | H13: Agent 01 | I13: =IF(AND(A13<>"",E13<>""),IF(C13>=E13,"Successful","Unsuccessful"),"—") -> — | J13: =IF(I13="Successful",TEXT(TODAY(),"YYYY-MM-DD")&" Auto","—") -> —
B14: =IF(A14="","",IFERROR(VLOOKUP(A14,DB_Customers!$A:$D,4,0),"❌ Account Not Found")) | C14: =IF(A14="","",IFERROR(VLOOKUP(A14,DB_Customers!$A:$N,14,0),"")) | D14: =IF(A14="","",TODAY()) | G14: =IF(OR(A14="",E14=""),"",IF(C14="","",C14-E14)) | I14: =IF(AND(A14<>"",E14<>""),IF(C14>=E14,"Successful","Unsuccessful"),"—") -> — | J14: =IF(I14="Successful",TEXT(TODAY(),"YYYY-MM-DD")&" Auto","—") -> —
B15: =IF(A15="","",IFERROR(VLOOKUP(A15,DB_Customers!$A:$D,4,0),"❌ Account Not Found")) | C15: =IF(A15="","",IFERROR(VLOOKUP(A15,DB_Customers!$A:$N,14,0),"")) | D15: =IF(A15="","",TODAY()) | G15: =IF(OR(A15="",E15=""),"",IF(C15="","",C15-E15)) | I15: =IF(AND(A15<>"",E15<>""),IF(C15>=E15,"Successful","Unsuccessful"),"—") -> — | J15: =IF(I15="Successful",TEXT(TODAY(),"YYYY-MM-DD")&" Auto","—") -> —
B16: =IF(A16="","",IFERROR(VLOOKUP(A16,DB_Customers!$A:$D,4,0),"❌ Account Not Found")) | C16: =IF(A16="","",IFERROR(VLOOKUP(A16,DB_Customers!$A:$N,14,0),"")) | D16: =IF(A16="","",TODAY()) | G16: =IF(OR(A16="",E16=""),"",IF(C16="","",C16-E16)) | I16: =IF(AND(A16<>"",E16<>""),IF(C16>=E16,"Successful","Unsuccessful"),"—") -> — | J16: =IF(I16="Successful",TEXT(TODAY(),"YYYY-MM-DD")&" Auto","—") -> —
B17: =IF(A17="","",IFERROR(VLOOKUP(A17,DB_Customers!$A:$D,4,0),"❌ Account Not Found")) | C17: =IF(A17="","",IFERROR(VLOOKUP(A17,DB_Customers!$A:$N,14,0),"")) | D17: =IF(A17="","",TODAY()) | G17: =IF(OR(A17="",E17=""),"",IF(C17="","",C17-E17)) | I17: =IF(AND(A17<>"",E17<>""),IF(C17>=E17,"Successful","Unsuccessful"),"—") -> — | J17: =IF(I17="Successful",TEXT(TODAY(),"YYYY-MM-DD")&" Auto","—") -> —
B18: =IF(A18="","",IFERROR(VLOOKUP(A18,DB_Customers!$A:$D,4,0),"❌ Account Not Found")) | C18: =IF(A18="","",IFERROR(VLOOKUP(A18,DB_Customers!$A:$N,14,0),"")) | D18: =IF(A18="","",TODAY()) | G18: =IF(OR(A18="",E18=""),"",IF(C18="","",C18-E18)) | I18: =IF(AND(A18<>"",E18<>""),IF(C18>=E18,"Successful","Unsuccessful"),"—") -> — | J18: =IF(I18="Successful",TEXT(TODAY(),"YYYY-MM-DD")&" Auto","—") -> —
B19: =IF(A19="","",IFERROR(VLOOKUP(A19,DB_Customers!$A:$D,4,0),"❌ Account Not Found")) | C19: =IF(A19="","",IFERROR(VLOOKUP(A19,DB_Customers!$A:$N,14,0),"")) | D19: =IF(A19="","",TODAY()) | G19: =IF(OR(A19="",E19=""),"",IF(C19="","",C19-E19)) | I19: =IF(AND(A19<>"",E19<>""),IF(C19>=E19,"Successful","Unsuccessful"),"—") -> — | J19: =IF(I19="Successful",TEXT(TODAY(),"YYYY-MM-DD")&" Auto","—") -> —
B20: =IF(A20="","",IFERROR(VLOOKUP(A20,DB_Customers!$A:$D,4,0),"❌ Account Not Found")) | C20: =IF(A20="","",IFERROR(VLOOKUP(A20,DB_Customers!$A:$N,14,0),"")) | D20: =IF(A20="","",TODAY()) | G20: =IF(OR(A20="",E20=""),"",IF(C20="","",C20-E20)) | I20: =IF(AND(A20<>"",E20<>""),IF(C20>=E20,"Successful","Unsuccessful"),"—") -> — | J20: =IF(I20="Successful",TEXT(TODAY(),"YYYY-MM-DD")&" Auto","—") -> —
B21: =IF(A21="","",IFERROR(VLOOKUP(A21,DB_Customers!$A:$D,4,0),"❌ Account Not Found")) | C21: =IF(A21="","",IFERROR(VLOOKUP(A21,DB_Customers!$A:$N,14,0),"")) | D21: =IF(A21="","",TODAY()) | G21: =IF(OR(A21="",E21=""),"",IF(C21="","",C21-E21)) | I21: =IF(AND(A21<>"",E21<>""),IF(C21>=E21,"Successful","Unsuccessful"),"—") -> — | J21: =IF(I21="Successful",TEXT(TODAY(),"YYYY-MM-DD")&" Auto","—") -> —
B22: =IF(A22="","",IFERROR(VLOOKUP(A22,DB_Customers!$A:$D,4,0),"❌ Account Not Found")) | C22: =IF(A22="","",IFERROR(VLOOKUP(A22,DB_Customers!$A:$N,14,0),"")) | D22: =IF(A22="","",TODAY()) | G22: =IF(OR(A22="",E22=""),"",IF(C22="","",C22-E22)) | I22: =IF(AND(A22<>"",E22<>""),IF(C22>=E22,"Successful","Unsuccessful"),"—") -> — | J22: =IF(I22="Successful",TEXT(TODAY(),"YYYY-MM-DD")&" Auto","—") -> —
B23: =IF(A23="","",IFERROR(VLOOKUP(A23,DB_Customers!$A:$D,4,0),"❌ Account Not Found")) | C23: =IF(A23="","",IFERROR(VLOOKUP(A23,DB_Customers!$A:$N,14,0),"")) | D23: =IF(A23="","",TODAY()) | G23: =IF(OR(A23="",E23=""),"",IF(C23="","",C23-E23)) | I23: =IF(AND(A23<>"",E23<>""),IF(C23>=E23,"Successful","Unsuccessful"),"—") -> — | J23: =IF(I23="Successful",TEXT(TODAY(),"YYYY-MM-DD")&" Auto","—") -> —
B24: =IF(A24="","",IFERROR(VLOOKUP(A24,DB_Customers!$A:$D,4,0),"❌ Account Not Found")) | C24: =IF(A24="","",IFERROR(VLOOKUP(A24,DB_Customers!$A:$N,14,0),"")) | D24: =IF(A24="","",TODAY()) | G24: =IF(OR(A24="",E24=""),"",IF(C24="","",C24-E24)) | I24: =IF(AND(A24<>"",E24<>""),IF(C24>=E24,"Successful","Unsuccessful"),"—") -> — | J24: =IF(I24="Successful",TEXT(TODAY(),"YYYY-MM-DD")&" Auto","—") -> —
B25: =IF(A25="","",IFERROR(VLOOKUP(A25,DB_Customers!$A:$D,4,0),"❌ Account Not Found")) | C25: =IF(A25="","",IFERROR(VLOOKUP(A25,DB_Customers!$A:$N,14,0),"")) | D25: =IF(A25="","",TODAY()) | G25: =IF(OR(A25="",E25=""),"",IF(C25="","",C25-E25)) | I25: =IF(AND(A25<>"",E25<>""),IF(C25>=E25,"Successful","Unsuccessful"),"—") -> — | J25: =IF(I25="Successful",TEXT(TODAY(),"YYYY-MM-DD")&" Auto","—") -> —
... B208: =IF(A208="","",IFERROR(VLOOKUP(A208,DB_Customers!$A:$D,4,0),"❌ Account Not Found")) | C208: =IF(A208="","",IFERROR(VLOOKUP(A208,DB_Customers!$A:$N,14,0),"")) | D208: =IF(A208="","",TODAY()) | G208: =IF(OR(A208="",E208=""),"",IF(C208="","",C208-E208)) | I208: =IF(AND(A208<>"",E208<>""),IF(C208>=E208,"Successful","Unsuccessful"),"—") -> — | J208: =IF(I208="Successful",TEXT(TODAY(),"YYYY-MM-DD")&" Auto","—") -> —

Sheet Agent01_Loans
A1: 🏦 SAMICIOUS MICROFINANCE — AGENT01 LOAN REQUESTS
A2: Total Repayable = Loan Amount + (Loan Amount × Rate% × Months) | Status: Pending → Approved when credited
A4: 🔢 INSTANT LOAN CALCULATOR
A5: Loan Amount (GHC): | B5: 10000
A6: Duration (Months): | B6: 4
A7: Interest Rate (%/m): | B7: 2.5
A8: ━ Total Interest: | B8: =IF(B5="","",B5*B7/100*B6) -> 1000
A9: ━ Total Repayable: | B9: =IF(B5="","",B5+(B5*B7/100*B6)) -> 11000
A10: ━ Monthly Payment: | B10: =IFERROR(B9/B6,"") -> 2750
A12: 📋 LOAN REQUEST ENTRIES — Loan ID & Request Date auto-generate | Total Repayable auto-calculated
A13: Loan ID | B13: Account # | C13: Customer Name | D13: Request Date | E13: Loan Amount | F13: Purpose | G13: Months | H13: Rate % | I13: Total Repayable | J13: Monthly Install | K13: Status | L13: Agent | M13: Note
A14: =IF(B14="","",IF(C14="❌ Account Not Found","INVALID","LN"&TEXT(D14,"YYYYMMDD")&TEXT(ROW()-13,"0000"))) -> LN202604140001 | B14: SAM20240100001 | C14: =IF(B14="","",IFERROR(VLOOKUP(B14,DB_Customers!$A:$D,4,0),"❌ Account Not Found")) -> Kwame Asare | D14: =IF(B14="","",TODAY()) -> 46126 | E14: 1085.95 | F14: Business expansion | G14: 18 | H14: 2.5 | I14: =IF(E14="","",E14+(E14*H14/100*G14)) -> 1574.6275 | J14: =IFERROR(I14/G14,"") -> 87.479306 | K14: =IF(B14="","","Pending") -> Pending | L14: Agent 01
A15: =IF(B15="","",IF(C15="❌ Account Not Found","INVALID","LN"&TEXT(D15,"YYYYMMDD")&TEXT(ROW()-13,"0000"))) -> LN202604140002 | B15: SAM20240100002 | C15: =IF(B15="","",IFERROR(VLOOKUP(B15,DB_Customers!$A:$D,4,0),"❌ Account Not Found")) -> Ama Mensah | D15: =IF(B15="","",TODAY()) -> 46126 | E15: 1985.99 | F15: Business expansion | G15: 9 | H15: 2.5 | I15: =IF(E15="","",E15+(E15*H15/100*G15)) -> 2432.8378 | J15: =IFERROR(I15/G15,"") -> 270.31531 | K15: =IF(B15="","","Pending") -> Pending | L15: Agent 01
A16: =IF(B16="","",IF(C16="❌ Account Not Found","INVALID","LN"&TEXT(D16,"YYYYMMDD")&TEXT(ROW()-13,"0000"))) | C16: =IF(B16="","",IFERROR(VLOOKUP(B16,DB_Customers!$A:$D,4,0),"❌ Account Not Found")) | D16: =IF(B16="","",TODAY()) | H16: 2.5 | I16: =IF(E16="","",E16+(E16*H16/100*G16)) | J16: =IFERROR(I16/G16,"") | K16: =IF(B16="","","Pending") | L16: Agent 01
A17: =IF(B17="","",IF(C17="❌ Account Not Found","INVALID","LN"&TEXT(D17,"YYYYMMDD")&TEXT(ROW()-13,"0000"))) | C17: =IF(B17="","",IFERROR(VLOOKUP(B17,DB_Customers!$A:$D,4,0),"❌ Account Not Found")) | D17: =IF(B17="","",TODAY()) | H17: 2.5 | I17: =IF(E17="","",E17+(E17*H17/100*G17)) | J17: =IFERROR(I17/G17,"") | K17: =IF(B17="","","Pending") | L17: Agent 01
A18: =IF(B18="","",IF(C18="❌ Account Not Found","INVALID","LN"&TEXT(D18,"YYYYMMDD")&TEXT(ROW()-13,"0000"))) | C18: =IF(B18="","",IFERROR(VLOOKUP(B18,DB_Customers!$A:$D,4,0),"❌ Account Not Found")) | D18: =IF(B18="","",TODAY()) | H18: 2.5 | I18: =IF(E18="","",E18+(E18*H18/100*G18)) | J18: =IFERROR(I18/G18,"") | K18: =IF(B18="","","Pending") | L18: Agent 01
A19: =IF(B19="","",IF(C19="❌ Account Not Found","INVALID","LN"&TEXT(D19,"YYYYMMDD")&TEXT(ROW()-13,"0000"))) | C19: =IF(B19="","",IFERROR(VLOOKUP(B19,DB_Customers!$A:$D,4,0),"❌ Account Not Found")) | D19: =IF(B19="","",TODAY()) | H19: 2.5 | I19: =IF(E19="","",E19+(E19*H19/100*G19)) | J19: =IFERROR(I19/G19,"") | K19: =IF(B19="","","Pending")
A20: =IF(B20="","",IF(C20="❌ Account Not Found","INVALID","LN"&TEXT(D20,"YYYYMMDD")&TEXT(ROW()-13,"0000"))) | C20: =IF(B20="","",IFERROR(VLOOKUP(B20,DB_Customers!$A:$D,4,0),"❌ Account Not Found")) | D20: =IF(B20="","",TODAY()) | H20: 2.5 | I20: =IF(E20="","",E20+(E20*H20/100*G20)) | J20: =IFERROR(I20/G20,"") | K20: =IF(B20="","","Pending")
A21: =IF(B21="","",IF(C21="❌ Account Not Found","INVALID","LN"&TEXT(D21,"YYYYMMDD")&TEXT(ROW()-13,"0000"))) | C21: =IF(B21="","",IFERROR(VLOOKUP(B21,DB_Customers!$A:$D,4,0),"❌ Account Not Found")) | D21: =IF(B21="","",TODAY()) | H21: 2.5 | I21: =IF(E21="","",E21+(E21*H21/100*G21)) | J21: =IFERROR(I21/G21,"") | K21: =IF(B21="","","Pending")
A22: =IF(B22="","",IF(C22="❌ Account Not Found","INVALID","LN"&TEXT(D22,"YYYYMMDD")&TEXT(ROW()-13,"0000"))) | C22: =IF(B22="","",IFERROR(VLOOKUP(B22,DB_Customers!$A:$D,4,0),"❌ Account Not Found")) | D22: =IF(B22="","",TODAY()) | H22: 2.5 | I22: =IF(E22="","",E22+(E22*H22/100*G22)) | J22: =IFERROR(I22/G22,"") | K22: =IF(B22="","","Pending")
A23: =IF(B23="","",IF(C23="❌ Account Not Found","INVALID","LN"&TEXT(D23,"YYYYMMDD")&TEXT(ROW()-13,"0000"))) | C23: =IF(B23="","",IFERROR(VLOOKUP(B23,DB_Customers!$A:$D,4,0),"❌ Account Not Found")) | D23: =IF(B23="","",TODAY()) | H23: 2.5 | I23: =IF(E23="","",E23+(E23*H23/100*G23)) | J23: =IFERROR(I23/G23,"") | K23: =IF(B23="","","Pending")
A24: =IF(B24="","",IF(C24="❌ Account Not Found","INVALID","LN"&TEXT(D24,"YYYYMMDD")&TEXT(ROW()-13,"0000"))) | C24: =IF(B24="","",IFERROR(VLOOKUP(B24,DB_Customers!$A:$D,4,0),"❌ Account Not Found")) | D24: =IF(B24="","",TODAY()) | H24: 2.5 | I24: =IF(E24="","",E24+(E24*H24/100*G24)) | J24: =IFERROR(I24/G24,"") | K24: =IF(B24="","","Pending")
A25: =IF(B25="","",IF(C25="❌ Account Not Found","INVALID","LN"&TEXT(D25,"YYYYMMDD")&TEXT(ROW()-13,"0000"))) | C25: =IF(B25="","",IFERROR(VLOOKUP(B25,DB_Customers!$A:$D,4,0),"❌ Account Not Found")) | D25: =IF(B25="","",TODAY()) | H25: 2.5 | I25: =IF(E25="","",E25+(E25*H25/100*G25)) | J25: =IFERROR(I25/G25,"") | K25: =IF(B25="","","Pending")
A26: =IF(B26="","",IF(C26="❌ Account Not Found","INVALID","LN"&TEXT(D26,"YYYYMMDD")&TEXT(ROW()-13,"0000"))) | C26: =IF(B26="","",IFERROR(VLOOKUP(B26,DB_Customers!$A:$D,4,0),"❌ Account Not Found")) | D26: =IF(B26="","",TODAY()) | H26: 2.5 | I26: =IF(E26="","",E26+(E26*H26/100*G26)) | J26: =IFERROR(I26/G26,"") | K26: =IF(B26="","","Pending")
A27: =IF(B27="","",IF(C27="❌ Account Not Found","INVALID","LN"&TEXT(D27,"YYYYMMDD")&TEXT(ROW()-13,"0000"))) | C27: =IF(B27="","",IFERROR(VLOOKUP(B27,DB_Customers!$A:$D,4,0),"❌ Account Not Found")) | D27: =IF(B27="","",TODAY()) | H27: 2.5 | I27: =IF(E27="","",E27+(E27*H27/100*G27)) | J27: =IFERROR(I27/G27,"") | K27: =IF(B27="","","Pending")
A28: =IF(B28="","",IF(C28="❌ Account Not Found","INVALID","LN"&TEXT(D28,"YYYYMMDD")&TEXT(ROW()-13,"0000"))) | C28: =IF(B28="","",IFERROR(VLOOKUP(B28,DB_Customers!$A:$D,4,0),"❌ Account Not Found")) | D28: =IF(B28="","",TODAY()) | H28: 2.5 | I28: =IF(E28="","",E28+(E28*H28/100*G28)) | J28: =IFERROR(I28/G28,"") | K28: =IF(B28="","","Pending")
A29: =IF(B29="","",IF(C29="❌ Account Not Found","INVALID","LN"&TEXT(D29,"YYYYMMDD")&TEXT(ROW()-13,"0000"))) | C29: =IF(B29="","",IFERROR(VLOOKUP(B29,DB_Customers!$A:$D,4,0),"❌ Account Not Found")) | D29: =IF(B29="","",TODAY()) | H29: 2.5 | I29: =IF(E29="","",E29+(E29*H29/100*G29)) | J29: =IFERROR(I29/G29,"") | K29: =IF(B29="","","Pending")
A30: =IF(B30="","",IF(C30="❌ Account Not Found","INVALID","LN"&TEXT(D30,"YYYYMMDD")&TEXT(ROW()-13,"0000"))) | C30: =IF(B30="","",IFERROR(VLOOKUP(B30,DB_Customers!$A:$D,4,0),"❌ Account Not Found")) | D30: =IF(B30="","",TODAY()) | H30: 2.5 | I30: =IF(E30="","",E30+(E30*H30/100*G30)) | J30: =IFERROR(I30/G30,"") | K30: =IF(B30="","","Pending")
... A113: =IF(B113="","",IF(C113="❌ Account Not Found","INVALID","LN"&TEXT(D113,"YYYYMMDD")&TEXT(ROW()-13,"0000"))) | C113: =IF(B113="","",IFERROR(VLOOKUP(B113,DB_Customers!$A:$D,4,0),"❌ Account Not Found")) | D113: =IF(B113="","",TODAY()) | H113: 2.5 | I113: =IF(E113="","",E113+(E113*H113/100*G113)) | J113: =IFERROR(I113/G113,"") | K113: =IF(B113="","","Pending")

Sheet Agent02_Savings
A1: 💰 SAMICIOUS MICROFINANCE — AGENT02 SAVINGS
A2: Agent: Agent 02 | Enter Account # → All fields auto-populate | Status auto-sets to "Saved"
A3: 💰 Total Collected Today | D3: 📊 Transactions Today | G3: 📅 Date | J3: 🎯 Daily Target
A4: =SUMIFS(DB_Savings!$F:$F,DB_Savings!$G:$G,"Agent 02",DB_Savings!$E:$E,TODAY()) -> 0 | D4: =COUNTIFS(DB_Savings!$G:$G,"Agent 02",DB_Savings!$E:$E,TODAY()) -> 0 | G4: =TEXT(TODAY(),"DDDD, DD MMMM YYYY") -> Tuesday, 14 April 2026 | J4: 5000
A5: =IF(SUMIFS(DB_Savings!$F:$F,DB_Savings!$G:$G,"Agent 02",DB_Savings!$E:$E,TODAY())>=J4,"✅ DAILY TARGET ACHIEVED! Well done Agent 02!","⏳ Collection in progress — Keep going! Remaining: GHC "&TEXT(J4-SUMIFS(DB_Savings!$F:$F,DB_Savings!$G:$G,"Agent 02",DB_Savings!$E:$E,TODAY()),"#,##0.00")) -> ⏳ Collection in progress — Keep going! Remaining: GHC 5,000.00
A7: 📝 ENTRY FORM — Enter Account Number in column A. All other fields auto-populate. Enter Savings Amount in column E then Tab to complete.
A8: Account # | B8: Customer Name | C8: Current Balance | D8: Date | E8: Savings Amount | F8: New Balance | G8: Agent | H8: Status | I8: Saved At | J8: Notes
A9: SAM20240200003 | B9: =IF(A9="","",IFERROR(VLOOKUP(A9,DB_Customers!$A:$D,4,0),"❌ Account Not Found")) -> Kofi Boateng | C9: =IF(A9="","",IFERROR(VLOOKUP(A9,DB_Customers!$A:$N,14,0),"")) -> 2556.82 | D9: =IF(A9="","",TODAY()) -> 46126 | E9: 382.59 | F9: =IF(OR(A9="",E9=""),"",IF(C9="","",C9+E9)) -> 2939.41 | G9: Agent 02 | H9: =IF(AND(A9<>"",E9<>"",G9<>""),"Saved","Pending") -> Saved | I9: =IF(H9="Saved",TEXT(TODAY(),"YYYY-MM-DD")&" Auto","—") -> 2026-04-14 Auto
A10: SAM20240200004 | B10: =IF(A10="","",IFERROR(VLOOKUP(A10,DB_Customers!$A:$D,4,0),"❌ Account Not Found")) -> Abena Owusu | C10: =IF(A10="","",IFERROR(VLOOKUP(A10,DB_Customers!$A:$N,14,0),"")) -> 1498.26 | D10: =IF(A10="","",TODAY()) -> 46126 | E10: 237.32 | F10: =IF(OR(A10="",E10=""),"",IF(C10="","",C10+E10)) -> 1735.58 | G10: Agent 02 | H10: =IF(AND(A10<>"",E10<>"",G10<>""),"Saved","Pending") -> Saved | I10: =IF(H10="Saved",TEXT(TODAY(),"YYYY-MM-DD")&" Auto","—") -> 2026-04-14 Auto
B11: =IF(A11="","",IFERROR(VLOOKUP(A11,DB_Customers!$A:$D,4,0),"❌ Account Not Found")) | C11: =IF(A11="","",IFERROR(VLOOKUP(A11,DB_Customers!$A:$N,14,0),"")) | D11: =IF(A11="","",TODAY()) | F11: =IF(OR(A11="",E11=""),"",IF(C11="","",C11+E11)) | G11: Agent 02 | H11: =IF(AND(A11<>"",E11<>"",G11<>""),"Saved","Pending") -> Pending | I11: =IF(H11="Saved",TEXT(TODAY(),"YYYY-MM-DD")&" Auto","—") -> —
B12: =IF(A12="","",IFERROR(VLOOKUP(A12,DB_Customers!$A:$D,4,0),"❌ Account Not Found")) | C12: =IF(A12="","",IFERROR(VLOOKUP(A12,DB_Customers!$A:$N,14,0),"")) | D12: =IF(A12="","",TODAY()) | F12: =IF(OR(A12="",E12=""),"",IF(C12="","",C12+E12)) | G12: Agent 02 | H12: =IF(AND(A12<>"",E12<>"",G12<>""),"Saved","Pending") -> Pending | I12: =IF(H12="Saved",TEXT(TODAY(),"YYYY-MM-DD")&" Auto","—") -> —
B13: =IF(A13="","",IFERROR(VLOOKUP(A13,DB_Customers!$A:$D,4,0),"❌ Account Not Found")) | C13: =IF(A13="","",IFERROR(VLOOKUP(A13,DB_Customers!$A:$N,14,0),"")) | D13: =IF(A13="","",TODAY()) | F13: =IF(OR(A13="",E13=""),"",IF(C13="","",C13+E13)) | G13: Agent 02 | H13: =IF(AND(A13<>"",E13<>"",G13<>""),"Saved","Pending") -> Pending | I13: =IF(H13="Saved",TEXT(TODAY(),"YYYY-MM-DD")&" Auto","—") -> —
B14: =IF(A14="","",IFERROR(VLOOKUP(A14,DB_Customers!$A:$D,4,0),"❌ Account Not Found")) | C14: =IF(A14="","",IFERROR(VLOOKUP(A14,DB_Customers!$A:$N,14,0),"")) | D14: =IF(A14="","",TODAY()) | F14: =IF(OR(A14="",E14=""),"",IF(C14="","",C14+E14)) | H14: =IF(AND(A14<>"",E14<>"",G14<>""),"Saved","Pending") -> Pending | I14: =IF(H14="Saved",TEXT(TODAY(),"YYYY-MM-DD")&" Auto","—") -> —
B15: =IF(A15="","",IFERROR(VLOOKUP(A15,DB_Customers!$A:$D,4,0),"❌ Account Not Found")) | C15: =IF(A15="","",IFERROR(VLOOKUP(A15,DB_Customers!$A:$N,14,0),"")) | D15: =IF(A15="","",TODAY()) | F15: =IF(OR(A15="",E15=""),"",IF(C15="","",C15+E15)) | H15: =IF(AND(A15<>"",E15<>"",G15<>""),"Saved","Pending") -> Pending | I15: =IF(H15="Saved",TEXT(TODAY(),"YYYY-MM-DD")&" Auto","—") -> —
B16: =IF(A16="","",IFERROR(VLOOKUP(A16,DB_Customers!$A:$D,4,0),"❌ Account Not Found")) | C16: =IF(A16="","",IFERROR(VLOOKUP(A16,DB_Customers!$A:$N,14,0),"")) | D16: =IF(A16="","",TODAY()) | F16: =IF(OR(A16="",E16=""),"",IF(C16="","",C16+E16)) | H16: =IF(AND(A16<>"",E16<>"",G16<>""),"Saved","Pending") -> Pending | I16: =IF(H16="Saved",TEXT(TODAY(),"YYYY-MM-DD")&" Auto","—") -> —
B17: =IF(A17="","",IFERROR(VLOOKUP(A17,DB_Customers!$A:$D,4,0),"❌ Account Not Found")) | C17: =IF(A17="","",IFERROR(VLOOKUP(A17,DB_Customers!$A:$N,14,0),"")) | D17: =IF(A17="","",TODAY()) | F17: =IF(OR(A17="",E17=""),"",IF(C17="","",C17+E17)) | H17: =IF(AND(A17<>"",E17<>"",G17<>""),"Saved","Pending") -> Pending | I17: =IF(H17="Saved",TEXT(TODAY(),"YYYY-MM-DD")&" Auto","—") -> —
B18: =IF(A18="","",IFERROR(VLOOKUP(A18,DB_Customers!$A:$D,4,0),"❌ Account Not Found")) | C18: =IF(A18="","",IFERROR(VLOOKUP(A18,DB_Customers!$A:$N,14,0),"")) | D18: =IF(A18="","",TODAY()) | F18: =IF(OR(A18="",E18=""),"",IF(C18="","",C18+E18)) | H18: =IF(AND(A18<>"",E18<>"",G18<>""),"Saved","Pending") -> Pending | I18: =IF(H18="Saved",TEXT(TODAY(),"YYYY-MM-DD")&" Auto","—") -> —
B19: =IF(A19="","",IFERROR(VLOOKUP(A19,DB_Customers!$A:$D,4,0),"❌ Account Not Found")) | C19: =IF(A19="","",IFERROR(VLOOKUP(A19,DB_Customers!$A:$N,14,0),"")) | D19: =IF(A19="","",TODAY()) | F19: =IF(OR(A19="",E19=""),"",IF(C19="","",C19+E19)) | H19: =IF(AND(A19<>"",E19<>"",G19<>""),"Saved","Pending") -> Pending | I19: =IF(H19="Saved",TEXT(TODAY(),"YYYY-MM-DD")&" Auto","—") -> —
B20: =IF(A20="","",IFERROR(VLOOKUP(A20,DB_Customers!$A:$D,4,0),"❌ Account Not Found")) | C20: =IF(A20="","",IFERROR(VLOOKUP(A20,DB_Customers!$A:$N,14,0),"")) | D20: =IF(A20="","",TODAY()) | F20: =IF(OR(A20="",E20=""),"",IF(C20="","",C20+E20)) | H20: =IF(AND(A20<>"",E20<>"",G20<>""),"Saved","Pending") -> Pending | I20: =IF(H20="Saved",TEXT(TODAY(),"YYYY-MM-DD")&" Auto","—") -> —
B21: =IF(A21="","",IFERROR(VLOOKUP(A21,DB_Customers!$A:$D,4,0),"❌ Account Not Found")) | C21: =IF(A21="","",IFERROR(VLOOKUP(A21,DB_Customers!$A:$N,14,0),"")) | D21: =IF(A21="","",TODAY()) | F21: =IF(OR(A21="",E21=""),"",IF(C21="","",C21+E21)) | H21: =IF(AND(A21<>"",E21<>"",G21<>""),"Saved","Pending") -> Pending | I21: =IF(H21="Saved",TEXT(TODAY(),"YYYY-MM-DD")&" Auto","—") -> —
B22: =IF(A22="","",IFERROR(VLOOKUP(A22,DB_Customers!$A:$D,4,0),"❌ Account Not Found")) | C22: =IF(A22="","",IFERROR(VLOOKUP(A22,DB_Customers!$A:$N,14,0),"")) | D22: =IF(A22="","",TODAY()) | F22: =IF(OR(A22="",E22=""),"",IF(C22="","",C22+E22)) | H22: =IF(AND(A22<>"",E22<>"",G22<>""),"Saved","Pending") -> Pending | I22: =IF(H22="Saved",TEXT(TODAY(),"YYYY-MM-DD")&" Auto","—") -> —
B23: =IF(A23="","",IFERROR(VLOOKUP(A23,DB_Customers!$A:$D,4,0),"❌ Account Not Found")) | C23: =IF(A23="","",IFERROR(VLOOKUP(A23,DB_Customers!$A:$N,14,0),"")) | D23: =IF(A23="","",TODAY()) | F23: =IF(OR(A23="",E23=""),"",IF(C23="","",C23+E23)) | H23: =IF(AND(A23<>"",E23<>"",G23<>""),"Saved","Pending") -> Pending | I23: =IF(H23="Saved",TEXT(TODAY(),"YYYY-MM-DD")&" Auto","—") -> —
B24: =IF(A24="","",IFERROR(VLOOKUP(A24,DB_Customers!$A:$D,4,0),"❌ Account Not Found")) | C24: =IF(A24="","",IFERROR(VLOOKUP(A24,DB_Customers!$A:$N,14,0),"")) | D24: =IF(A24="","",TODAY()) | F24: =IF(OR(A24="",E24=""),"",IF(C24="","",C24+E24)) | H24: =IF(AND(A24<>"",E24<>"",G24<>""),"Saved","Pending") -> Pending | I24: =IF(H24="Saved",TEXT(TODAY(),"YYYY-MM-DD")&" Auto","—") -> —
B25: =IF(A25="","",IFERROR(VLOOKUP(A25,DB_Customers!$A:$D,4,0),"❌ Account Not Found")) | C25: =IF(A25="","",IFERROR(VLOOKUP(A25,DB_Customers!$A:$N,14,0),"")) | D25: =IF(A25="","",TODAY()) | F25: =IF(OR(A25="",E25=""),"",IF(C25="","",C25+E25)) | H25: =IF(AND(A25<>"",E25<>"",G25<>""),"Saved","Pending") -> Pending | I25: =IF(H25="Saved",TEXT(TODAY(),"YYYY-MM-DD")&" Auto","—") -> —
... B208: =IF(A208="","",IFERROR(VLOOKUP(A208,DB_Customers!$A:$D,4,0),"❌ Account Not Found")) | C208: =IF(A208="","",IFERROR(VLOOKUP(A208,DB_Customers!$A:$N,14,0),"")) | D208: =IF(A208="","",TODAY()) | F208: =IF(OR(A208="",E208=""),"",IF(C208="","",C208+E208)) | H208: =IF(AND(A208<>"",E208<>"",G208<>""),"Saved","Pending") -> Pending | I208: =IF(H208="Saved",TEXT(TODAY(),"YYYY-MM-DD")&" Auto","—") -> —

Sheet Agent02_Withdrawals
A1: 🏧 SAMICIOUS MICROFINANCE — AGENT02 WITHDRAWALS
A2: Agent: Agent 02 | Status auto: "Successful" or "Unsuccessful" based on balance check
A3: 🏧 Total Withdrawn Today | D3: ✅ Successful | G3: ❌ Unsuccessful | J3: 📅 Date
A4: =SUMIFS(DB_Withdrawals!$G:$G,DB_Withdrawals!$J:$J,"Agent 02",DB_Withdrawals!$F:$F,TODAY()) -> 0 | D4: =COUNTIFS(DB_Withdrawals!$J:$J,"Agent 02",DB_Withdrawals!$K:$K,"Successful",DB_Withdrawals!$F:$F,TODAY()) -> 0 | G4: =COUNTIFS(DB_Withdrawals!$J:$J,"Agent 02",DB_Withdrawals!$K:$K,"Unsuccessful",DB_Withdrawals!$F:$F,TODAY()) -> 0 | J4: =TEXT(TODAY(),"DD MMM YYYY") -> 14 Apr 2026
A5: ⚠️ WITHDRAWALS — System auto-validates balance. Insufficient funds will show "Unsuccessful" status.
A7: 📝 ENTRY FORM — Enter Account # → Name, Balance, Date auto-populate. Enter Withdrawal Amount & Authorized By.
A8: Account # | B8: Customer Name | C8: Available Balance | D8: Date | E8: Withdrawal Amt | F8: Authorized By | G8: New Balance | H8: Agent | I8: Status | J8: Saved At | K8: Notes
A9: SAM20240200003 | B9: =IF(A9="","",IFERROR(VLOOKUP(A9,DB_Customers!$A:$D,4,0),"❌ Account Not Found")) -> Kofi Boateng | C9: =IF(A9="","",IFERROR(VLOOKUP(A9,DB_Customers!$A:$N,14,0),"")) -> 2556.82 | D9: =IF(A9="","",TODAY()) -> 46126 | E9: 150.96 | F9: Manager | G9: =IF(OR(A9="",E9=""),"",IF(C9="","",C9-E9)) -> 2405.86 | H9: Agent 02 | I9: =IF(AND(A9<>"",E9<>""),IF(C9>=E9,"Successful","Unsuccessful"),"—") -> Successful | J9: =IF(I9="Successful",TEXT(TODAY(),"YYYY-MM-DD")&" Auto","—") -> 2026-04-14 Auto
A10: SAM20240200004 | B10: =IF(A10="","",IFERROR(VLOOKUP(A10,DB_Customers!$A:$D,4,0),"❌ Account Not Found")) -> Abena Owusu | C10: =IF(A10="","",IFERROR(VLOOKUP(A10,DB_Customers!$A:$N,14,0),"")) -> 1498.26 | D10: =IF(A10="","",TODAY()) -> 46126 | E10: 53.73 | F10: Manager | G10: =IF(OR(A10="",E10=""),"",IF(C10="","",C10-E10)) -> 1444.53 | H10: Agent 02 | I10: =IF(AND(A10<>"",E10<>""),IF(C10>=E10,"Successful","Unsuccessful"),"—") -> Successful | J10: =IF(I10="Successful",TEXT(TODAY(),"YYYY-MM-DD")&" Auto","—") -> 2026-04-14 Auto
B11: =IF(A11="","",IFERROR(VLOOKUP(A11,DB_Customers!$A:$D,4,0),"❌ Account Not Found")) | C11: =IF(A11="","",IFERROR(VLOOKUP(A11,DB_Customers!$A:$N,14,0),"")) | D11: =IF(A11="","",TODAY()) | F11: Manager | G11: =IF(OR(A11="",E11=""),"",IF(C11="","",C11-E11)) | H11: Agent 02 | I11: =IF(AND(A11<>"",E11<>""),IF(C11>=E11,"Successful","Unsuccessful"),"—") -> — | J11: =IF(I11="Successful",TEXT(TODAY(),"YYYY-MM-DD")&" Auto","—") -> —
B12: =IF(A12="","",IFERROR(VLOOKUP(A12,DB_Customers!$A:$D,4,0),"❌ Account Not Found")) | C12: =IF(A12="","",IFERROR(VLOOKUP(A12,DB_Customers!$A:$N,14,0),"")) | D12: =IF(A12="","",TODAY()) | G12: =IF(OR(A12="",E12=""),"",IF(C12="","",C12-E12)) | H12: Agent 02 | I12: =IF(AND(A12<>"",E12<>""),IF(C12>=E12,"Successful","Unsuccessful"),"—") -> — | J12: =IF(I12="Successful",TEXT(TODAY(),"YYYY-MM-DD")&" Auto","—") -> —
B13: =IF(A13="","",IFERROR(VLOOKUP(A13,DB_Customers!$A:$D,4,0),"❌ Account Not Found")) | C13: =IF(A13="","",IFERROR(VLOOKUP(A13,DB_Customers!$A:$N,14,0),"")) | D13: =IF(A13="","",TODAY()) | G13: =IF(OR(A13="",E13=""),"",IF(C13="","",C13-E13)) | H13: Agent 02 | I13: =IF(AND(A13<>"",E13<>""),IF(C13>=E13,"Successful","Unsuccessful"),"—") -> — | J13: =IF(I13="Successful",TEXT(TODAY(),"YYYY-MM-DD")&" Auto","—") -> —
B14: =IF(A14="","",IFERROR(VLOOKUP(A14,DB_Customers!$A:$D,4,0),"❌ Account Not Found")) | C14: =IF(A14="","",IFERROR(VLOOKUP(A14,DB_Customers!$A:$N,14,0),"")) | D14: =IF(A14="","",TODAY()) | G14: =IF(OR(A14="",E14=""),"",IF(C14="","",C14-E14)) | I14: =IF(AND(A14<>"",E14<>""),IF(C14>=E14,"Successful","Unsuccessful"),"—") -> — | J14: =IF(I14="Successful",TEXT(TODAY(),"YYYY-MM-DD")&" Auto","—") -> —
B15: =IF(A15="","",IFERROR(VLOOKUP(A15,DB_Customers!$A:$D,4,0),"❌ Account Not Found")) | C15: =IF(A15="","",IFERROR(VLOOKUP(A15,DB_Customers!$A:$N,14,0),"")) | D15: =IF(A15="","",TODAY()) | G15: =IF(OR(A15="",E15=""),"",IF(C15="","",C15-E15)) | I15: =IF(AND(A15<>"",E15<>""),IF(C15>=E15,"Successful","Unsuccessful"),"—") -> — | J15: =IF(I15="Successful",TEXT(TODAY(),"YYYY-MM-DD")&" Auto","—") -> —
B16: =IF(A16="","",IFERROR(VLOOKUP(A16,DB_Customers!$A:$D,4,0),"❌ Account Not Found")) | C16: =IF(A16="","",IFERROR(VLOOKUP(A16,DB_Customers!$A:$N,14,0),"")) | D16: =IF(A16="","",TODAY()) | G16: =IF(OR(A16="",E16=""),"",IF(C16="","",C16-E16)) | I16: =IF(AND(A16<>"",E16<>""),IF(C16>=E16,"Successful","Unsuccessful"),"—") -> — | J16: =IF(I16="Successful",TEXT(TODAY(),"YYYY-MM-DD")&" Auto","—") -> —
B17: =IF(A17="","",IFERROR(VLOOKUP(A17,DB_Customers!$A:$D,4,0),"❌ Account Not Found")) | C17: =IF(A17="","",IFERROR(VLOOKUP(A17,DB_Customers!$A:$N,14,0),"")) | D17: =IF(A17="","",TODAY()) | G17: =IF(OR(A17="",E17=""),"",IF(C17="","",C17-E17)) | I17: =IF(AND(A17<>"",E17<>""),IF(C17>=E17,"Successful","Unsuccessful"),"—") -> — | J17: =IF(I17="Successful",TEXT(TODAY(),"YYYY-MM-DD")&" Auto","—") -> —
B18: =IF(A18="","",IFERROR(VLOOKUP(A18,DB_Customers!$A:$D,4,0),"❌ Account Not Found")) | C18: =IF(A18="","",IFERROR(VLOOKUP(A18,DB_Customers!$A:$N,14,0),"")) | D18: =IF(A18="","",TODAY()) | G18: =IF(OR(A18="",E18=""),"",IF(C18="","",C18-E18)) | I18: =IF(AND(A18<>"",E18<>""),IF(C18>=E18,"Successful","Unsuccessful"),"—") -> — | J18: =IF(I18="Successful",TEXT(TODAY(),"YYYY-MM-DD")&" Auto","—") -> —
B19: =IF(A19="","",IFERROR(VLOOKUP(A19,DB_Customers!$A:$D,4,0),"❌ Account Not Found")) | C19: =IF(A19="","",IFERROR(VLOOKUP(A19,DB_Customers!$A:$N,14,0),"")) | D19: =IF(A19="","",TODAY()) | G19: =IF(OR(A19="",E19=""),"",IF(C19="","",C19-E19)) | I19: =IF(AND(A19<>"",E19<>""),IF(C19>=E19,"Successful","Unsuccessful"),"—") -> — | J19: =IF(I19="Successful",TEXT(TODAY(),"YYYY-MM-DD")&" Auto","—") -> —
B20: =IF(A20="","",IFERROR(VLOOKUP(A20,DB_Customers!$A:$D,4,0),"❌ Account Not Found")) | C20: =IF(A20="","",IFERROR(VLOOKUP(A20,DB_Customers!$A:$N,14,0),"")) | D20: =IF(A20="","",TODAY()) | G20: =IF(OR(A20="",E20=""),"",IF(C20="","",C20-E20)) | I20: =IF(AND(A20<>"",E20<>""),IF(C20>=E20,"Successful","Unsuccessful"),"—") -> — | J20: =IF(I20="Successful",TEXT(TODAY(),"YYYY-MM-DD")&" Auto","—") -> —
B21: =IF(A21="","",IFERROR(VLOOKUP(A21,DB_Customers!$A:$D,4,0),"❌ Account Not Found")) | C21: =IF(A21="","",IFERROR(VLOOKUP(A21,DB_Customers!$A:$N,14,0),"")) | D21: =IF(A21="","",TODAY()) | G21: =IF(OR(A21="",E21=""),"",IF(C21="","",C21-E21)) | I21: =IF(AND(A21<>"",E21<>""),IF(C21>=E21,"Successful","Unsuccessful"),"—") -> — | J21: =IF(I21="Successful",TEXT(TODAY(),"YYYY-MM-DD")&" Auto","—") -> —
B22: =IF(A22="","",IFERROR(VLOOKUP(A22,DB_Customers!$A:$D,4,0),"❌ Account Not Found")) | C22: =IF(A22="","",IFERROR(VLOOKUP(A22,DB_Customers!$A:$N,14,0),"")) | D22: =IF(A22="","",TODAY()) | G22: =IF(OR(A22="",E22=""),"",IF(C22="","",C22-E22)) | I22: =IF(AND(A22<>"",E22<>""),IF(C22>=E22,"Successful","Unsuccessful"),"—") -> — | J22: =IF(I22="Successful",TEXT(TODAY(),"YYYY-MM-DD")&" Auto","—") -> —
B23: =IF(A23="","",IFERROR(VLOOKUP(A23,DB_Customers!$A:$D,4,0),"❌ Account Not Found")) | C23: =IF(A23="","",IFERROR(VLOOKUP(A23,DB_Customers!$A:$N,14,0),"")) | D23: =IF(A23="","",TODAY()) | G23: =IF(OR(A23="",E23=""),"",IF(C23="","",C23-E23)) | I23: =IF(AND(A23<>"",E23<>""),IF(C23>=E23,"Successful","Unsuccessful"),"—") -> — | J23: =IF(I23="Successful",TEXT(TODAY(),"YYYY-MM-DD")&" Auto","—") -> —
B24: =IF(A24="","",IFERROR(VLOOKUP(A24,DB_Customers!$A:$D,4,0),"❌ Account Not Found")) | C24: =IF(A24="","",IFERROR(VLOOKUP(A24,DB_Customers!$A:$N,14,0),"")) | D24: =IF(A24="","",TODAY()) | G24: =IF(OR(A24="",E24=""),"",IF(C24="","",C24-E24)) | I24: =IF(AND(A24<>"",E24<>""),IF(C24>=E24,"Successful","Unsuccessful"),"—") -> — | J24: =IF(I24="Successful",TEXT(TODAY(),"YYYY-MM-DD")&" Auto","—") -> —
B25: =IF(A25="","",IFERROR(VLOOKUP(A25,DB_Customers!$A:$D,4,0),"❌ Account Not Found")) | C25: =IF(A25="","",IFERROR(VLOOKUP(A25,DB_Customers!$A:$N,14,0),"")) | D25: =IF(A25="","",TODAY()) | G25: =IF(OR(A25="",E25=""),"",IF(C25="","",C25-E25)) | I25: =IF(AND(A25<>"",E25<>""),IF(C25>=E25,"Successful","Unsuccessful"),"—") -> — | J25: =IF(I25="Successful",TEXT(TODAY(),"YYYY-MM-DD")&" Auto","—") -> —
... B208: =IF(A208="","",IFERROR(VLOOKUP(A208,DB_Customers!$A:$D,4,0),"❌ Account Not Found")) | C208: =IF(A208="","",IFERROR(VLOOKUP(A208,DB_Customers!$A:$N,14,0),"")) | D208: =IF(A208="","",TODAY()) | G208: =IF(OR(A208="",E208=""),"",IF(C208="","",C208-E208)) | I208: =IF(AND(A208<>"",E208<>""),IF(C208>=E208,"Successful","Unsuccessful"),"—") -> — | J208: =IF(I208="Successful",TEXT(TODAY(),"YYYY-MM-DD")&" Auto","—") -> —

Sheet Agent02_Loans
A1: 🏦 SAMICIOUS MICROFINANCE — AGENT02 LOAN REQUESTS
A2: Total Repayable = Loan Amount + (Loan Amount × Rate% × Months) | Status: Pending → Approved when credited
A4: 🔢 INSTANT LOAN CALCULATOR
A5: Loan Amount (GHC):
A6: Duration (Months):
A7: Interest Rate (%/m): | B7: 2.5
A8: ━ Total Interest: | B8: =IF(B5="","",B5*B7/100*B6)
A9: ━ Total Repayable: | B9: =IF(B5="","",B5+(B5*B7/100*B6))
A10: ━ Monthly Payment: | B10: =IFERROR(B9/B6,"")
A12: 📋 LOAN REQUEST ENTRIES — Loan ID & Request Date auto-generate | Total Repayable auto-calculated
A13: Loan ID | B13: Account # | C13: Customer Name | D13: Request Date | E13: Loan Amount | F13: Purpose | G13: Months | H13: Rate % | I13: Total Repayable | J13: Monthly Install | K13: Status | L13: Agent | M13: Note
A14: =IF(B14="","",IF(C14="❌ Account Not Found","INVALID","LN"&TEXT(D14,"YYYYMMDD")&TEXT(ROW()-13,"0000"))) -> LN202604140001 | B14: SAM20240200003 | C14: =IF(B14="","",IFERROR(VLOOKUP(B14,DB_Customers!$A:$D,4,0),"❌ Account Not Found")) -> Kofi Boateng | D14: =IF(B14="","",TODAY()) -> 46126 | E14: 7495.94 | F14: School fees | G14: 6 | H14: 2.5 | I14: =IF(E14="","",E14+(E14*H14/100*G14)) -> 8620.331 | J14: =IFERROR(I14/G14,"") -> 1436.7218 | K14: =IF(B14="","","Pending") -> Pending | L14: Agent 02
A15: =IF(B15="","",IF(C15="❌ Account Not Found","INVALID","LN"&TEXT(D15,"YYYYMMDD")&TEXT(ROW()-13,"0000"))) -> LN202604140002 | B15: SAM20240200004 | C15: =IF(B15="","",IFERROR(VLOOKUP(B15,DB_Customers!$A:$D,4,0),"❌ Account Not Found")) -> Abena Owusu | D15: =IF(B15="","",TODAY()) -> 46126 | E15: 7794.4 | F15: School fees | G15: 18 | H15: 2.5 | I15: =IF(E15="","",E15+(E15*H15/100*G15)) -> 11301.88 | J15: =IFERROR(I15/G15,"") -> 627.88222 | K15: =IF(B15="","","Pending") -> Pending | L15: Agent 02
A16: =IF(B16="","",IF(C16="❌ Account Not Found","INVALID","LN"&TEXT(D16,"YYYYMMDD")&TEXT(ROW()-13,"0000"))) | C16: =IF(B16="","",IFERROR(VLOOKUP(B16,DB_Customers!$A:$D,4,0),"❌ Account Not Found")) | D16: =IF(B16="","",TODAY()) | H16: 2.5 | I16: =IF(E16="","",E16+(E16*H16/100*G16)) | J16: =IFERROR(I16/G16,"") | K16: =IF(B16="","","Pending") | L16: Agent 02
A17: =IF(B17="","",IF(C17="❌ Account Not Found","INVALID","LN"&TEXT(D17,"YYYYMMDD")&TEXT(ROW()-13,"0000"))) | C17: =IF(B17="","",IFERROR(VLOOKUP(B17,DB_Customers!$A:$D,4,0),"❌ Account Not Found")) | D17: =IF(B17="","",TODAY()) | H17: 2.5 | I17: =IF(E17="","",E17+(E17*H17/100*G17)) | J17: =IFERROR(I17/G17,"") | K17: =IF(B17="","","Pending") | L17: Agent 02
A18: =IF(B18="","",IF(C18="❌ Account Not Found","INVALID","LN"&TEXT(D18,"YYYYMMDD")&TEXT(ROW()-13,"0000"))) | C18: =IF(B18="","",IFERROR(VLOOKUP(B18,DB_Customers!$A:$D,4,0),"❌ Account Not Found")) | D18: =IF(B18="","",TODAY()) | H18: 2.5 | I18: =IF(E18="","",E18+(E18*H18/100*G18)) | J18: =IFERROR(I18/G18,"") | K18: =IF(B18="","","Pending") | L18: Agent 02
A19: =IF(B19="","",IF(C19="❌ Account Not Found","INVALID","LN"&TEXT(D19,"YYYYMMDD")&TEXT(ROW()-13,"0000"))) | C19: =IF(B19="","",IFERROR(VLOOKUP(B19,DB_Customers!$A:$D,4,0),"❌ Account Not Found")) | D19: =IF(B19="","",TODAY()) | H19: 2.5 | I19: =IF(E19="","",E19+(E19*H19/100*G19)) | J19: =IFERROR(I19/G19,"") | K19: =IF(B19="","","Pending")
A20: =IF(B20="","",IF(C20="❌ Account Not Found","INVALID","LN"&TEXT(D20,"YYYYMMDD")&TEXT(ROW()-13,"0000"))) | C20: =IF(B20="","",IFERROR(VLOOKUP(B20,DB_Customers!$A:$D,4,0),"❌ Account Not Found")) | D20: =IF(B20="","",TODAY()) | H20: 2.5 | I20: =IF(E20="","",E20+(E20*H20/100*G20)) | J20: =IFERROR(I20/G20,"") | K20: =IF(B20="","","Pending")
A21: =IF(B21="","",IF(C21="❌ Account Not Found","INVALID","LN"&TEXT(D21,"YYYYMMDD")&TEXT(ROW()-13,"0000"))) | C21: =IF(B21="","",IFERROR(VLOOKUP(B21,DB_Customers!$A:$D,4,0),"❌ Account Not Found")) | D21: =IF(B21="","",TODAY()) | H21: 2.5 | I21: =IF(E21="","",E21+(E21*H21/100*G21)) | J21: =IFERROR(I21/G21,"") | K21: =IF(B21="","","Pending")
A22: =IF(B22="","",IF(C22="❌ Account Not Found","INVALID","LN"&TEXT(D22,"YYYYMMDD")&TEXT(ROW()-13,"0000"))) | C22: =IF(B22="","",IFERROR(VLOOKUP(B22,DB_Customers!$A:$D,4,0),"❌ Account Not Found")) | D22: =IF(B22="","",TODAY()) | H22: 2.5 | I22: =IF(E22="","",E22+(E22*H22/100*G22)) | J22: =IFERROR(I22/G22,"") | K22: =IF(B22="","","Pending")
A23: =IF(B23="","",IF(C23="❌ Account Not Found","INVALID","LN"&TEXT(D23,"YYYYMMDD")&TEXT(ROW()-13,"0000"))) | C23: =IF(B23="","",IFERROR(VLOOKUP(B23,DB_Customers!$A:$D,4,0),"❌ Account Not Found")) | D23: =IF(B23="","",TODAY()) | H23: 2.5 | I23: =IF(E23="","",E23+(E23*H23/100*G23)) | J23: =IFERROR(I23/G23,"") | K23: =IF(B23="","","Pending")
A24: =IF(B24="","",IF(C24="❌ Account Not Found","INVALID","LN"&TEXT(D24,"YYYYMMDD")&TEXT(ROW()-13,"0000"))) | C24: =IF(B24="","",IFERROR(VLOOKUP(B24,DB_Customers!$A:$D,4,0),"❌ Account Not Found")) | D24: =IF(B24="","",TODAY()) | H24: 2.5 | I24: =IF(E24="","",E24+(E24*H24/100*G24)) | J24: =IFERROR(I24/G24,"") | K24: =IF(B24="","","Pending")
A25: =IF(B25="","",IF(C25="❌ Account Not Found","INVALID","LN"&TEXT(D25,"YYYYMMDD")&TEXT(ROW()-13,"0000"))) | C25: =IF(B25="","",IFERROR(VLOOKUP(B25,DB_Customers!$A:$D,4,0),"❌ Account Not Found")) | D25: =IF(B25="","",TODAY()) | H25: 2.5 | I25: =IF(E25="","",E25+(E25*H25/100*G25)) | J25: =IFERROR(I25/G25,"") | K25: =IF(B25="","","Pending")
A26: =IF(B26="","",IF(C26="❌ Account Not Found","INVALID","LN"&TEXT(D26,"YYYYMMDD")&TEXT(ROW()-13,"0000"))) | C26: =IF(B26="","",IFERROR(VLOOKUP(B26,DB_Customers!$A:$D,4,0),"❌ Account Not Found")) | D26: =IF(B26="","",TODAY()) | H26: 2.5 | I26: =IF(E26="","",E26+(E26*H26/100*G26)) | J26: =IFERROR(I26/G26,"") | K26: =IF(B26="","","Pending")
A27: =IF(B27="","",IF(C27="❌ Account Not Found","INVALID","LN"&TEXT(D27,"YYYYMMDD")&TEXT(ROW()-13,"0000"))) | C27: =IF(B27="","",IFERROR(VLOOKUP(B27,DB_Customers!$A:$D,4,0),"❌ Account Not Found")) | D27: =IF(B27="","",TODAY()) | H27: 2.5 | I27: =IF(E27="","",E27+(E27*H27/100*G27)) | J27: =IFERROR(I27/G27,"") | K27: =IF(B27="","","Pending")
A28: =IF(B28="","",IF(C28="❌ Account Not Found","INVALID","LN"&TEXT(D28,"YYYYMMDD")&TEXT(ROW()-13,"0000"))) | C28: =IF(B28="","",IFERROR(VLOOKUP(B28,DB_Customers!$A:$D,4,0),"❌ Account Not Found")) | D28: =IF(B28="","",TODAY()) | H28: 2.5 | I28: =IF(E28="","",E28+(E28*H28/100*G28)) | J28: =IFERROR(I28/G28,"") | K28: =IF(B28="","","Pending")
A29: =IF(B29="","",IF(C29="❌ Account Not Found","INVALID","LN"&TEXT(D29,"YYYYMMDD")&TEXT(ROW()-13,"0000"))) | C29: =IF(B29="","",IFERROR(VLOOKUP(B29,DB_Customers!$A:$D,4,0),"❌ Account Not Found")) | D29: =IF(B29="","",TODAY()) | H29: 2.5 | I29: =IF(E29="","",E29+(E29*H29/100*G29)) | J29: =IFERROR(I29/G29,"") | K29: =IF(B29="","","Pending")
A30: =IF(B30="","",IF(C30="❌ Account Not Found","INVALID","LN"&TEXT(D30,"YYYYMMDD")&TEXT(ROW()-13,"0000"))) | C30: =IF(B30="","",IFERROR(VLOOKUP(B30,DB_Customers!$A:$D,4,0),"❌ Account Not Found")) | D30: =IF(B30="","",TODAY()) | H30: 2.5 | I30: =IF(E30="","",E30+(E30*H30/100*G30)) | J30: =IFERROR(I30/G30,"") | K30: =IF(B30="","","Pending")
... A113: =IF(B113="","",IF(C113="❌ Account Not Found","INVALID","LN"&TEXT(D113,"YYYYMMDD")&TEXT(ROW()-13,"0000"))) | C113: =IF(B113="","",IFERROR(VLOOKUP(B113,DB_Customers!$A:$D,4,0),"❌ Account Not Found")) | D113: =IF(B113="","",TODAY()) | H113: 2.5 | I113: =IF(E113="","",E113+(E113*H113/100*G113)) | J113: =IFERROR(I113/G113,"") | K113: =IF(B113="","","Pending")

Sheet Agent03_Savings
A1: 💰 SAMICIOUS MICROFINANCE — AGENT03 SAVINGS
A2: Agent: Agent 03 | Enter Account # → All fields auto-populate | Status auto-sets to "Saved"
A3: 💰 Total Collected Today | D3: 📊 Transactions Today | G3: 📅 Date | J3: 🎯 Daily Target
A4: =SUMIFS(DB_Savings!$F:$F,DB_Savings!$G:$G,"Agent 03",DB_Savings!$E:$E,TODAY()) -> 0 | D4: =COUNTIFS(DB_Savings!$G:$G,"Agent 03",DB_Savings!$E:$E,TODAY()) -> 0 | G4: =TEXT(TODAY(),"DDDD, DD MMMM YYYY") -> Tuesday, 14 April 2026 | J4: 5000
A5: =IF(SUMIFS(DB_Savings!$F:$F,DB_Savings!$G:$G,"Agent 03",DB_Savings!$E:$E,TODAY())>=J4,"✅ DAILY TARGET ACHIEVED! Well done Agent 03!","⏳ Collection in progress — Keep going! Remaining: GHC "&TEXT(J4-SUMIFS(DB_Savings!$F:$F,DB_Savings!$G:$G,"Agent 03",DB_Savings!$E:$E,TODAY()),"#,##0.00")) -> ⏳ Collection in progress — Keep going! Remaining: GHC 5,000.00
A7: 📝 ENTRY FORM — Enter Account Number in column A. All other fields auto-populate. Enter Savings Amount in column E then Tab to complete.
A8: Account # | B8: Customer Name | C8: Current Balance | D8: Date | E8: Savings Amount | F8: New Balance | G8: Agent | H8: Status | I8: Saved At | J8: Notes
A9: SAM20240200005 | B9: =IF(A9="","",IFERROR(VLOOKUP(A9,DB_Customers!$A:$D,4,0),"❌ Account Not Found")) -> Yaw Darko | C9: =IF(A9="","",IFERROR(VLOOKUP(A9,DB_Customers!$A:$N,14,0),"")) -> 3825.72 | D9: =IF(A9="","",TODAY()) -> 46126 | E9: 158.46 | F9: =IF(OR(A9="",E9=""),"",IF(C9="","",C9+E9)) -> 3984.18 | G9: Agent 03 | H9: =IF(AND(A9<>"",E9<>"",G9<>""),"Saved","Pending") -> Saved | I9: =IF(H9="Saved",TEXT(TODAY(),"YYYY-MM-DD")&" Auto","—") -> 2026-04-14 Auto
A10: SAM20240300006 | B10: =IF(A10="","",IFERROR(VLOOKUP(A10,DB_Customers!$A:$D,4,0),"❌ Account Not Found")) -> Efua Kumi | C10: =IF(A10="","",IFERROR(VLOOKUP(A10,DB_Customers!$A:$N,14,0),"")) -> 1244.27 | D10: =IF(A10="","",TODAY()) -> 46126 | E10: 284.79 | F10: =IF(OR(A10="",E10=""),"",IF(C10="","",C10+E10)) -> 1529.06 | G10: Agent 03 | H10: =IF(AND(A10<>"",E10<>"",G10<>""),"Saved","Pending") -> Saved | I10: =IF(H10="Saved",TEXT(TODAY(),"YYYY-MM-DD")&" Auto","—") -> 2026-04-14 Auto
B11: =IF(A11="","",IFERROR(VLOOKUP(A11,DB_Customers!$A:$D,4,0),"❌ Account Not Found")) | C11: =IF(A11="","",IFERROR(VLOOKUP(A11,DB_Customers!$A:$N,14,0),"")) | D11: =IF(A11="","",TODAY()) | F11: =IF(OR(A11="",E11=""),"",IF(C11="","",C11+E11)) | G11: Agent 03 | H11: =IF(AND(A11<>"",E11<>"",G11<>""),"Saved","Pending") -> Pending | I11: =IF(H11="Saved",TEXT(TODAY(),"YYYY-MM-DD")&" Auto","—") -> —
B12: =IF(A12="","",IFERROR(VLOOKUP(A12,DB_Customers!$A:$D,4,0),"❌ Account Not Found")) | C12: =IF(A12="","",IFERROR(VLOOKUP(A12,DB_Customers!$A:$N,14,0),"")) | D12: =IF(A12="","",TODAY()) | F12: =IF(OR(A12="",E12=""),"",IF(C12="","",C12+E12)) | G12: Agent 03 | H12: =IF(AND(A12<>"",E12<>"",G12<>""),"Saved","Pending") -> Pending | I12: =IF(H12="Saved",TEXT(TODAY(),"YYYY-MM-DD")&" Auto","—") -> —
B13: =IF(A13="","",IFERROR(VLOOKUP(A13,DB_Customers!$A:$D,4,0),"❌ Account Not Found")) | C13: =IF(A13="","",IFERROR(VLOOKUP(A13,DB_Customers!$A:$N,14,0),"")) | D13: =IF(A13="","",TODAY()) | F13: =IF(OR(A13="",E13=""),"",IF(C13="","",C13+E13)) | G13: Agent 03 | H13: =IF(AND(A13<>"",E13<>"",G13<>""),"Saved","Pending") -> Pending | I13: =IF(H13="Saved",TEXT(TODAY(),"YYYY-MM-DD")&" Auto","—") -> —
B14: =IF(A14="","",IFERROR(VLOOKUP(A14,DB_Customers!$A:$D,4,0),"❌ Account Not Found")) | C14: =IF(A14="","",IFERROR(VLOOKUP(A14,DB_Customers!$A:$N,14,0),"")) | D14: =IF(A14="","",TODAY()) | F14: =IF(OR(A14="",E14=""),"",IF(C14="","",C14+E14)) | H14: =IF(AND(A14<>"",E14<>"",G14<>""),"Saved","Pending") -> Pending | I14: =IF(H14="Saved",TEXT(TODAY(),"YYYY-MM-DD")&" Auto","—") -> —
B15: =IF(A15="","",IFERROR(VLOOKUP(A15,DB_Customers!$A:$D,4,0),"❌ Account Not Found")) | C15: =IF(A15="","",IFERROR(VLOOKUP(A15,DB_Customers!$A:$N,14,0),"")) | D15: =IF(A15="","",TODAY()) | F15: =IF(OR(A15="",E15=""),"",IF(C15="","",C15+E15)) | H15: =IF(AND(A15<>"",E15<>"",G15<>""),"Saved","Pending") -> Pending | I15: =IF(H15="Saved",TEXT(TODAY(),"YYYY-MM-DD")&" Auto","—") -> —
B16: =IF(A16="","",IFERROR(VLOOKUP(A16,DB_Customers!$A:$D,4,0),"❌ Account Not Found")) | C16: =IF(A16="","",IFERROR(VLOOKUP(A16,DB_Customers!$A:$N,14,0),"")) | D16: =IF(A16="","",TODAY()) | F16: =IF(OR(A16="",E16=""),"",IF(C16="","",C16+E16)) | H16: =IF(AND(A16<>"",E16<>"",G16<>""),"Saved","Pending") -> Pending | I16: =IF(H16="Saved",TEXT(TODAY(),"YYYY-MM-DD")&" Auto","—") -> —
B17: =IF(A17="","",IFERROR(VLOOKUP(A17,DB_Customers!$A:$D,4,0),"❌ Account Not Found")) | C17: =IF(A17="","",IFERROR(VLOOKUP(A17,DB_Customers!$A:$N,14,0),"")) | D17: =IF(A17="","",TODAY()) | F17: =IF(OR(A17="",E17=""),"",IF(C17="","",C17+E17)) | H17: =IF(AND(A17<>"",E17<>"",G17<>""),"Saved","Pending") -> Pending | I17: =IF(H17="Saved",TEXT(TODAY(),"YYYY-MM-DD")&" Auto","—") -> —
B18: =IF(A18="","",IFERROR(VLOOKUP(A18,DB_Customers!$A:$D,4,0),"❌ Account Not Found")) | C18: =IF(A18="","",IFERROR(VLOOKUP(A18,DB_Customers!$A:$N,14,0),"")) | D18: =IF(A18="","",TODAY()) | F18: =IF(OR(A18="",E18=""),"",IF(C18="","",C18+E18)) | H18: =IF(AND(A18<>"",E18<>"",G18<>""),"Saved","Pending") -> Pending | I18: =IF(H18="Saved",TEXT(TODAY(),"YYYY-MM-DD")&" Auto","—") -> —
