Workbook

Sheet 🏠 DASHBOARD
A1: 🏦 SAMICIOUS MICROFINANCE ENTERPRISE v16.0
A2: =TEXT(TODAY(),"dddd, mmmm d, yyyy")&" | 10-Agent | Formula-Only | Zero VBA | " -> Saturday, April 25, 2026 | 10-Agent | Formula-Only | Zero VBA |
B4: TOTAL SAVINGS (GHS) | D4: TOTAL WITHDRAWALS | F4: CUSTOMERS | H4: LOAN PORTFOLIO | J4: TOP-UPS
B5: =IFERROR(SUM(DB_Savings!F:F),0) -> 0 | D5: =IFERROR(SUM(DB_Withdrawals!G:G),0) -> 0 | F5: =IFERROR(COUNTA(DB_Customers!A:A)-3,0) -> 500 | H5: =IFERROR(SUM(DB_Loans!E:E),0) -> 0 | J5: =IFERROR(COUNTA('LOAN TOPUP'!B:B)-4,0) -> -3
A6: 🟡 YELLOW = Enter your data | 🔵 BLUE = Auto-computed — DO NOT EDIT | 🔒 WRONG CODE = Agent code mismatch — check code in System_Config
B7: 📋 NEW ACCOUNT | D7: 🗄️ DATABASE | F7: 🏦 MANAGER DASHBOARD | H7: 📊 REPORTS | J7: 🔗 LOAN TOP-UP
B8: 💰 SAVINGS DB | D8: 🏧 WITHDRAWALS DB | F8: 🏦 LOANS DB | H8: ⚙️ SYSTEM CONFIG | J8: 👥 AGENTS DB
A10: ⚡ FULLY AUTOMATED • 10 Agents • 4-Digit Code Security (FIXED BUG v16) • GHS 10 Min Balance • Real-Time DB Sync • Multi-Year • 🔵 Blue = System-Controlled • 🟡 Yellow = User Input • Zero VBA

Sheet DEVELOPER
A1: 🏦 SAMICIOUS MICROFINANCE
A2: ENTERPRISE MANAGEMENT SYSTEM | Developer Information
A4: ABOUT THE DEVELOPER
A6: THIS SAMICIOUS MICROFINANCE MANAGEMENT SYSTEM WAS DESIGNED AND DEVELOPED BY
A7: FRANK ABBAN
A8: IT CONSULTANT
A10: 📞 FOR ALL ENQUIRIES, KINDLY REACH OUT USING ANY OF THE CONTACT NUMBERS BELOW:
A12: 📱 0241911273
A14: 📱 0207530771
A16: 📋 Select any number above → Ctrl+C to copy
A20: SAMICIOUS MICROFINANCE v16.0 | Formula-Driven Architecture | No VBA

Sheet ACKNOWLEDGEMENT
A1: 🏦 SAMICIOUS MICROFINANCE
A2: ENTERPRISE MANAGEMENT SYSTEM | Official Documentation
A4: ACKNOWLEDGEMENT
B6: I give all glory to the Almighty God for His grace, strength, and wisdom that have guided me throughout this journey. Without Him, this work would not have been possible.
B8: I sincerely appreciate Dr. Gabriel Annan, Lecturer at the University of Cape Coast (UCC), for his mentorship, guidance, and invaluable support throughout the development of this system.
B10: I am deeply grateful to Rev. Ebenezer Asibu Dadzie for his spiritual guidance, encouragement, and prayers, which strengthened me greatly.
B12: Special thanks to Mr. Addu Gyamfi, CEO of Samicious Microfinance, for his trust and confidence in my ability to serve as the IT Consultant for this project.
B14: To my beloved wife and children, your patience, sacrifices, and unwavering support have been invaluable. Your love continues to inspire me.
B16: Through your collective support, this vision has been successfully realized.
A18: 📖 BIBLICAL SUPPORT
B20: "I can do all things through Christ who strengthens me."
B22: — Philippians 4:13
A24: A M E N

Sheet 🏦 MANAGER DASHBOARD
A1: 🏦 SAMICIOUS MICROFINANCE — MANAGER COMMAND CENTER v16.0
A2: =UPPER(TEXT(TODAY(),"DDDD, DD MMMM YYYY"))&" | 10 Agents | Real-Time | Formula Engine | Zero VBA" -> SATURDAY, 25 APRIL 2026 | 10 Agents | Real-Time | Formula Engine | Zero VBA
B4: TOTAL SAVINGS (GHS) | D4: TOTAL WITHDRAWALS | F4: NET FLOW (GHS) | H4: CUSTOMERS | J4: LOAN PORTFOLIO | L4: ACTIVE TOP-UPS
B5: =IFERROR(SUM(DB_Savings!$F:$F),0) -> 0 | D5: =IFERROR(SUM(DB_Withdrawals!$G:$G),0) -> 0 | F5: =B5-D5 -> 0 | H5: =IFERROR(COUNTA(DB_Customers!A:A)-3,0) -> 500 | J5: =IFERROR(SUM(DB_Loans!$E:$E),0) -> 0 | L5: =IFERROR(COUNTA('LOAN TOPUP'!B:B)-4,0) -> -3
A7: 📊 REAL-TIME AGENT PERFORMANCE TRACKER
A8: Agent | B8: Today Savings | C8: Today Withdrawals | D8: Net Today | E8: Txns Today | F8: MTD Savings | G8: Active Customers | H8: Target | I8: % Target
A9: Agent 01 | B9: =IFERROR(SUMIFS(DB_Savings!$F:$F,DB_Savings!$D:$D,"Agent 01",DB_Savings!$E:$E,TODAY()),0) -> 0 | C9: =IFERROR(SUMIFS(DB_Withdrawals!$G:$G,DB_Withdrawals!$I:$I,"Agent 01",DB_Withdrawals!$E:$E,TODAY()),0) -> 0 | D9: =B9-C9 -> 0 | E9: =IFERROR(COUNTIFS(DB_Savings!$D:$D,"Agent 01",DB_Savings!$E:$E,TODAY()),0) -> 0 | F9: =IFERROR(SUMIF(DB_Savings!$D:$D,"Agent 01",DB_Savings!$F:$F),0) -> 0 | G9: =IFERROR(COUNTIF(DB_Customers!$G:$G,"Agent 01"),0) -> 0 | H9: 5000 | I9: =IFERROR(B9/H9,0) -> 0
A10: Agent 02 | B10: =IFERROR(SUMIFS(DB_Savings!$F:$F,DB_Savings!$D:$D,"Agent 02",DB_Savings!$E:$E,TODAY()),0) -> 0 | C10: =IFERROR(SUMIFS(DB_Withdrawals!$G:$G,DB_Withdrawals!$I:$I,"Agent 02",DB_Withdrawals!$E:$E,TODAY()),0) -> 0 | D10: =B10-C10 -> 0 | E10: =IFERROR(COUNTIFS(DB_Savings!$D:$D,"Agent 02",DB_Savings!$E:$E,TODAY()),0) -> 0 | F10: =IFERROR(SUMIF(DB_Savings!$D:$D,"Agent 02",DB_Savings!$F:$F),0) -> 0 | G10: =IFERROR(COUNTIF(DB_Customers!$G:$G,"Agent 02"),0) -> 0 | H10: 5000 | I10: =IFERROR(B10/H10,0) -> 0
A11: Agent 03 | B11: =IFERROR(SUMIFS(DB_Savings!$F:$F,DB_Savings!$D:$D,"Agent 03",DB_Savings!$E:$E,TODAY()),0) -> 0 | C11: =IFERROR(SUMIFS(DB_Withdrawals!$G:$G,DB_Withdrawals!$I:$I,"Agent 03",DB_Withdrawals!$E:$E,TODAY()),0) -> 0 | D11: =B11-C11 -> 0 | E11: =IFERROR(COUNTIFS(DB_Savings!$D:$D,"Agent 03",DB_Savings!$E:$E,TODAY()),0) -> 0 | F11: =IFERROR(SUMIF(DB_Savings!$D:$D,"Agent 03",DB_Savings!$F:$F),0) -> 0 | G11: =IFERROR(COUNTIF(DB_Customers!$G:$G,"Agent 03"),0) -> 0 | H11: 5000 | I11: =IFERROR(B11/H11,0) -> 0
A12: Agent 04 | B12: =IFERROR(SUMIFS(DB_Savings!$F:$F,DB_Savings!$D:$D,"Agent 04",DB_Savings!$E:$E,TODAY()),0) -> 0 | C12: =IFERROR(SUMIFS(DB_Withdrawals!$G:$G,DB_Withdrawals!$I:$I,"Agent 04",DB_Withdrawals!$E:$E,TODAY()),0) -> 0 | D12: =B12-C12 -> 0 | E12: =IFERROR(COUNTIFS(DB_Savings!$D:$D,"Agent 04",DB_Savings!$E:$E,TODAY()),0) -> 0 | F12: =IFERROR(SUMIF(DB_Savings!$D:$D,"Agent 04",DB_Savings!$F:$F),0) -> 0 | G12: =IFERROR(COUNTIF(DB_Customers!$G:$G,"Agent 04"),0) -> 0 | H12: 5000 | I12: =IFERROR(B12/H12,0) -> 0
A13: Agent 05 | B13: =IFERROR(SUMIFS(DB_Savings!$F:$F,DB_Savings!$D:$D,"Agent 05",DB_Savings!$E:$E,TODAY()),0) -> 0 | C13: =IFERROR(SUMIFS(DB_Withdrawals!$G:$G,DB_Withdrawals!$I:$I,"Agent 05",DB_Withdrawals!$E:$E,TODAY()),0) -> 0 | D13: =B13-C13 -> 0 | E13: =IFERROR(COUNTIFS(DB_Savings!$D:$D,"Agent 05",DB_Savings!$E:$E,TODAY()),0) -> 0 | F13: =IFERROR(SUMIF(DB_Savings!$D:$D,"Agent 05",DB_Savings!$F:$F),0) -> 0 | G13: =IFERROR(COUNTIF(DB_Customers!$G:$G,"Agent 05"),0) -> 0 | H13: 5000 | I13: =IFERROR(B13/H13,0) -> 0
A14: Agent 06 | B14: =IFERROR(SUMIFS(DB_Savings!$F:$F,DB_Savings!$D:$D,"Agent 06",DB_Savings!$E:$E,TODAY()),0) -> 0 | C14: =IFERROR(SUMIFS(DB_Withdrawals!$G:$G,DB_Withdrawals!$I:$I,"Agent 06",DB_Withdrawals!$E:$E,TODAY()),0) -> 0 | D14: =B14-C14 -> 0 | E14: =IFERROR(COUNTIFS(DB_Savings!$D:$D,"Agent 06",DB_Savings!$E:$E,TODAY()),0) -> 0 | F14: =IFERROR(SUMIF(DB_Savings!$D:$D,"Agent 06",DB_Savings!$F:$F),0) -> 0 | G14: =IFERROR(COUNTIF(DB_Customers!$G:$G,"Agent 06"),0) -> 0 | H14: 5000 | I14: =IFERROR(B14/H14,0) -> 0
A15: Agent 07 | B15: =IFERROR(SUMIFS(DB_Savings!$F:$F,DB_Savings!$D:$D,"Agent 07",DB_Savings!$E:$E,TODAY()),0) -> 0 | C15: =IFERROR(SUMIFS(DB_Withdrawals!$G:$G,DB_Withdrawals!$I:$I,"Agent 07",DB_Withdrawals!$E:$E,TODAY()),0) -> 0 | D15: =B15-C15 -> 0 | E15: =IFERROR(COUNTIFS(DB_Savings!$D:$D,"Agent 07",DB_Savings!$E:$E,TODAY()),0) -> 0 | F15: =IFERROR(SUMIF(DB_Savings!$D:$D,"Agent 07",DB_Savings!$F:$F),0) -> 0 | G15: =IFERROR(COUNTIF(DB_Customers!$G:$G,"Agent 07"),0) -> 0 | H15: 5000 | I15: =IFERROR(B15/H15,0) -> 0
A16: Agent 08 | B16: =IFERROR(SUMIFS(DB_Savings!$F:$F,DB_Savings!$D:$D,"Agent 08",DB_Savings!$E:$E,TODAY()),0) -> 0 | C16: =IFERROR(SUMIFS(DB_Withdrawals!$G:$G,DB_Withdrawals!$I:$I,"Agent 08",DB_Withdrawals!$E:$E,TODAY()),0) -> 0 | D16: =B16-C16 -> 0 | E16: =IFERROR(COUNTIFS(DB_Savings!$D:$D,"Agent 08",DB_Savings!$E:$E,TODAY()),0) -> 0 | F16: =IFERROR(SUMIF(DB_Savings!$D:$D,"Agent 08",DB_Savings!$F:$F),0) -> 0 | G16: =IFERROR(COUNTIF(DB_Customers!$G:$G,"Agent 08"),0) -> 0 | H16: 5000 | I16: =IFERROR(B16/H16,0) -> 0
A17: Agent 09 | B17: =IFERROR(SUMIFS(DB_Savings!$F:$F,DB_Savings!$D:$D,"Agent 09",DB_Savings!$E:$E,TODAY()),0) -> 0 | C17: =IFERROR(SUMIFS(DB_Withdrawals!$G:$G,DB_Withdrawals!$I:$I,"Agent 09",DB_Withdrawals!$E:$E,TODAY()),0) -> 0 | D17: =B17-C17 -> 0 | E17: =IFERROR(COUNTIFS(DB_Savings!$D:$D,"Agent 09",DB_Savings!$E:$E,TODAY()),0) -> 0 | F17: =IFERROR(SUMIF(DB_Savings!$D:$D,"Agent 09",DB_Savings!$F:$F),0) -> 0 | G17: =IFERROR(COUNTIF(DB_Customers!$G:$G,"Agent 09"),0) -> 0 | H17: 5000 | I17: =IFERROR(B17/H17,0) -> 0
A18: Agent 10 | B18: =IFERROR(SUMIFS(DB_Savings!$F:$F,DB_Savings!$D:$D,"Agent 10",DB_Savings!$E:$E,TODAY()),0) -> 0 | C18: =IFERROR(SUMIFS(DB_Withdrawals!$G:$G,DB_Withdrawals!$I:$I,"Agent 10",DB_Withdrawals!$E:$E,TODAY()),0) -> 0 | D18: =B18-C18 -> 0 | E18: =IFERROR(COUNTIFS(DB_Savings!$D:$D,"Agent 10",DB_Savings!$E:$E,TODAY()),0) -> 0 | F18: =IFERROR(SUMIF(DB_Savings!$D:$D,"Agent 10",DB_Savings!$F:$F),0) -> 0 | G18: =IFERROR(COUNTIF(DB_Customers!$G:$G,"Agent 10"),0) -> 0 | H18: 5000 | I18: =IFERROR(B18/H18,0) -> 0
A19: TOTALS | B19: =SUM(B9:B18) -> 0 | C19: =SUM(C9:C18) -> 0 | D19: =SUM(D9:D18) -> 0 | E19: =SUM(E9:E18) -> 0 | F19: =SUM(F9:F18) -> 0 | G19: =SUM(G9:G18) -> 0 | H19: =SUM(H9:H18) -> 50000 | I19: =IFERROR(B19/H19,0) -> 0

Sheet NEW ACCOUNT
A1: 👤 NEW CUSTOMER ACCOUNT REGISTRATION
A2: ✅ AUTOMATED — Type customer details in 🟡 YELLOW cells. Account Number (col A) and Date (col I) are 🔵 BLUE = auto-generated. DATABASE reads this table live. No copy-paste. No buttons.
A3: ⚠️ GHS 10.00 MINIMUM OPENING BALANCE ENFORCED | Accounts below GHS 10 are flagged ⚠️ Below Min Balance
A4: Account No. | B4: Customer Name | C4: Date of Birth | D4: Phone Number | E4: Location | F4: Occupation | G4: Assigned Agent | H4: Opening Balance (GHS) | I4: Date Registered | J4: Status
A5: =IF(B5="","","ACC"&TEXT(ROW()-4,"0000")) | I5: =IF(B5="","",TEXT(TODAY(),"dd/mm/yyyy")) | J5: =IF(B5="","",IF(ISNUMBER(H5),IF(H5>=10,"✅ Active","⚠️ Below Min Balance"),"Pending"))
A6: =IF(B6="","","ACC"&TEXT(ROW()-4,"0000")) | I6: =IF(B6="","",TEXT(TODAY(),"dd/mm/yyyy")) | J6: =IF(B6="","",IF(ISNUMBER(H6),IF(H6>=10,"✅ Active","⚠️ Below Min Balance"),"Pending"))
A7: =IF(B7="","","ACC"&TEXT(ROW()-4,"0000")) | I7: =IF(B7="","",TEXT(TODAY(),"dd/mm/yyyy")) | J7: =IF(B7="","",IF(ISNUMBER(H7),IF(H7>=10,"✅ Active","⚠️ Below Min Balance"),"Pending"))
A8: =IF(B8="","","ACC"&TEXT(ROW()-4,"0000")) | I8: =IF(B8="","",TEXT(TODAY(),"dd/mm/yyyy")) | J8: =IF(B8="","",IF(ISNUMBER(H8),IF(H8>=10,"✅ Active","⚠️ Below Min Balance"),"Pending"))
A9: =IF(B9="","","ACC"&TEXT(ROW()-4,"0000")) | I9: =IF(B9="","",TEXT(TODAY(),"dd/mm/yyyy")) | J9: =IF(B9="","",IF(ISNUMBER(H9),IF(H9>=10,"✅ Active","⚠️ Below Min Balance"),"Pending"))
A10: =IF(B10="","","ACC"&TEXT(ROW()-4,"0000")) | I10: =IF(B10="","",TEXT(TODAY(),"dd/mm/yyyy")) | J10: =IF(B10="","",IF(ISNUMBER(H10),IF(H10>=10,"✅ Active","⚠️ Below Min Balance"),"Pending"))
A11: =IF(B11="","","ACC"&TEXT(ROW()-4,"0000")) | I11: =IF(B11="","",TEXT(TODAY(),"dd/mm/yyyy")) | J11: =IF(B11="","",IF(ISNUMBER(H11),IF(H11>=10,"✅ Active","⚠️ Below Min Balance"),"Pending"))
A12: =IF(B12="","","ACC"&TEXT(ROW()-4,"0000")) | I12: =IF(B12="","",TEXT(TODAY(),"dd/mm/yyyy")) | J12: =IF(B12="","",IF(ISNUMBER(H12),IF(H12>=10,"✅ Active","⚠️ Below Min Balance"),"Pending"))
A13: =IF(B13="","","ACC"&TEXT(ROW()-4,"0000")) | I13: =IF(B13="","",TEXT(TODAY(),"dd/mm/yyyy")) | J13: =IF(B13="","",IF(ISNUMBER(H13),IF(H13>=10,"✅ Active","⚠️ Below Min Balance"),"Pending"))
A14: =IF(B14="","","ACC"&TEXT(ROW()-4,"0000")) | I14: =IF(B14="","",TEXT(TODAY(),"dd/mm/yyyy")) | J14: =IF(B14="","",IF(ISNUMBER(H14),IF(H14>=10,"✅ Active","⚠️ Below Min Balance"),"Pending"))
A15: =IF(B15="","","ACC"&TEXT(ROW()-4,"0000")) | I15: =IF(B15="","",TEXT(TODAY(),"dd/mm/yyyy")) | J15: =IF(B15="","",IF(ISNUMBER(H15),IF(H15>=10,"✅ Active","⚠️ Below Min Balance"),"Pending"))
A16: =IF(B16="","","ACC"&TEXT(ROW()-4,"0000")) | I16: =IF(B16="","",TEXT(TODAY(),"dd/mm/yyyy")) | J16: =IF(B16="","",IF(ISNUMBER(H16),IF(H16>=10,"✅ Active","⚠️ Below Min Balance"),"Pending"))
... A504: =IF(B504="","","ACC"&TEXT(ROW()-4,"0000")) | I504: =IF(B504="","",TEXT(TODAY(),"dd/mm/yyyy")) | J504: =IF(B504="","",IF(ISNUMBER(H504),IF(H504>=10,"✅ Active","⚠️ Below Min Balance"),"Pending"))
A506: 🟡 Yellow = Enter data here | 🔵 Blue = Auto-generated (DO NOT EDIT)

Sheet DB_Customers
A1: 🗄️ CUSTOMER DATABASE — Central Source of Truth (All columns formula-driven, READ-ONLY)
A2: 🔵 ALL CELLS AUTO-COMPUTED — Do NOT type here. Columns A–J mirror NEW ACCOUNT. Columns K–N computed from all transactions.
A3: Account No. | B3: Full Name | C3: Date of Birth | D3: Phone Number | E3: Location | F3: Occupation | G3: Assigned Agent | H3: Opening Balance (GHS) | I3: Date Registered | J3: Status | K3: Total Savings (GHS) | L3: Total Withdrawals (GHS) | M3: Current Balance (GHS) | N3: Withdrawable Balance (GHS)
A4: ='NEW ACCOUNT'!A5 | B4: =IF('NEW ACCOUNT'!A5="","",'NEW ACCOUNT'!B5) | C4: =IF('NEW ACCOUNT'!A5="","",'NEW ACCOUNT'!C5) | D4: =IF('NEW ACCOUNT'!A5="","",'NEW ACCOUNT'!D5) | E4: =IF('NEW ACCOUNT'!A5="","",'NEW ACCOUNT'!E5) | F4: =IF('NEW ACCOUNT'!A5="","",'NEW ACCOUNT'!F5) | G4: =IF('NEW ACCOUNT'!A5="","",'NEW ACCOUNT'!G5) | H4: =IF('NEW ACCOUNT'!A5="","",'NEW ACCOUNT'!H5) | I4: =IF('NEW ACCOUNT'!A5="","",'NEW ACCOUNT'!I5) | J4: =IF('NEW ACCOUNT'!A5="","",'NEW ACCOUNT'!J5) | K4: =IFERROR(IF(A4="","",SUMIF(DB_Savings!$A:$A,A4,DB_Savings!$F:$F)),"") | L4: =IFERROR(IF(A4="","",SUMIF(DB_Withdrawals!$A:$A,A4,DB_Withdrawals!$G:$G)),"") | M4: =IFERROR(IF(A4="","",IFERROR(VALUE(H4),0)+IFERROR(SUMIF(DB_Savings!$A:$A,A4,DB_Savings!$F:$F),0)-IFERROR(SUMIF(DB_Withdrawals!$A:$A,A4,DB_Withdrawals!$G:$G),0)),"") | N4: =IFERROR(IF(A4="","",MAX(0,M4-System_Config!$B$9)),"")
A5: ='NEW ACCOUNT'!A6 | B5: =IF('NEW ACCOUNT'!A6="","",'NEW ACCOUNT'!B6) | C5: =IF('NEW ACCOUNT'!A6="","",'NEW ACCOUNT'!C6) | D5: =IF('NEW ACCOUNT'!A6="","",'NEW ACCOUNT'!D6) | E5: =IF('NEW ACCOUNT'!A6="","",'NEW ACCOUNT'!E6) | F5: =IF('NEW ACCOUNT'!A6="","",'NEW ACCOUNT'!F6) | G5: =IF('NEW ACCOUNT'!A6="","",'NEW ACCOUNT'!G6) | H5: =IF('NEW ACCOUNT'!A6="","",'NEW ACCOUNT'!H6) | I5: =IF('NEW ACCOUNT'!A6="","",'NEW ACCOUNT'!I6) | J5: =IF('NEW ACCOUNT'!A6="","",'NEW ACCOUNT'!J6) | K5: =IFERROR(IF(A5="","",SUMIF(DB_Savings!$A:$A,A5,DB_Savings!$F:$F)),"") | L5: =IFERROR(IF(A5="","",SUMIF(DB_Withdrawals!$A:$A,A5,DB_Withdrawals!$G:$G)),"") | M5: =IFERROR(IF(A5="","",IFERROR(VALUE(H5),0)+IFERROR(SUMIF(DB_Savings!$A:$A,A5,DB_Savings!$F:$F),0)-IFERROR(SUMIF(DB_Withdrawals!$A:$A,A5,DB_Withdrawals!$G:$G),0)),"") | N5: =IFERROR(IF(A5="","",MAX(0,M5-System_Config!$B$9)),"")
A6: ='NEW ACCOUNT'!A7 | B6: =IF('NEW ACCOUNT'!A7="","",'NEW ACCOUNT'!B7) | C6: =IF('NEW ACCOUNT'!A7="","",'NEW ACCOUNT'!C7) | D6: =IF('NEW ACCOUNT'!A7="","",'NEW ACCOUNT'!D7) | E6: =IF('NEW ACCOUNT'!A7="","",'NEW ACCOUNT'!E7) | F6: =IF('NEW ACCOUNT'!A7="","",'NEW ACCOUNT'!F7) | G6: =IF('NEW ACCOUNT'!A7="","",'NEW ACCOUNT'!G7) | H6: =IF('NEW ACCOUNT'!A7="","",'NEW ACCOUNT'!H7) | I6: =IF('NEW ACCOUNT'!A7="","",'NEW ACCOUNT'!I7) | J6: =IF('NEW ACCOUNT'!A7="","",'NEW ACCOUNT'!J7) | K6: =IFERROR(IF(A6="","",SUMIF(DB_Savings!$A:$A,A6,DB_Savings!$F:$F)),"") | L6: =IFERROR(IF(A6="","",SUMIF(DB_Withdrawals!$A:$A,A6,DB_Withdrawals!$G:$G)),"") | M6: =IFERROR(IF(A6="","",IFERROR(VALUE(H6),0)+IFERROR(SUMIF(DB_Savings!$A:$A,A6,DB_Savings!$F:$F),0)-IFERROR(SUMIF(DB_Withdrawals!$A:$A,A6,DB_Withdrawals!$G:$G),0)),"") | N6: =IFERROR(IF(A6="","",MAX(0,M6-System_Config!$B$9)),"")
A7: ='NEW ACCOUNT'!A8 | B7: =IF('NEW ACCOUNT'!A8="","",'NEW ACCOUNT'!B8) | C7: =IF('NEW ACCOUNT'!A8="","",'NEW ACCOUNT'!C8) | D7: =IF('NEW ACCOUNT'!A8="","",'NEW ACCOUNT'!D8) | E7: =IF('NEW ACCOUNT'!A8="","",'NEW ACCOUNT'!E8) | F7: =IF('NEW ACCOUNT'!A8="","",'NEW ACCOUNT'!F8) | G7: =IF('NEW ACCOUNT'!A8="","",'NEW ACCOUNT'!G8) | H7: =IF('NEW ACCOUNT'!A8="","",'NEW ACCOUNT'!H8) | I7: =IF('NEW ACCOUNT'!A8="","",'NEW ACCOUNT'!I8) | J7: =IF('NEW ACCOUNT'!A8="","",'NEW ACCOUNT'!J8) | K7: =IFERROR(IF(A7="","",SUMIF(DB_Savings!$A:$A,A7,DB_Savings!$F:$F)),"") | L7: =IFERROR(IF(A7="","",SUMIF(DB_Withdrawals!$A:$A,A7,DB_Withdrawals!$G:$G)),"") | M7: =IFERROR(IF(A7="","",IFERROR(VALUE(H7),0)+IFERROR(SUMIF(DB_Savings!$A:$A,A7,DB_Savings!$F:$F),0)-IFERROR(SUMIF(DB_Withdrawals!$A:$A,A7,DB_Withdrawals!$G:$G),0)),"") | N7: =IFERROR(IF(A7="","",MAX(0,M7-System_Config!$B$9)),"")
A8: ='NEW ACCOUNT'!A9 | B8: =IF('NEW ACCOUNT'!A9="","",'NEW ACCOUNT'!B9) | C8: =IF('NEW ACCOUNT'!A9="","",'NEW ACCOUNT'!C9) | D8: =IF('NEW ACCOUNT'!A9="","",'NEW ACCOUNT'!D9) | E8: =IF('NEW ACCOUNT'!A9="","",'NEW ACCOUNT'!E9) | F8: =IF('NEW ACCOUNT'!A9="","",'NEW ACCOUNT'!F9) | G8: =IF('NEW ACCOUNT'!A9="","",'NEW ACCOUNT'!G9) | H8: =IF('NEW ACCOUNT'!A9="","",'NEW ACCOUNT'!H9) | I8: =IF('NEW ACCOUNT'!A9="","",'NEW ACCOUNT'!I9) | J8: =IF('NEW ACCOUNT'!A9="","",'NEW ACCOUNT'!J9) | K8: =IFERROR(IF(A8="","",SUMIF(DB_Savings!$A:$A,A8,DB_Savings!$F:$F)),"") | L8: =IFERROR(IF(A8="","",SUMIF(DB_Withdrawals!$A:$A,A8,DB_Withdrawals!$G:$G)),"") | M8: =IFERROR(IF(A8="","",IFERROR(VALUE(H8),0)+IFERROR(SUMIF(DB_Savings!$A:$A,A8,DB_Savings!$F:$F),0)-IFERROR(SUMIF(DB_Withdrawals!$A:$A,A8,DB_Withdrawals!$G:$G),0)),"") | N8: =IFERROR(IF(A8="","",MAX(0,M8-System_Config!$B$9)),"")
A9: ='NEW ACCOUNT'!A10 | B9: =IF('NEW ACCOUNT'!A10="","",'NEW ACCOUNT'!B10) | C9: =IF('NEW ACCOUNT'!A10="","",'NEW ACCOUNT'!C10) | D9: =IF('NEW ACCOUNT'!A10="","",'NEW ACCOUNT'!D10) | E9: =IF('NEW ACCOUNT'!A10="","",'NEW ACCOUNT'!E10) | F9: =IF('NEW ACCOUNT'!A10="","",'NEW ACCOUNT'!F10) | G9: =IF('NEW ACCOUNT'!A10="","",'NEW ACCOUNT'!G10) | H9: =IF('NEW ACCOUNT'!A10="","",'NEW ACCOUNT'!H10) | I9: =IF('NEW ACCOUNT'!A10="","",'NEW ACCOUNT'!I10) | J9: =IF('NEW ACCOUNT'!A10="","",'NEW ACCOUNT'!J10) | K9: =IFERROR(IF(A9="","",SUMIF(DB_Savings!$A:$A,A9,DB_Savings!$F:$F)),"") | L9: =IFERROR(IF(A9="","",SUMIF(DB_Withdrawals!$A:$A,A9,DB_Withdrawals!$G:$G)),"") | M9: =IFERROR(IF(A9="","",IFERROR(VALUE(H9),0)+IFERROR(SUMIF(DB_Savings!$A:$A,A9,DB_Savings!$F:$F),0)-IFERROR(SUMIF(DB_Withdrawals!$A:$A,A9,DB_Withdrawals!$G:$G),0)),"") | N9: =IFERROR(IF(A9="","",MAX(0,M9-System_Config!$B$9)),"")
A10: ='NEW ACCOUNT'!A11 | B10: =IF('NEW ACCOUNT'!A11="","",'NEW ACCOUNT'!B11) | C10: =IF('NEW ACCOUNT'!A11="","",'NEW ACCOUNT'!C11) | D10: =IF('NEW ACCOUNT'!A11="","",'NEW ACCOUNT'!D11) | E10: =IF('NEW ACCOUNT'!A11="","",'NEW ACCOUNT'!E11) | F10: =IF('NEW ACCOUNT'!A11="","",'NEW ACCOUNT'!F11) | G10: =IF('NEW ACCOUNT'!A11="","",'NEW ACCOUNT'!G11) | H10: =IF('NEW ACCOUNT'!A11="","",'NEW ACCOUNT'!H11) | I10: =IF('NEW ACCOUNT'!A11="","",'NEW ACCOUNT'!I11) | J10: =IF('NEW ACCOUNT'!A11="","",'NEW ACCOUNT'!J11) | K10: =IFERROR(IF(A10="","",SUMIF(DB_Savings!$A:$A,A10,DB_Savings!$F:$F)),"") | L10: =IFERROR(IF(A10="","",SUMIF(DB_Withdrawals!$A:$A,A10,DB_Withdrawals!$G:$G)),"") | M10: =IFERROR(IF(A10="","",IFERROR(VALUE(H10),0)+IFERROR(SUMIF(DB_Savings!$A:$A,A10,DB_Savings!$F:$F),0)-IFERROR(SUMIF(DB_Withdrawals!$A:$A,A10,DB_Withdrawals!$G:$G),0)),"") | N10: =IFERROR(IF(A10="","",MAX(0,M10-System_Config!$B$9)),"")
A11: ='NEW ACCOUNT'!A12 | B11: =IF('NEW ACCOUNT'!A12="","",'NEW ACCOUNT'!B12) | C11: =IF('NEW ACCOUNT'!A12="","",'NEW ACCOUNT'!C12) | D11: =IF('NEW ACCOUNT'!A12="","",'NEW ACCOUNT'!D12) | E11: =IF('NEW ACCOUNT'!A12="","",'NEW ACCOUNT'!E12) | F11: =IF('NEW ACCOUNT'!A12="","",'NEW ACCOUNT'!F12) | G11: =IF('NEW ACCOUNT'!A12="","",'NEW ACCOUNT'!G12) | H11: =IF('NEW ACCOUNT'!A12="","",'NEW ACCOUNT'!H12) | I11: =IF('NEW ACCOUNT'!A12="","",'NEW ACCOUNT'!I12) | J11: =IF('NEW ACCOUNT'!A12="","",'NEW ACCOUNT'!J12) | K11: =IFERROR(IF(A11="","",SUMIF(DB_Savings!$A:$A,A11,DB_Savings!$F:$F)),"") | L11: =IFERROR(IF(A11="","",SUMIF(DB_Withdrawals!$A:$A,A11,DB_Withdrawals!$G:$G)),"") | M11: =IFERROR(IF(A11="","",IFERROR(VALUE(H11),0)+IFERROR(SUMIF(DB_Savings!$A:$A,A11,DB_Savings!$F:$F),0)-IFERROR(SUMIF(DB_Withdrawals!$A:$A,A11,DB_Withdrawals!$G:$G),0)),"") | N11: =IFERROR(IF(A11="","",MAX(0,M11-System_Config!$B$9)),"")
A12: ='NEW ACCOUNT'!A13 | B12: =IF('NEW ACCOUNT'!A13="","",'NEW ACCOUNT'!B13) | C12: =IF('NEW ACCOUNT'!A13="","",'NEW ACCOUNT'!C13) | D12: =IF('NEW ACCOUNT'!A13="","",'NEW ACCOUNT'!D13) | E12: =IF('NEW ACCOUNT'!A13="","",'NEW ACCOUNT'!E13) | F12: =IF('NEW ACCOUNT'!A13="","",'NEW ACCOUNT'!F13) | G12: =IF('NEW ACCOUNT'!A13="","",'NEW ACCOUNT'!G13) | H12: =IF('NEW ACCOUNT'!A13="","",'NEW ACCOUNT'!H13) | I12: =IF('NEW ACCOUNT'!A13="","",'NEW ACCOUNT'!I13) | J12: =IF('NEW ACCOUNT'!A13="","",'NEW ACCOUNT'!J13) | K12: =IFERROR(IF(A12="","",SUMIF(DB_Savings!$A:$A,A12,DB_Savings!$F:$F)),"") | L12: =IFERROR(IF(A12="","",SUMIF(DB_Withdrawals!$A:$A,A12,DB_Withdrawals!$G:$G)),"") | M12: =IFERROR(IF(A12="","",IFERROR(VALUE(H12),0)+IFERROR(SUMIF(DB_Savings!$A:$A,A12,DB_Savings!$F:$F),0)-IFERROR(SUMIF(DB_Withdrawals!$A:$A,A12,DB_Withdrawals!$G:$G),0)),"") | N12: =IFERROR(IF(A12="","",MAX(0,M12-System_Config!$B$9)),"")
A13: ='NEW ACCOUNT'!A14 | B13: =IF('NEW ACCOUNT'!A14="","",'NEW ACCOUNT'!B14) | C13: =IF('NEW ACCOUNT'!A14="","",'NEW ACCOUNT'!C14) | D13: =IF('NEW ACCOUNT'!A14="","",'NEW ACCOUNT'!D14) | E13: =IF('NEW ACCOUNT'!A14="","",'NEW ACCOUNT'!E14) | F13: =IF('NEW ACCOUNT'!A14="","",'NEW ACCOUNT'!F14) | G13: =IF('NEW ACCOUNT'!A14="","",'NEW ACCOUNT'!G14) | H13: =IF('NEW ACCOUNT'!A14="","",'NEW ACCOUNT'!H14) | I13: =IF('NEW ACCOUNT'!A14="","",'NEW ACCOUNT'!I14) | J13: =IF('NEW ACCOUNT'!A14="","",'NEW ACCOUNT'!J14) | K13: =IFERROR(IF(A13="","",SUMIF(DB_Savings!$A:$A,A13,DB_Savings!$F:$F)),"") | L13: =IFERROR(IF(A13="","",SUMIF(DB_Withdrawals!$A:$A,A13,DB_Withdrawals!$G:$G)),"") | M13: =IFERROR(IF(A13="","",IFERROR(VALUE(H13),0)+IFERROR(SUMIF(DB_Savings!$A:$A,A13,DB_Savings!$F:$F),0)-IFERROR(SUMIF(DB_Withdrawals!$A:$A,A13,DB_Withdrawals!$G:$G),0)),"") | N13: =IFERROR(IF(A13="","",MAX(0,M13-System_Config!$B$9)),"")
A14: ='NEW ACCOUNT'!A15 | B14: =IF('NEW ACCOUNT'!A15="","",'NEW ACCOUNT'!B15) | C14: =IF('NEW ACCOUNT'!A15="","",'NEW ACCOUNT'!C15) | D14: =IF('NEW ACCOUNT'!A15="","",'NEW ACCOUNT'!D15) | E14: =IF('NEW ACCOUNT'!A15="","",'NEW ACCOUNT'!E15) | F14: =IF('NEW ACCOUNT'!A15="","",'NEW ACCOUNT'!F15) | G14: =IF('NEW ACCOUNT'!A15="","",'NEW ACCOUNT'!G15) | H14: =IF('NEW ACCOUNT'!A15="","",'NEW ACCOUNT'!H15) | I14: =IF('NEW ACCOUNT'!A15="","",'NEW ACCOUNT'!I15) | J14: =IF('NEW ACCOUNT'!A15="","",'NEW ACCOUNT'!J15) | K14: =IFERROR(IF(A14="","",SUMIF(DB_Savings!$A:$A,A14,DB_Savings!$F:$F)),"") | L14: =IFERROR(IF(A14="","",SUMIF(DB_Withdrawals!$A:$A,A14,DB_Withdrawals!$G:$G)),"") | M14: =IFERROR(IF(A14="","",IFERROR(VALUE(H14),0)+IFERROR(SUMIF(DB_Savings!$A:$A,A14,DB_Savings!$F:$F),0)-IFERROR(SUMIF(DB_Withdrawals!$A:$A,A14,DB_Withdrawals!$G:$G),0)),"") | N14: =IFERROR(IF(A14="","",MAX(0,M14-System_Config!$B$9)),"")
A15: ='NEW ACCOUNT'!A16 | B15: =IF('NEW ACCOUNT'!A16="","",'NEW ACCOUNT'!B16) | C15: =IF('NEW ACCOUNT'!A16="","",'NEW ACCOUNT'!C16) | D15: =IF('NEW ACCOUNT'!A16="","",'NEW ACCOUNT'!D16) | E15: =IF('NEW ACCOUNT'!A16="","",'NEW ACCOUNT'!E16) | F15: =IF('NEW ACCOUNT'!A16="","",'NEW ACCOUNT'!F16) | G15: =IF('NEW ACCOUNT'!A16="","",'NEW ACCOUNT'!G16) | H15: =IF('NEW ACCOUNT'!A16="","",'NEW ACCOUNT'!H16) | I15: =IF('NEW ACCOUNT'!A16="","",'NEW ACCOUNT'!I16) | J15: =IF('NEW ACCOUNT'!A16="","",'NEW ACCOUNT'!J16) | K15: =IFERROR(IF(A15="","",SUMIF(DB_Savings!$A:$A,A15,DB_Savings!$F:$F)),"") | L15: =IFERROR(IF(A15="","",SUMIF(DB_Withdrawals!$A:$A,A15,DB_Withdrawals!$G:$G)),"") | M15: =IFERROR(IF(A15="","",IFERROR(VALUE(H15),0)+IFERROR(SUMIF(DB_Savings!$A:$A,A15,DB_Savings!$F:$F),0)-IFERROR(SUMIF(DB_Withdrawals!$A:$A,A15,DB_Withdrawals!$G:$G),0)),"") | N15: =IFERROR(IF(A15="","",MAX(0,M15-System_Config!$B$9)),"")
... A503: ='NEW ACCOUNT'!A504 | B503: =IF('NEW ACCOUNT'!A504="","",'NEW ACCOUNT'!B504) | C503: =IF('NEW ACCOUNT'!A504="","",'NEW ACCOUNT'!C504) | D503: =IF('NEW ACCOUNT'!A504="","",'NEW ACCOUNT'!D504) | E503: =IF('NEW ACCOUNT'!A504="","",'NEW ACCOUNT'!E504) | F503: =IF('NEW ACCOUNT'!A504="","",'NEW ACCOUNT'!F504) | G503: =IF('NEW ACCOUNT'!A504="","",'NEW ACCOUNT'!G504) | H503: =IF('NEW ACCOUNT'!A504="","",'NEW ACCOUNT'!H504) | I503: =IF('NEW ACCOUNT'!A504="","",'NEW ACCOUNT'!I504) | J503: =IF('NEW ACCOUNT'!A504="","",'NEW ACCOUNT'!J504) | K503: =IFERROR(IF(A503="","",SUMIF(DB_Savings!$A:$A,A503,DB_Savings!$F:$F)),"") | L503: =IFERROR(IF(A503="","",SUMIF(DB_Withdrawals!$A:$A,A503,DB_Withdrawals!$G:$G)),"") | M503: =IFERROR(IF(A503="","",IFERROR(VALUE(H503),0)+IFERROR(SUMIF(DB_Savings!$A:$A,A503,DB_Savings!$F:$F),0)-IFERROR(SUMIF(DB_Withdrawals!$A:$A,A503,DB_Withdrawals!$G:$G),0)),"") | N503: =IFERROR(IF(A503="","",MAX(0,M503-System_Config!$B$9)),"")

Sheet DB_Savings
A1: 💰 SAVINGS DATABASE — All 10 Agents Combined (Formula-Driven, READ-ONLY)
A2: 🔵 DO NOT ENTER DATA HERE — This sheet auto-aggregates from all Agent Savings sheets. Rows 4–203 = Agent 01, 204–403 = Agent 02, …, 1804–2003 = Agent 10.
A3: Account_No | B3: Transaction_ID | C3: Customer_Name | D3: Agent | E3: Date | F3: Amount_GHS | G3: New_Balance | H3: Status | I3: Saved_At | J3: Notes | K3: Year
A4: =IF(Agent01_Savings!A9="","",Agent01_Savings!A9) | B4: =IF(Agent01_Savings!A9="","","SV"&TEXT(4-3,"0000")&"-"&TEXT(TODAY(),"YYYYMMDD")) | C4: =IF(Agent01_Savings!A9="","",Agent01_Savings!B9) | D4: =IF(Agent01_Savings!A9="","",Agent01_Savings!G9) | E4: =IF(Agent01_Savings!A9="","",Agent01_Savings!D9) | F4: =IF(Agent01_Savings!A9="","",Agent01_Savings!E9) | G4: =IF(Agent01_Savings!A9="","",Agent01_Savings!F9) | H4: =IF(Agent01_Savings!A9="","",Agent01_Savings!I9) | I4: =IF(Agent01_Savings!A9="","",Agent01_Savings!J9) | J4: =IF(Agent01_Savings!A9="","",Agent01_Savings!K9) | K4: =IFERROR(IF(Agent01_Savings!A9="","",YEAR(Agent01_Savings!D9)),"")
A5: =IF(Agent01_Savings!A10="","",Agent01_Savings!A10) | B5: =IF(Agent01_Savings!A10="","","SV"&TEXT(5-3,"0000")&"-"&TEXT(TODAY(),"YYYYMMDD")) | C5: =IF(Agent01_Savings!A10="","",Agent01_Savings!B10) | D5: =IF(Agent01_Savings!A10="","",Agent01_Savings!G10) | E5: =IF(Agent01_Savings!A10="","",Agent01_Savings!D10) | F5: =IF(Agent01_Savings!A10="","",Agent01_Savings!E10) | G5: =IF(Agent01_Savings!A10="","",Agent01_Savings!F10) | H5: =IF(Agent01_Savings!A10="","",Agent01_Savings!I10) | I5: =IF(Agent01_Savings!A10="","",Agent01_Savings!J10) | J5: =IF(Agent01_Savings!A10="","",Agent01_Savings!K10) | K5: =IFERROR(IF(Agent01_Savings!A10="","",YEAR(Agent01_Savings!D10)),"")
A6: =IF(Agent01_Savings!A11="","",Agent01_Savings!A11) | B6: =IF(Agent01_Savings!A11="","","SV"&TEXT(6-3,"0000")&"-"&TEXT(TODAY(),"YYYYMMDD")) | C6: =IF(Agent01_Savings!A11="","",Agent01_Savings!B11) | D6: =IF(Agent01_Savings!A11="","",Agent01_Savings!G11) | E6: =IF(Agent01_Savings!A11="","",Agent01_Savings!D11) | F6: =IF(Agent01_Savings!A11="","",Agent01_Savings!E11) | G6: =IF(Agent01_Savings!A11="","",Agent01_Savings!F11) | H6: =IF(Agent01_Savings!A11="","",Agent01_Savings!I11) | I6: =IF(Agent01_Savings!A11="","",Agent01_Savings!J11) | J6: =IF(Agent01_Savings!A11="","",Agent01_Savings!K11) | K6: =IFERROR(IF(Agent01_Savings!A11="","",YEAR(Agent01_Savings!D11)),"")
A7: =IF(Agent01_Savings!A12="","",Agent01_Savings!A12) | B7: =IF(Agent01_Savings!A12="","","SV"&TEXT(7-3,"0000")&"-"&TEXT(TODAY(),"YYYYMMDD")) | C7: =IF(Agent01_Savings!A12="","",Agent01_Savings!B12) | D7: =IF(Agent01_Savings!A12="","",Agent01_Savings!G12) | E7: =IF(Agent01_Savings!A12="","",Agent01_Savings!D12) | F7: =IF(Agent01_Savings!A12="","",Agent01_Savings!E12) | G7: =IF(Agent01_Savings!A12="","",Agent01_Savings!F12) | H7: =IF(Agent01_Savings!A12="","",Agent01_Savings!I12) | I7: =IF(Agent01_Savings!A12="","",Agent01_Savings!J12) | J7: =IF(Agent01_Savings!A12="","",Agent01_Savings!K12) | K7: =IFERROR(IF(Agent01_Savings!A12="","",YEAR(Agent01_Savings!D12)),"")
A8: =IF(Agent01_Savings!A13="","",Agent01_Savings!A13) | B8: =IF(Agent01_Savings!A13="","","SV"&TEXT(8-3,"0000")&"-"&TEXT(TODAY(),"YYYYMMDD")) | C8: =IF(Agent01_Savings!A13="","",Agent01_Savings!B13) | D8: =IF(Agent01_Savings!A13="","",Agent01_Savings!G13) | E8: =IF(Agent01_Savings!A13="","",Agent01_Savings!D13) | F8: =IF(Agent01_Savings!A13="","",Agent01_Savings!E13) | G8: =IF(Agent01_Savings!A13="","",Agent01_Savings!F13) | H8: =IF(Agent01_Savings!A13="","",Agent01_Savings!I13) | I8: =IF(Agent01_Savings!A13="","",Agent01_Savings!J13) | J8: =IF(Agent01_Savings!A13="","",Agent01_Savings!K13) | K8: =IFERROR(IF(Agent01_Savings!A13="","",YEAR(Agent01_Savings!D13)),"")
A9: =IF(Agent01_Savings!A14="","",Agent01_Savings!A14) | B9: =IF(Agent01_Savings!A14="","","SV"&TEXT(9-3,"0000")&"-"&TEXT(TODAY(),"YYYYMMDD")) | C9: =IF(Agent01_Savings!A14="","",Agent01_Savings!B14) | D9: =IF(Agent01_Savings!A14="","",Agent01_Savings!G14) | E9: =IF(Agent01_Savings!A14="","",Agent01_Savings!D14) | F9: =IF(Agent01_Savings!A14="","",Agent01_Savings!E14) | G9: =IF(Agent01_Savings!A14="","",Agent01_Savings!F14) | H9: =IF(Agent01_Savings!A14="","",Agent01_Savings!I14) | I9: =IF(Agent01_Savings!A14="","",Agent01_Savings!J14) | J9: =IF(Agent01_Savings!A14="","",Agent01_Savings!K14) | K9: =IFERROR(IF(Agent01_Savings!A14="","",YEAR(Agent01_Savings!D14)),"")
A10: =IF(Agent01_Savings!A15="","",Agent01_Savings!A15) | B10: =IF(Agent01_Savings!A15="","","SV"&TEXT(10-3,"0000")&"-"&TEXT(TODAY(),"YYYYMMDD")) | C10: =IF(Agent01_Savings!A15="","",Agent01_Savings!B15) | D10: =IF(Agent01_Savings!A15="","",Agent01_Savings!G15) | E10: =IF(Agent01_Savings!A15="","",Agent01_Savings!D15) | F10: =IF(Agent01_Savings!A15="","",Agent01_Savings!E15) | G10: =IF(Agent01_Savings!A15="","",Agent01_Savings!F15) | H10: =IF(Agent01_Savings!A15="","",Agent01_Savings!I15) | I10: =IF(Agent01_Savings!A15="","",Agent01_Savings!J15) | J10: =IF(Agent01_Savings!A15="","",Agent01_Savings!K15) | K10: =IFERROR(IF(Agent01_Savings!A15="","",YEAR(Agent01_Savings!D15)),"")
A11: =IF(Agent01_Savings!A16="","",Agent01_Savings!A16) | B11: =IF(Agent01_Savings!A16="","","SV"&TEXT(11-3,"0000")&"-"&TEXT(TODAY(),"YYYYMMDD")) | C11: =IF(Agent01_Savings!A16="","",Agent01_Savings!B16) | D11: =IF(Agent01_Savings!A16="","",Agent01_Savings!G16) | E11: =IF(Agent01_Savings!A16="","",Agent01_Savings!D16) | F11: =IF(Agent01_Savings!A16="","",Agent01_Savings!E16) | G11: =IF(Agent01_Savings!A16="","",Agent01_Savings!F16) | H11: =IF(Agent01_Savings!A16="","",Agent01_Savings!I16) | I11: =IF(Agent01_Savings!A16="","",Agent01_Savings!J16) | J11: =IF(Agent01_Savings!A16="","",Agent01_Savings!K16) | K11: =IFERROR(IF(Agent01_Savings!A16="","",YEAR(Agent01_Savings!D16)),"")
A12: =IF(Agent01_Savings!A17="","",Agent01_Savings!A17) | B12: =IF(Agent01_Savings!A17="","","SV"&TEXT(12-3,"0000")&"-"&TEXT(TODAY(),"YYYYMMDD")) | C12: =IF(Agent01_Savings!A17="","",Agent01_Savings!B17) | D12: =IF(Agent01_Savings!A17="","",Agent01_Savings!G17) | E12: =IF(Agent01_Savings!A17="","",Agent01_Savings!D17) | F12: =IF(Agent01_Savings!A17="","",Agent01_Savings!E17) | G12: =IF(Agent01_Savings!A17="","",Agent01_Savings!F17) | H12: =IF(Agent01_Savings!A17="","",Agent01_Savings!I17) | I12: =IF(Agent01_Savings!A17="","",Agent01_Savings!J17) | J12: =IF(Agent01_Savings!A17="","",Agent01_Savings!K17) | K12: =IFERROR(IF(Agent01_Savings!A17="","",YEAR(Agent01_Savings!D17)),"")
A13: =IF(Agent01_Savings!A18="","",Agent01_Savings!A18) | B13: =IF(Agent01_Savings!A18="","","SV"&TEXT(13-3,"0000")&"-"&TEXT(TODAY(),"YYYYMMDD")) | C13: =IF(Agent01_Savings!A18="","",Agent01_Savings!B18) | D13: =IF(Agent01_Savings!A18="","",Agent01_Savings!G18) | E13: =IF(Agent01_Savings!A18="","",Agent01_Savings!D18) | F13: =IF(Agent01_Savings!A18="","",Agent01_Savings!E18) | G13: =IF(Agent01_Savings!A18="","",Agent01_Savings!F18) | H13: =IF(Agent01_Savings!A18="","",Agent01_Savings!I18) | I13: =IF(Agent01_Savings!A18="","",Agent01_Savings!J18) | J13: =IF(Agent01_Savings!A18="","",Agent01_Savings!K18) | K13: =IFERROR(IF(Agent01_Savings!A18="","",YEAR(Agent01_Savings!D18)),"")
A14: =IF(Agent01_Savings!A19="","",Agent01_Savings!A19) | B14: =IF(Agent01_Savings!A19="","","SV"&TEXT(14-3,"0000")&"-"&TEXT(TODAY(),"YYYYMMDD")) | C14: =IF(Agent01_Savings!A19="","",Agent01_Savings!B19) | D14: =IF(Agent01_Savings!A19="","",Agent01_Savings!G19) | E14: =IF(Agent01_Savings!A19="","",Agent01_Savings!D19) | F14: =IF(Agent01_Savings!A19="","",Agent01_Savings!E19) | G14: =IF(Agent01_Savings!A19="","",Agent01_Savings!F19) | H14: =IF(Agent01_Savings!A19="","",Agent01_Savings!I19) | I14: =IF(Agent01_Savings!A19="","",Agent01_Savings!J19) | J14: =IF(Agent01_Savings!A19="","",Agent01_Savings!K19) | K14: =IFERROR(IF(Agent01_Savings!A19="","",YEAR(Agent01_Savings!D19)),"")
A15: =IF(Agent01_Savings!A20="","",Agent01_Savings!A20) | B15: =IF(Agent01_Savings!A20="","","SV"&TEXT(15-3,"0000")&"-"&TEXT(TODAY(),"YYYYMMDD")) | C15: =IF(Agent01_Savings!A20="","",Agent01_Savings!B20) | D15: =IF(Agent01_Savings!A20="","",Agent01_Savings!G20) | E15: =IF(Agent01_Savings!A20="","",Agent01_Savings!D20) | F15: =IF(Agent01_Savings!A20="","",Agent01_Savings!E20) | G15: =IF(Agent01_Savings!A20="","",Agent01_Savings!F20) | H15: =IF(Agent01_Savings!A20="","",Agent01_Savings!I20) | I15: =IF(Agent01_Savings!A20="","",Agent01_Savings!J20) | J15: =IF(Agent01_Savings!A20="","",Agent01_Savings!K20) | K15: =IFERROR(IF(Agent01_Savings!A20="","",YEAR(Agent01_Savings!D20)),"")
A16: =IF(Agent01_Savings!A21="","",Agent01_Savings!A21) | B16: =IF(Agent01_Savings!A21="","","SV"&TEXT(16-3,"0000")&"-"&TEXT(TODAY(),"YYYYMMDD")) | C16: =IF(Agent01_Savings!A21="","",Agent01_Savings!B21) | D16: =IF(Agent01_Savings!A21="","",Agent01_Savings!G21) | E16: =IF(Agent01_Savings!A21="","",Agent01_Savings!D21) | F16: =IF(Agent01_Savings!A21="","",Agent01_Savings!E21) | G16: =IF(Agent01_Savings!A21="","",Agent01_Savings!F21) | H16: =IF(Agent01_Savings!A21="","",Agent01_Savings!I21) | I16: =IF(Agent01_Savings!A21="","",Agent01_Savings!J21) | J16: =IF(Agent01_Savings!A21="","",Agent01_Savings!K21) | K16: =IFERROR(IF(Agent01_Savings!A21="","",YEAR(Agent01_Savings!D21)),"")
A17: =IF(Agent01_Savings!A22="","",Agent01_Savings!A22) | B17: =IF(Agent01_Savings!A22="","","SV"&TEXT(17-3,"0000")&"-"&TEXT(TODAY(),"YYYYMMDD")) | C17: =IF(Agent01_Savings!A22="","",Agent01_Savings!B22) | D17: =IF(Agent01_Savings!A22="","",Agent01_Savings!G22) | E17: =IF(Agent01_Savings!A22="","",Agent01_Savings!D22) | F17: =IF(Agent01_Savings!A22="","",Agent01_Savings!E22) | G17: =IF(Agent01_Savings!A22="","",Agent01_Savings!F22) | H17: =IF(Agent01_Savings!A22="","",Agent01_Savings!I22) | I17: =IF(Agent01_Savings!A22="","",Agent01_Savings!J22) | J17: =IF(Agent01_Savings!A22="","",Agent01_Savings!K22) | K17: =IFERROR(IF(Agent01_Savings!A22="","",YEAR(Agent01_Savings!D22)),"")
A18: =IF(Agent01_Savings!A23="","",Agent01_Savings!A23) | B18: =IF(Agent01_Savings!A23="","","SV"&TEXT(18-3,"0000")&"-"&TEXT(TODAY(),"YYYYMMDD")) | C18: =IF(Agent01_Savings!A23="","",Agent01_Savings!B23) | D18: =IF(Agent01_Savings!A23="","",Agent01_Savings!G23) | E18: =IF(Agent01_Savings!A23="","",Agent01_Savings!D23) | F18: =IF(Agent01_Savings!A23="","",Agent01_Savings!E23) | G18: =IF(Agent01_Savings!A23="","",Agent01_Savings!F23) | H18: =IF(Agent01_Savings!A23="","",Agent01_Savings!I23) | I18: =IF(Agent01_Savings!A23="","",Agent01_Savings!J23) | J18: =IF(Agent01_Savings!A23="","",Agent01_Savings!K23) | K18: =IFERROR(IF(Agent01_Savings!A23="","",YEAR(Agent01_Savings!D23)),"")
A19: =IF(Agent01_Savings!A24="","",Agent01_Savings!A24) | B19: =IF(Agent01_Savings!A24="","","SV"&TEXT(19-3,"0000")&"-"&TEXT(TODAY(),"YYYYMMDD")) | C19: =IF(Agent01_Savings!A24="","",Agent01_Savings!B24) | D19: =IF(Agent01_Savings!A24="","",Agent01_Savings!G24) | E19: =IF(Agent01_Savings!A24="","",Agent01_Savings!D24) | F19: =IF(Agent01_Savings!A24="","",Agent01_Savings!E24) | G19: =IF(Agent01_Savings!A24="","",Agent01_Savings!F24) | H19: =IF(Agent01_Savings!A24="","",Agent01_Savings!I24) | I19: =IF(Agent01_Savings!A24="","",Agent01_Savings!J24) | J19: =IF(Agent01_Savings!A24="","",Agent01_Savings!K24) | K19: =IFERROR(IF(Agent01_Savings!A24="","",YEAR(Agent01_Savings!D24)),"")
A20: =IF(Agent01_Savings!A25="","",Agent01_Savings!A25) | B20: =IF(Agent01_Savings!A25="","","SV"&TEXT(20-3,"0000")&"-"&TEXT(TODAY(),"YYYYMMDD")) | C20: =IF(Agent01_Savings!A25="","",Agent01_Savings!B25) | D20: =IF(Agent01_Savings!A25="","",Agent01_Savings!G25) | E20: =IF(Agent01_Savings!A25="","",Agent01_Savings!D25) | F20: =IF(Agent01_Savings!A25="","",Agent01_Savings!E25) | G20: =IF(Agent01_Savings!A25="","",Agent01_Savings!F25) | H20: =IF(Agent01_Savings!A25="","",Agent01_Savings!I25) | I20: =IF(Agent01_Savings!A25="","",Agent01_Savings!J25) | J20: =IF(Agent01_Savings!A25="","",Agent01_Savings!K25) | K20: =IFERROR(IF(Agent01_Savings!A25="","",YEAR(Agent01_Savings!D25)),"")
A21: =IF(Agent01_Savings!A26="","",Agent01_Savings!A26) | B21: =IF(Agent01_Savings!A26="","","SV"&TEXT(21-3,"0000")&"-"&TEXT(TODAY(),"YYYYMMDD")) | C21: =IF(Agent01_Savings!A26="","",Agent01_Savings!B26) | D21: =IF(Agent01_Savings!A26="","",Agent01_Savings!G26) | E21: =IF(Agent01_Savings!A26="","",Agent01_Savings!D26) | F21: =IF(Agent01_Savings!A26="","",Agent01_Savings!E26) | G21: =IF(Agent01_Savings!A26="","",Agent01_Savings!F26) | H21: =IF(Agent01_Savings!A26="","",Agent01_Savings!I26) | I21: =IF(Agent01_Savings!A26="","",Agent01_Savings!J26) | J21: =IF(Agent01_Savings!A26="","",Agent01_Savings!K26) | K21: =IFERROR(IF(Agent01_Savings!A26="","",YEAR(Agent01_Savings!D26)),"")
A22: =IF(Agent01_Savings!A27="","",Agent01_Savings!A27) | B22: =IF(Agent01_Savings!A27="","","SV"&TEXT(22-3,"0000")&"-"&TEXT(TODAY(),"YYYYMMDD")) | C22: =IF(Agent01_Savings!A27="","",Agent01_Savings!B27) | D22: =IF(Agent01_Savings!A27="","",Agent01_Savings!G27) | E22: =IF(Agent01_Savings!A27="","",Agent01_Savings!D27) | F22: =IF(Agent01_Savings!A27="","",Agent01_Savings!E27) | G22: =IF(Agent01_Savings!A27="","",Agent01_Savings!F27) | H22: =IF(Agent01_Savings!A27="","",Agent01_Savings!I27) | I22: =IF(Agent01_Savings!A27="","",Agent01_Savings!J27) | J22: =IF(Agent01_Savings!A27="","",Agent01_Savings!K27) | K22: =IFERROR(IF(Agent01_Savings!A27="","",YEAR(Agent01_Savings!D27)),"")
A23: =IF(Agent01_Savings!A28="","",Agent01_Savings!A28) | B23: =IF(Agent01_Savings!A28="","","SV"&TEXT(23-3,"0000")&"-"&TEXT(TODAY(),"YYYYMMDD")) | C23: =IF(Agent01_Savings!A28="","",Agent01_Savings!B28) | D23: =IF(Agent01_Savings!A28="","",Agent01_Savings!G28) | E23: =IF(Agent01_Savings!A28="","",Agent01_Savings!D28) | F23: =IF(Agent01_Savings!A28="","",Agent01_Savings!E28) | G23: =IF(Agent01_Savings!A28="","",Agent01_Savings!F28) | H23: =IF(Agent01_Savings!A28="","",Agent01_Savings!I28) | I23: =IF(Agent01_Savings!A28="","",Agent01_Savings!J28) | J23: =IF(Agent01_Savings!A28="","",Agent01_Savings!K28) | K23: =IFERROR(IF(Agent01_Savings!A28="","",YEAR(Agent01_Savings!D28)),"")
A24: =IF(Agent01_Savings!A29="","",Agent01_Savings!A29) | B24: =IF(Agent01_Savings!A29="","","SV"&TEXT(24-3,"0000")&"-"&TEXT(TODAY(),"YYYYMMDD")) | C24: =IF(Agent01_Savings!A29="","",Agent01_Savings!B29) | D24: =IF(Agent01_Savings!A29="","",Agent01_Savings!G29) | E24: =IF(Agent01_Savings!A29="","",Agent01_Savings!D29) | F24: =IF(Agent01_Savings!A29="","",Agent01_Savings!E29) | G24: =IF(Agent01_Savings!A29="","",Agent01_Savings!F29) | H24: =IF(Agent01_Savings!A29="","",Agent01_Savings!I29) | I24: =IF(Agent01_Savings!A29="","",Agent01_Savings!J29) | J24: =IF(Agent01_Savings!A29="","",Agent01_Savings!K29) | K24: =IFERROR(IF(Agent01_Savings!A29="","",YEAR(Agent01_Savings!D29)),"")
A25: =IF(Agent01_Savings!A30="","",Agent01_Savings!A30) | B25: =IF(Agent01_Savings!A30="","","SV"&TEXT(25-3,"0000")&"-"&TEXT(TODAY(),"YYYYMMDD")) | C25: =IF(Agent01_Savings!A30="","",Agent01_Savings!B30) | D25: =IF(Agent01_Savings!A30="","",Agent01_Savings!G30) | E25: =IF(Agent01_Savings!A30="","",Agent01_Savings!D30) | F25: =IF(Agent01_Savings!A30="","",Agent01_Savings!E30) | G25: =IF(Agent01_Savings!A30="","",Agent01_Savings!F30) | H25: =IF(Agent01_Savings!A30="","",Agent01_Savings!I30) | I25: =IF(Agent01_Savings!A30="","",Agent01_Savings!J30) | J25: =IF(Agent01_Savings!A30="","",Agent01_Savings!K30) | K25: =IFERROR(IF(Agent01_Savings!A30="","",YEAR(Agent01_Savings!D30)),"")
A26: =IF(Agent01_Savings!A31="","",Agent01_Savings!A31) | B26: =IF(Agent01_Savings!A31="","","SV"&TEXT(26-3,"0000")&"-"&TEXT(TODAY(),"YYYYMMDD")) | C26: =IF(Agent01_Savings!A31="","",Agent01_Savings!B31) | D26: =IF(Agent01_Savings!A31="","",Agent01_Savings!G31) | E26: =IF(Agent01_Savings!A31="","",Agent01_Savings!D31) | F26: =IF(Agent01_Savings!A31="","",Agent01_Savings!E31) | G26: =IF(Agent01_Savings!A31="","",Agent01_Savings!F31) | H26: =IF(Agent01_Savings!A31="","",Agent01_Savings!I31) | I26: =IF(Agent01_Savings!A31="","",Agent01_Savings!J31) | J26: =IF(Agent01_Savings!A31="","",Agent01_Savings!K31) | K26: =IFERROR(IF(Agent01_Savings!A31="","",YEAR(Agent01_Savings!D31)),"")
A27: =IF(Agent01_Savings!A32="","",Agent01_Savings!A32) | B27: =IF(Agent01_Savings!A32="","","SV"&TEXT(27-3,"0000")&"-"&TEXT(TODAY(),"YYYYMMDD")) | C27: =IF(Agent01_Savings!A32="","",Agent01_Savings!B32) | D27: =IF(Agent01_Savings!A32="","",Agent01_Savings!G32) | E27: =IF(Agent01_Savings!A32="","",Agent01_Savings!D32) | F27: =IF(Agent01_Savings!A32="","",Agent01_Savings!E32) | G27: =IF(Agent01_Savings!A32="","",Agent01_Savings!F32) | H27: =IF(Agent01_Savings!A32="","",Agent01_Savings!I32) | I27: =IF(Agent01_Savings!A32="","",Agent01_Savings!J32) | J27: =IF(Agent01_Savings!A32="","",Agent01_Savings!K32) | K27: =IFERROR(IF(Agent01_Savings!A32="","",YEAR(Agent01_Savings!D32)),"")
A28: =IF(Agent01_Savings!A33="","",Agent01_Savings!A33) | B28: =IF(Agent01_Savings!A33="","","SV"&TEXT(28-3,"0000")&"-"&TEXT(TODAY(),"YYYYMMDD")) | C28: =IF(Agent01_Savings!A33="","",Agent01_Savings!B33) | D28: =IF(Agent01_Savings!A33="","",Agent01_Savings!G33) | E28: =IF(Agent01_Savings!A33="","",Agent01_Savings!D33) | F28: =IF(Agent01_Savings!A33="","",Agent01_Savings!E33) | G28: =IF(Agent01_Savings!A33="","",Agent01_Savings!F33) | H28: =IF(Agent01_Savings!A33="","",Agent01_Savings!I33) | I28: =IF(Agent01_Savings!A33="","",Agent01_Savings!J33) | J28: =IF(Agent01_Savings!A33="","",Agent01_Savings!K33) | K28: =IFERROR(IF(Agent01_Savings!A33="","",YEAR(Agent01_Savings!D33)),"")
A29: =IF(Agent01_Savings!A34="","",Agent01_Savings!A34) | B29: =IF(Agent01_Savings!A34="","","SV"&TEXT(29-3,"0000")&"-"&TEXT(TODAY(),"YYYYMMDD")) | C29: =IF(Agent01_Savings!A34="","",Agent01_Savings!B34) | D29: =IF(Agent01_Savings!A34="","",Agent01_Savings!G34) | E29: =IF(Agent01_Savings!A34="","",Agent01_Savings!D34) | F29: =IF(Agent01_Savings!A34="","",Agent01_Savings!E34) | G29: =IF(Agent01_Savings!A34="","",Agent01_Savings!F34) | H29: =IF(Agent01_Savings!A34="","",Agent01_Savings!I34) | I29: =IF(Agent01_Savings!A34="","",Agent01_Savings!J34) | J29: =IF(Agent01_Savings!A34="","",Agent01_Savings!K34) | K29: =IFERROR(IF(Agent01_Savings!A34="","",YEAR(Agent01_Savings!D34)),"")
A30: =IF(Agent01_Savings!A35="","",Agent01_Savings!A35) | B30: =IF(Agent01_Savings!A35="","","SV"&TEXT(30-3,"0000")&"-"&TEXT(TODAY(),"YYYYMMDD")) | C30: =IF(Agent01_Savings!A35="","",Agent01_Savings!B35) | D30: =IF(Agent01_Savings!A35="","",Agent01_Savings!G35) | E30: =IF(Agent01_Savings!A35="","",Agent01_Savings!D35) | F30: =IF(Agent01_Savings!A35="","",Agent01_Savings!E35) | G30: =IF(Agent01_Savings!A35="","",Agent01_Savings!F35) | H30: =IF(Agent01_Savings!A35="","",Agent01_Savings!I35) | I30: =IF(Agent01_Savings!A35="","",Agent01_Savings!J35) | J30: =IF(Agent01_Savings!A35="","",Agent01_Savings!K35) | K30: =IFERROR(IF(Agent01_Savings!A35="","",YEAR(Agent01_Savings!D35)),"")
A31: =IF(Agent01_Savings!A36="","",Agent01_Savings!A36) | B31: =IF(Agent01_Savings!A36="","","SV"&TEXT(31-3,"0000")&"-"&TEXT(TODAY(),"YYYYMMDD")) | C31: =IF(Agent01_Savings!A36="","",Agent01_Savings!B36) | D31: =IF(Agent01_Savings!A36="","",Agent01_Savings!G36) | E31: =IF(Agent01_Savings!A36="","",Agent01_Savings!D36) | F31: =IF(Agent01_Savings!A36="","",Agent01_Savings!E36) | G31: =IF(Agent01_Savings!A36="","",Agent01_Savings!F36) | H31: =IF(Agent01_Savings!A36="","",Agent01_Savings!I36) | I31: =IF(Agent01_Savings!A36="","",Agent01_Savings!J36) | J31: =IF(Agent01_Savings!A36="","",Agent01_Savings!K36) | K31: =IFERROR(IF(Agent01_Savings!A36="","",YEAR(Agent01_Savings!D36)),"")
A32: =IF(Agent01_Savings!A37="","",Agent01_Savings!A37) | B32: =IF(Agent01_Savings!A37="","","SV"&TEXT(32-3,"0000")&"-"&TEXT(TODAY(),"YYYYMMDD")) | C32: =IF(Agent01_Savings!A37="","",Agent01_Savings!B37) | D32: =IF(Agent01_Savings!A37="","",Agent01_Savings!G37) | E32: =IF(Agent01_Savings!A37="","",Agent01_Savings!D37) | F32: =IF(Agent01_Savings!A37="","",Agent01_Savings!E37) | G32: =IF(Agent01_Savings!A37="","",Agent01_Savings!F37) | H32: =IF(Agent01_Savings!A37="","",Agent01_Savings!I37) | I32: =IF(Agent01_Savings!A37="","",Agent01_Savings!J37) | J32: =IF(Agent01_Savings!A37="","",Agent01_Savings!K37) | K32: =IFERROR(IF(Agent01_Savings!A37="","",YEAR(Agent01_Savings!D37)),"")
A33: =IF(Agent01_Savings!A38="","",Agent01_Savings!A38) | B33: =IF(Agent01_Savings!A38="","","SV"&TEXT(33-3,"0000")&"-"&TEXT(TODAY(),"YYYYMMDD")) | C33: =IF(Agent01_Savings!A38="","",Agent01_Savings!B38) | D33: =IF(Agent01_Savings!A38="","",Agent01_Savings!G38) | E33: =IF(Agent01_Savings!A38="","",Agent01_Savings!D38) | F33: =IF(Agent01_Savings!A38="","",Agent01_Savings!E38) | G33: =IF(Agent01_Savings!A38="","",Agent01_Savings!F38) | H33: =IF(Agent01_Savings!A38="","",Agent01_Savings!I38) | I33: =IF(Agent01_Savings!A38="","",Agent01_Savings!J38) | J33: =IF(Agent01_Savings!A38="","",Agent01_Savings!K38) | K33: =IFERROR(IF(Agent01_Savings!A38="","",YEAR(Agent01_Savings!D38)),"")
A34: =IF(Agent01_Savings!A39="","",Agent01_Savings!A39) | B34: =IF(Agent01_Savings!A39="","","SV"&TEXT(34-3,"0000")&"-"&TEXT(TODAY(),"YYYYMMDD")) | C34: =IF(Agent01_Savings!A39="","",Agent01_Savings!B39) | D34: =IF(Agent01_Savings!A39="","",Agent01_Savings!G39) | E34: =IF(Agent01_Savings!A39="","",Agent01_Savings!D39) | F34: =IF(Agent01_Savings!A39="","",Agent01_Savings!E39) | G34: =IF(Agent01_Savings!A39="","",Agent01_Savings!F39) | H34: =IF(Agent01_Savings!A39="","",Agent01_Savings!I39) | I34: =IF(Agent01_Savings!A39="","",Agent01_Savings!J39) | J34: =IF(Agent01_Savings!A39="","",Agent01_Savings!K39) | K34: =IFERROR(IF(Agent01_Savings!A39="","",YEAR(Agent01_Savings!D39)),"")
A35: =IF(Agent01_Savings!A40="","",Agent01_Savings!A40) | B35: =IF(Agent01_Savings!A40="","","SV"&TEXT(35-3,"0000")&"-"&TEXT(TODAY(),"YYYYMMDD")) | C35: =IF(Agent01_Savings!A40="","",Agent01_Savings!B40) | D35: =IF(Agent01_Savings!A40="","",Agent01_Savings!G40) | E35: =IF(Agent01_Savings!A40="","",Agent01_Savings!D40) | F35: =IF(Agent01_Savings!A40="","",Agent01_Savings!E40) | G35: =IF(Agent01_Savings!A40="","",Agent01_Savings!F40) | H35: =IF(Agent01_Savings!A40="","",Agent01_Savings!I40) | I35: =IF(Agent01_Savings!A40="","",Agent01_Savings!J40) | J35: =IF(Agent01_Savings!A40="","",Agent01_Savings!K40) | K35: =IFERROR(IF(Agent01_Savings!A40="","",YEAR(Agent01_Savings!D40)),"")
A36: =IF(Agent01_Savings!A41="","",Agent01_Savings!A41) | B36: =IF(Agent01_Savings!A41="","","SV"&TEXT(36-3,"0000")&"-"&TEXT(TODAY(),"YYYYMMDD")) | C36: =IF(Agent01_Savings!A41="","",Agent01_Savings!B41) | D36: =IF(Agent01_Savings!A41="","",Agent01_Savings!G41) | E36: =IF(Agent01_Savings!A41="","",Agent01_Savings!D41) | F36: =IF(Agent01_Savings!A41="","",Agent01_Savings!E41) | G36: =IF(Agent01_Savings!A41="","",Agent01_Savings!F41) | H36: =IF(Agent01_Savings!A41="","",Agent01_Savings!I41) | I36: =IF(Agent01_Savings!A41="","",Agent01_Savings!J41) | J36: =IF(Agent01_Savings!A41="","",Agent01_Savings!K41) | K36: =IFERROR(IF(Agent01_Savings!A41="","",YEAR(Agent01_Savings!D41)),"")
A37: =IF(Agent01_Savings!A42="","",Agent01_Savings!A42) | B37: =IF(Agent01_Savings!A42="","","SV"&TEXT(37-3,"0000")&"-"&TEXT(TODAY(),"YYYYMMDD")) | C37: =IF(Agent01_Savings!A42="","",Agent01_Savings!B42) | D37: =IF(Agent01_Savings!A42="","",Agent01_Savings!G42) | E37: =IF(Agent01_Savings!A42="","",Agent01_Savings!D42) | F37: =IF(Agent01_Savings!A42="","",Agent01_Savings!E42) | G37: =IF(Agent01_Savings!A42="","",Agent01_Savings!F42) | H37: =IF(Agent01_Savings!A42="","",Agent01_Savings!I42) | I37: =IF(Agent01_Savings!A42="","",Agent01_Savings!J42) | J37: =IF(Agent01_Savings!A42="","",Agent01_Savings!K42) | K37: =IFERROR(IF(Agent01_Savings!A42="","",YEAR(Agent01_Savings!D42)),"")
A38: =IF(Agent01_Savings!A43="","",Agent01_Savings!A43) | B38: =IF(Agent01_Savings!A43="","","SV"&TEXT(38-3,"0000")&"-"&TEXT(TODAY(),"YYYYMMDD")) | C38: =IF(Agent01_Savings!A43="","",Agent01_Savings!B43) | D38: =IF(Agent01_Savings!A43="","",Agent01_Savings!G43) | E38: =IF(Agent01_Savings!A43="","",Agent01_Savings!D43) | F38: =IF(Agent01_Savings!A43="","",Agent01_Savings!E43) | G38: =IF(Agent01_Savings!A43="","",Agent01_Savings!F43) | H38: =IF(Agent01_Savings!A43="","",Agent01_Savings!I43) | I38: =IF(Agent01_Savings!A43="","",Agent01_Savings!J43) | J38: =IF(Agent01_Savings!A43="","",Agent01_Savings!K43) | K38: =IFERROR(IF(Agent01_Savings!A43="","",YEAR(Agent01_Savings!D43)),"")
A39: =IF(Agent01_Savings!A44="","",Agent01_Savings!A44) | B39: =IF(Agent01_Savings!A44="","","SV"&TEXT(39-3,"0000")&"-"&TEXT(TODAY(),"YYYYMMDD")) | C39: =IF(Agent01_Savings!A44="","",Agent01_Savings!B44) | D39: =IF(Agent01_Savings!A44="","",Agent01_Savings!G44) | E39: =IF(Agent01_Savings!A44="","",Agent01_Savings!D44) | F39: =IF(Agent01_Savings!A44="","",Agent01_Savings!E44) | G39: =IF(Agent01_Savings!A44="","",Agent01_Savings!F44) | H39: =IF(Agent01_Savings!A44="","",Agent01_Savings!I44) | I39: =IF(Agent01_Savings!A44="","",Agent01_Savings!J44) | J39: =IF(Agent01_Savings!A44="","",Agent01_Savings!K44) | K39: =IFERROR(IF(Agent01_Savings!A44="","",YEAR(Agent01_Savings!D44)),"")
A40: =IF(Agent01_Savings!A45="","",Agent01_Savings!A45) | B40: =IF(Agent01_Savings!A45="","","SV"&TEXT(40-3,"0000")&"-"&TEXT(TODAY(),"YYYYMMDD")) | C40: =IF(Agent01_Savings!A45="","",Agent01_Savings!B45) | D40: =IF(Agent01_Savings!A45="","",Agent01_Savings!G45) | E40: =IF(Agent01_Savings!A45="","",Agent01_Savings!D45) | F40: =IF(Agent01_Savings!A45="","",Agent01_Savings!E45) | G40: =IF(Agent01_Savings!A45="","",Agent01_Savings!F45) | H40: =IF(Agent01_Savings!A45="","",Agent01_Savings!I45) | I40: =IF(Agent01_Savings!A45="","",Agent01_Savings!J45) | J40: =IF(Agent01_Savings!A45="","",Agent01_Savings!K45) | K40: =IFERROR(IF(Agent01_Savings!A45="","",YEAR(Agent01_Savings!D45)),"")
...

Sheet DB_Withdrawals
A1: 🏧 WITHDRAWALS DATABASE — All 10 Agents Combined (Formula-Driven, READ-ONLY)
A2: 🔵 DO NOT ENTER DATA HERE — auto-aggregates from all Agent Withdrawal sheets. Rows 4–203=Agent01, 204–403=Agent02 … 1804–2003=Agent10.
A3: Account_No | B3: Transaction_ID | C3: Customer_Name | D3: Balance_Before | E3: Date | F3: Authorized_By | G3: Withdrawal_Amt_GHS | H3: New_Balance_GHS | I3: Agent | J3: Status | K3: Saved_At | L3: Min_Bal_Compliant | M3: Year
A4: =IF(Agent01_Withdrawals!A9="","",Agent01_Withdrawals!A9) | B4: =IF(Agent01_Withdrawals!A9="","","WD"&TEXT(4-3,"0000")&"-"&TEXT(TODAY(),"YYYYMMDD")) | C4: =IF(Agent01_Withdrawals!A9="","",Agent01_Withdrawals!B9) | D4: =IF(Agent01_Withdrawals!A9="","",Agent01_Withdrawals!C9) | E4: =IF(Agent01_Withdrawals!A9="","",Agent01_Withdrawals!D9) | F4: =IF(Agent01_Withdrawals!A9="","",Agent01_Withdrawals!F9) | G4: =IF(Agent01_Withdrawals!A9="","",Agent01_Withdrawals!E9) | H4: =IF(Agent01_Withdrawals!A9="","",Agent01_Withdrawals!G9) | I4: =IF(Agent01_Withdrawals!A9="","",Agent01_Withdrawals!H9) | J4: =IF(Agent01_Withdrawals!A9="","",Agent01_Withdrawals!J9) | K4: =IF(Agent01_Withdrawals!A9="","",Agent01_Withdrawals!K9) | L4: =IF(G4="","",IF(D4-G4>=System_Config!$B$9,"✅ OK","⚠️ BREACH")) | M4: =IFERROR(IF(Agent01_Withdrawals!A9="","",YEAR(Agent01_Withdrawals!D9)),"")
A5: =IF(Agent01_Withdrawals!A10="","",Agent01_Withdrawals!A10) | B5: =IF(Agent01_Withdrawals!A10="","","WD"&TEXT(5-3,"0000")&"-"&TEXT(TODAY(),"YYYYMMDD")) | C5: =IF(Agent01_Withdrawals!A10="","",Agent01_Withdrawals!B10) | D5: =IF(Agent01_Withdrawals!A10="","",Agent01_Withdrawals!C10) | E5: =IF(Agent01_Withdrawals!A10="","",Agent01_Withdrawals!D10) | F5: =IF(Agent01_Withdrawals!A10="","",Agent01_Withdrawals!F10) | G5: =IF(Agent01_Withdrawals!A10="","",Agent01_Withdrawals!E10) | H5: =IF(Agent01_Withdrawals!A10="","",Agent01_Withdrawals!G10) | I5: =IF(Agent01_Withdrawals!A10="","",Agent01_Withdrawals!H10) | J5: =IF(Agent01_Withdrawals!A10="","",Agent01_Withdrawals!J10) | K5: =IF(Agent01_Withdrawals!A10="","",Agent01_Withdrawals!K10) | L5: =IF(G5="","",IF(D5-G5>=System_Config!$B$9,"✅ OK","⚠️ BREACH")) | M5: =IFERROR(IF(Agent01_Withdrawals!A10="","",YEAR(Agent01_Withdrawals!D10)),"")
A6: =IF(Agent01_Withdrawals!A11="","",Agent01_Withdrawals!A11) | B6: =IF(Agent01_Withdrawals!A11="","","WD"&TEXT(6-3,"0000")&"-"&TEXT(TODAY(),"YYYYMMDD")) | C6: =IF(Agent01_Withdrawals!A11="","",Agent01_Withdrawals!B11) | D6: =IF(Agent01_Withdrawals!A11="","",Agent01_Withdrawals!C11) | E6: =IF(Agent01_Withdrawals!A11="","",Agent01_Withdrawals!D11) | F6: =IF(Agent01_Withdrawals!A11="","",Agent01_Withdrawals!F11) | G6: =IF(Agent01_Withdrawals!A11="","",Agent01_Withdrawals!E11) | H6: =IF(Agent01_Withdrawals!A11="","",Agent01_Withdrawals!G11) | I6: =IF(Agent01_Withdrawals!A11="","",Agent01_Withdrawals!H11) | J6: =IF(Agent01_Withdrawals!A11="","",Agent01_Withdrawals!J11) | K6: =IF(Agent01_Withdrawals!A11="","",Agent01_Withdrawals!K11) | L6: =IF(G6="","",IF(D6-G6>=System_Config!$B$9,"✅ OK","⚠️ BREACH")) | M6: =IFERROR(IF(Agent01_Withdrawals!A11="","",YEAR(Agent01_Withdrawals!D11)),"")
A7: =IF(Agent01_Withdrawals!A12="","",Agent01_Withdrawals!A12) | B7: =IF(Agent01_Withdrawals!A12="","","WD"&TEXT(7-3,"0000")&"-"&TEXT(TODAY(),"YYYYMMDD")) | C7: =IF(Agent01_Withdrawals!A12="","",Agent01_Withdrawals!B12) | D7: =IF(Agent01_Withdrawals!A12="","",Agent01_Withdrawals!C12) | E7: =IF(Agent01_Withdrawals!A12="","",Agent01_Withdrawals!D12) | F7: =IF(Agent01_Withdrawals!A12="","",Agent01_Withdrawals!F12) | G7: =IF(Agent01_Withdrawals!A12="","",Agent01_Withdrawals!E12) | H7: =IF(Agent01_Withdrawals!A12="","",Agent01_Withdrawals!G12) | I7: =IF(Agent01_Withdrawals!A12="","",Agent01_Withdrawals!H12) | J7: =IF(Agent01_Withdrawals!A12="","",Agent01_Withdrawals!J12) | K7: =IF(Agent01_Withdrawals!A12="","",Agent01_Withdrawals!K12) | L7: =IF(G7="","",IF(D7-G7>=System_Config!$B$9,"✅ OK","⚠️ BREACH")) | M7: =IFERROR(IF(Agent01_Withdrawals!A12="","",YEAR(Agent01_Withdrawals!D12)),"")
A8: =IF(Agent01_Withdrawals!A13="","",Agent01_Withdrawals!A13) | B8: =IF(Agent01_Withdrawals!A13="","","WD"&TEXT(8-3,"0000")&"-"&TEXT(TODAY(),"YYYYMMDD")) | C8: =IF(Agent01_Withdrawals!A13="","",Agent01_Withdrawals!B13) | D8: =IF(Agent01_Withdrawals!A13="","",Agent01_Withdrawals!C13) | E8: =IF(Agent01_Withdrawals!A13="","",Agent01_Withdrawals!D13) | F8: =IF(Agent01_Withdrawals!A13="","",Agent01_Withdrawals!F13) | G8: =IF(Agent01_Withdrawals!A13="","",Agent01_Withdrawals!E13) | H8: =IF(Agent01_Withdrawals!A13="","",Agent01_Withdrawals!G13) | I8: =IF(Agent01_Withdrawals!A13="","",Agent01_Withdrawals!H13) | J8: =IF(Agent01_Withdrawals!A13="","",Agent01_Withdrawals!J13) | K8: =IF(Agent01_Withdrawals!A13="","",Agent01_Withdrawals!K13) | L8: =IF(G8="","",IF(D8-G8>=System_Config!$B$9,"✅ OK","⚠️ BREACH")) | M8: =IFERROR(IF(Agent01_Withdrawals!A13="","",YEAR(Agent01_Withdrawals!D13)),"")
A9: =IF(Agent01_Withdrawals!A14="","",Agent01_Withdrawals!A14) | B9: =IF(Agent01_Withdrawals!A14="","","WD"&TEXT(9-3,"0000")&"-"&TEXT(TODAY(),"YYYYMMDD")) | C9: =IF(Agent01_Withdrawals!A14="","",Agent01_Withdrawals!B14) | D9: =IF(Agent01_Withdrawals!A14="","",Agent01_Withdrawals!C14) | E9: =IF(Agent01_Withdrawals!A14="","",Agent01_Withdrawals!D14) | F9: =IF(Agent01_Withdrawals!A14="","",Agent01_Withdrawals!F14) | G9: =IF(Agent01_Withdrawals!A14="","",Agent01_Withdrawals!E14) | H9: =IF(Agent01_Withdrawals!A14="","",Agent01_Withdrawals!G14) | I9: =IF(Agent01_Withdrawals!A14="","",Agent01_Withdrawals!H14) | J9: =IF(Agent01_Withdrawals!A14="","",Agent01_Withdrawals!J14) | K9: =IF(Agent01_Withdrawals!A14="","",Agent01_Withdrawals!K14) | L9: =IF(G9="","",IF(D9-G9>=System_Config!$B$9,"✅ OK","⚠️ BREACH")) | M9: =IFERROR(IF(Agent01_Withdrawals!A14="","",YEAR(Agent01_Withdrawals!D14)),"")
A10: =IF(Agent01_Withdrawals!A15="","",Agent01_Withdrawals!A15) | B10: =IF(Agent01_Withdrawals!A15="","","WD"&TEXT(10-3,"0000")&"-"&TEXT(TODAY(),"YYYYMMDD")) | C10: =IF(Agent01_Withdrawals!A15="","",Agent01_Withdrawals!B15) | D10: =IF(Agent01_Withdrawals!A15="","",Agent01_Withdrawals!C15) | E10: =IF(Agent01_Withdrawals!A15="","",Agent01_Withdrawals!D15) | F10: =IF(Agent01_Withdrawals!A15="","",Agent01_Withdrawals!F15) | G10: =IF(Agent01_Withdrawals!A15="","",Agent01_Withdrawals!E15) | H10: =IF(Agent01_Withdrawals!A15="","",Agent01_Withdrawals!G15) | I10: =IF(Agent01_Withdrawals!A15="","",Agent01_Withdrawals!H15) | J10: =IF(Agent01_Withdrawals!A15="","",Agent01_Withdrawals!J15) | K10: =IF(Agent01_Withdrawals!A15="","",Agent01_Withdrawals!K15) | L10: =IF(G10="","",IF(D10-G10>=System_Config!$B$9,"✅ OK","⚠️ BREACH")) | M10: =IFERROR(IF(Agent01_Withdrawals!A15="","",YEAR(Agent01_Withdrawals!D15)),"")
A11: =IF(Agent01_Withdrawals!A16="","",Agent01_Withdrawals!A16) | B11: =IF(Agent01_Withdrawals!A16="","","WD"&TEXT(11-3,"0000")&"-"&TEXT(TODAY(),"YYYYMMDD")) | C11: =IF(Agent01_Withdrawals!A16="","",Agent01_Withdrawals!B16) | D11: =IF(Agent01_Withdrawals!A16="","",Agent01_Withdrawals!C16) | E11: =IF(Agent01_Withdrawals!A16="","",Agent01_Withdrawals!D16) | F11: =IF(Agent01_Withdrawals!A16="","",Agent01_Withdrawals!F16) | G11: =IF(Agent01_Withdrawals!A16="","",Agent01_Withdrawals!E16) | H11: =IF(Agent01_Withdrawals!A16="","",Agent01_Withdrawals!G16) | I11: =IF(Agent01_Withdrawals!A16="","",Agent01_Withdrawals!H16) | J11: =IF(Agent01_Withdrawals!A16="","",Agent01_Withdrawals!J16) | K11: =IF(Agent01_Withdrawals!A16="","",Agent01_Withdrawals!K16) | L11: =IF(G11="","",IF(D11-G11>=System_Config!$B$9,"✅ OK","⚠️ BREACH")) | M11: =IFERROR(IF(Agent01_Withdrawals!A16="","",YEAR(Agent01_Withdrawals!D16)),"")
A12: =IF(Agent01_Withdrawals!A17="","",Agent01_Withdrawals!A17) | B12: =IF(Agent01_Withdrawals!A17="","","WD"&TEXT(12-3,"0000")&"-"&TEXT(TODAY(),"YYYYMMDD")) | C12: =IF(Agent01_Withdrawals!A17="","",Agent01_Withdrawals!B17) | D12: =IF(Agent01_Withdrawals!A17="","",Agent01_Withdrawals!C17) | E12: =IF(Agent01_Withdrawals!A17="","",Agent01_Withdrawals!D17) | F12: =IF(Agent01_Withdrawals!A17="","",Agent01_Withdrawals!F17) | G12: =IF(Agent01_Withdrawals!A17="","",Agent01_Withdrawals!E17) | H12: =IF(Agent01_Withdrawals!A17="","",Agent01_Withdrawals!G17) | I12: =IF(Agent01_Withdrawals!A17="","",Agent01_Withdrawals!H17) | J12: =IF(Agent01_Withdrawals!A17="","",Agent01_Withdrawals!J17) | K12: =IF(Agent01_Withdrawals!A17="","",Agent01_Withdrawals!K17) | L12: =IF(G12="","",IF(D12-G12>=System_Config!$B$9,"✅ OK","⚠️ BREACH")) | M12: =IFERROR(IF(Agent01_Withdrawals!A17="","",YEAR(Agent01_Withdrawals!D17)),"")
A13: =IF(Agent01_Withdrawals!A18="","",Agent01_Withdrawals!A18) | B13: =IF(Agent01_Withdrawals!A18="","","WD"&TEXT(13-3,"0000")&"-"&TEXT(TODAY(),"YYYYMMDD")) | C13: =IF(Agent01_Withdrawals!A18="","",Agent01_Withdrawals!B18) | D13: =IF(Agent01_Withdrawals!A18="","",Agent01_Withdrawals!C18) | E13: =IF(Agent01_Withdrawals!A18="","",Agent01_Withdrawals!D18) | F13: =IF(Agent01_Withdrawals!A18="","",Agent01_Withdrawals!F18) | G13: =IF(Agent01_Withdrawals!A18="","",Agent01_Withdrawals!E18) | H13: =IF(Agent01_Withdrawals!A18="","",Agent01_Withdrawals!G18) | I13: =IF(Agent01_Withdrawals!A18="","",Agent01_Withdrawals!H18) | J13: =IF(Agent01_Withdrawals!A18="","",Agent01_Withdrawals!J18) | K13: =IF(Agent01_Withdrawals!A18="","",Agent01_Withdrawals!K18) | L13: =IF(G13="","",IF(D13-G13>=System_Config!$B$9,"✅ OK","⚠️ BREACH")) | M13: =IFERROR(IF(Agent01_Withdrawals!A18="","",YEAR(Agent01_Withdrawals!D18)),"")
