Workbook

Sheet Manager_Dashboard
A1: 🏦 SAMICIOUS MICROFINANCE — MANAGER COMMAND CENTER
A2: =UPPER(TEXT(TODAY(),"DDDD, DD MMMM YYYY"))&" | All figures auto-update from agent sheets" -> SUNDAY, 12 APRIL 2026 | All figures auto-update from agent sheets
A4: 💰 Today Savings | C4: 🏧 Today Withdrawals | E4: 📈 Net Movement | G4: 👥 Customers Served | I4: 🔔 Pending Loans | K4: ⏳ Pending KYC
A5: =Daily_Balancing!B14 -> 6570.67 | C5: =Daily_Balancing!C14 -> 0 | E5: =Daily_Balancing!D14 -> 6570.67 | G5: =Daily_Balancing!E14 -> 20 | I5: =COUNTIF(Active_Loans!K3:K200,"Pending") -> 2 | K5: =COUNTIF(Master_Customers!L2:L1000,"Pending") -> 0
A7: 📊 REAL-TIME AGENT PERFORMANCE TODAY
A8: Agent | B8: Savings (GHC) | C8: Withdrawals (GHC) | D8: Net (GHC) | E8: Customers | F8: Transactions | G8: Target GHC | H8: % of Target | I8: Status
A9: Agent01 | B9: =Daily_Balancing!B4 -> 731.47 | C9: =Daily_Balancing!C4 -> 0 | D9: =Daily_Balancing!D4 -> 731.47 | E9: =Daily_Balancing!E4 -> 2 | F9: =Daily_Balancing!F4 -> 2 | G9: 5000 | H9: =IFERROR(B9/G9,0) -> 0.146294 | I9: =Daily_Balancing!G4 -> ❌ Low
A10: Agent02 | B10: =Daily_Balancing!B5 -> 645.87 | C10: =Daily_Balancing!C5 -> 0 | D10: =Daily_Balancing!D5 -> 645.87 | E10: =Daily_Balancing!E5 -> 2 | F10: =Daily_Balancing!F5 -> 2 | G10: 5000 | H10: =IFERROR(B10/G10,0) -> 0.129174 | I10: =Daily_Balancing!G5 -> ❌ Low
A11: Agent03 | B11: =Daily_Balancing!B6 -> 498.29 | C11: =Daily_Balancing!C6 -> 0 | D11: =Daily_Balancing!D6 -> 498.29 | E11: =Daily_Balancing!E6 -> 2 | F11: =Daily_Balancing!F6 -> 2 | G11: 5000 | H11: =IFERROR(B11/G11,0) -> 0.099658 | I11: =Daily_Balancing!G6 -> ❌ Low
A12: Agent04 | B12: =Daily_Balancing!B7 -> 872.99 | C12: =Daily_Balancing!C7 -> 0 | D12: =Daily_Balancing!D7 -> 872.99 | E12: =Daily_Balancing!E7 -> 2 | F12: =Daily_Balancing!F7 -> 2 | G12: 5000 | H12: =IFERROR(B12/G12,0) -> 0.174598 | I12: =Daily_Balancing!G7 -> ❌ Low
A13: Agent05 | B13: =Daily_Balancing!B8 -> 525.86 | C13: =Daily_Balancing!C8 -> 0 | D13: =Daily_Balancing!D8 -> 525.86 | E13: =Daily_Balancing!E8 -> 2 | F13: =Daily_Balancing!F8 -> 2 | G13: 5000 | H13: =IFERROR(B13/G13,0) -> 0.105172 | I13: =Daily_Balancing!G8 -> ❌ Low
A14: Agent06 | B14: =Daily_Balancing!B9 -> 505.66 | C14: =Daily_Balancing!C9 -> 0 | D14: =Daily_Balancing!D9 -> 505.66 | E14: =Daily_Balancing!E9 -> 2 | F14: =Daily_Balancing!F9 -> 2 | G14: 5000 | H14: =IFERROR(B14/G14,0) -> 0.101132 | I14: =Daily_Balancing!G9 -> ❌ Low
A15: Agent07 | B15: =Daily_Balancing!B10 -> 642.46 | C15: =Daily_Balancing!C10 -> 0 | D15: =Daily_Balancing!D10 -> 642.46 | E15: =Daily_Balancing!E10 -> 2 | F15: =Daily_Balancing!F10 -> 2 | G15: 5000 | H15: =IFERROR(B15/G15,0) -> 0.128492 | I15: =Daily_Balancing!G10 -> ❌ Low
A16: Agent08 | B16: =Daily_Balancing!B11 -> 641.53 | C16: =Daily_Balancing!C11 -> 0 | D16: =Daily_Balancing!D11 -> 641.53 | E16: =Daily_Balancing!E11 -> 2 | F16: =Daily_Balancing!F11 -> 2 | G16: 5000 | H16: =IFERROR(B16/G16,0) -> 0.128306 | I16: =Daily_Balancing!G11 -> ❌ Low
A17: Agent09 | B17: =Daily_Balancing!B12 -> 627.62 | C17: =Daily_Balancing!C12 -> 0 | D17: =Daily_Balancing!D12 -> 627.62 | E17: =Daily_Balancing!E12 -> 2 | F17: =Daily_Balancing!F12 -> 2 | G17: 5000 | H17: =IFERROR(B17/G17,0) -> 0.125524 | I17: =Daily_Balancing!G12 -> ❌ Low
A18: Agent10 | B18: =Daily_Balancing!B13 -> 878.92 | C18: =Daily_Balancing!C13 -> 0 | D18: =Daily_Balancing!D13 -> 878.92 | E18: =Daily_Balancing!E13 -> 2 | F18: =Daily_Balancing!F13 -> 2 | G18: 5000 | H18: =IFERROR(B18/G18,0) -> 0.175784 | I18: =Daily_Balancing!G13 -> ❌ Low
A19: TOTALS | B19: =SUM(B9:B18) -> 6570.67 | C19: =SUM(C9:C18) -> 0 | D19: =SUM(D9:D18) -> 6570.67 | E19: =SUM(E9:E18) -> 20 | F19: =SUM(F9:F18) -> 20 | G19: =SUM(G9:G18) -> 50000 | H19: =IFERROR(B19/G19,0) -> 0.1314134
A21: 🔔 PENDING LOAN APPROVALS | H21: 👥 CUSTOMER STATISTICS
A22: Loan ID | B22: Account # | C22: Customer | D22: Amount (GHC) | E22: Purpose | F22: Agent | H22: Total Active Customers | K22: =COUNTIF(Master_Customers!T2:T1000,"Active") -> 20
A23: =IFERROR(INDEX(Active_Loans!A3:A200,MATCH("Pending",Active_Loans!K3:K200,0)),"") -> LN202604120002 | B23: =IFERROR(INDEX(Active_Loans!B3:B200,MATCH("Pending",Active_Loans!K3:K200,0)),"") -> SAM20240200005 | C23: =IFERROR(INDEX(Active_Loans!C3:C200,MATCH("Pending",Active_Loans!K3:K200,0)),"") -> Yaw Darko | D23: =IFERROR(INDEX(Active_Loans!E3:E200,MATCH("Pending",Active_Loans!K3:K200,0)),"") -> 5000 | E23: =IFERROR(INDEX(Active_Loans!F3:F200,MATCH("Pending",Active_Loans!K3:K200,0)),"") -> School fees | F23: =IFERROR(INDEX(Active_Loans!L3:L200,MATCH("Pending",Active_Loans!K3:K200,0)),"") -> Agent03 | H23: Total Savings Portfolio | K23: =SUM(Master_Customers!P2:P1000) -> 35770.16
H24: Total Withdrawals | K24: =SUM(Master_Customers!Q2:Q1000) -> 4561.65
H25: Total Loan Portfolio | K25: =SUM(Active_Loans!E3:E200) -> 19500
H26: Pending KYC Verifications | K26: =COUNTIF(Master_Customers!L2:L1000,"Pending") -> 0
H27: This Month New Accounts | K27: =COUNTIF(Master_Customers!K2:K1000,">="&DATE(YEAR(TODAY()),MONTH(TODAY()),1)) -> 0
A30: 🔗 QUICK NAVIGATION — Click any sheet tab below, or use Ctrl+Page Up/Down to navigate between agents
A31: 📂 Savings | B31: 🏧 Withdrawals | C31: 💳 Loans | D31: 👤 Account Opening | E31: 📊 Daily Balance | F31: 📅 Weekly | G31: 📆 Monthly | H31: 📋 Transactions | I31: 🔒 Audit

Sheet Account_Opening
A1: 👤 NEW CUSTOMER ACCOUNT OPENING FORM
A2: SAMICIOUS MICROFINANCE | Complete all required fields marked with *
A3: 🔑 SYSTEM-GENERATED ACCOUNT NUMBER WILL APPEAR BELOW AFTER SUBMISSION
A5: * First Name:
A6: * Last Name:
A7: * Ghana Card Number:
A8: * Phone Number:
A9: * Physical Address:
A10: * Occupation:
A11: * Assigned Agent:
A12: Opening Balance (GHC):
A13: 📄 KYC DOCUMENTS CHECKLIST
A14: Passport Photo uploaded: | C14: ☐ Pending
A15: Ghana Card (Front) captured: | C15: ☐ Pending
A16: Ghana Card (Back) captured: | C16: ☐ Pending
A17: Proof of Address provided: | C17: ☐ Pending
A19: ✅ GENERATED ACCOUNT NUMBER
A20: =IF(C5="","Please complete form above and click CREATE ACCOUNT","SAM"&TEXT(TODAY(),"YYYY")&TEXT(TODAY(),"MM")&"XXXXX (Auto-generated by system)") -> Please complete form above and click CREATE ACCOUNT
A21: ⚠️ After form completion, use the VBA macro "CreateNewAccount" to auto-generate account number

Sheet Agent01_Savings
A1: 💰 SAMICIOUS MICROFINANCE — AGENT01 SAVINGS
A2: Agent: Agent01 | Date: 2026-04-12 | Module: Daily Savings Collection
B3: Daily Target (GHC) | E3: Total Collected | H3: Remaining
B4: 5000 | E4: =SUMIF(I9:I1008,"SAVED",E9:E1008) -> 731.47 | H4: =IF(B4-E4<0,"TARGET MET!",B4-E4) -> 4268.53
A5: =IF(B4-E4<=0,"✅ DAILY TARGET ACHIEVED! Great work Agent01!","⏳ Collection in progress — Keep going!") -> ⏳ Collection in progress — Keep going!
A7: 📝 TRANSACTION ENTRY — Enter Account Number and Amount, then click RECORD or press Ctrl+S
A8: Account # | B8: Customer Name | C8: Current Balance | D8: Date | E8: Savings Amount | F8: New Balance | G8: Receipt # | H8: Agent | I8: Status | J8: Saved At
A9: SAM20240100001 | B9: =IF(A9="","",IFERROR(VLOOKUP(A9,Master_Customers!$A:$D,4,FALSE()),"❌ Not Found")) -> Kwame Asare | C9: =IF(A9="","",IFERROR(VLOOKUP(A9,Master_Customers!$A:$O,15,FALSE()),"")) -> 2436.65 | D9: 2026-04-12 | E9: 308.79 | F9: =IF(E9="","",IF(C9="","",C9+E9)) -> 2745.44 | H9: Agent01 | I9: SAVED | J9: 2026-04-12
A10: SAM20240100002 | B10: =IF(A10="","",IFERROR(VLOOKUP(A10,Master_Customers!$A:$D,4,FALSE()),"❌ Not Found")) -> Ama Mensah | C10: =IF(A10="","",IFERROR(VLOOKUP(A10,Master_Customers!$A:$O,15,FALSE()),"")) -> 2024.1 | D10: 2026-04-12 | E10: 422.68 | F10: =IF(E10="","",IF(C10="","",C10+E10)) -> 2446.78 | H10: Agent01 | I10: SAVED | J10: 2026-04-12
B11: =IF(A11="","",IFERROR(VLOOKUP(A11,Master_Customers!$A:$D,4,FALSE()),"❌ Not Found")) | C11: =IF(A11="","",IFERROR(VLOOKUP(A11,Master_Customers!$A:$O,15,FALSE()),"")) | F11: =IF(E11="","",IF(C11="","",C11+E11))
B12: =IF(A12="","",IFERROR(VLOOKUP(A12,Master_Customers!$A:$D,4,FALSE()),"❌ Not Found")) | C12: =IF(A12="","",IFERROR(VLOOKUP(A12,Master_Customers!$A:$O,15,FALSE()),"")) | F12: =IF(E12="","",IF(C12="","",C12+E12))
B13: =IF(A13="","",IFERROR(VLOOKUP(A13,Master_Customers!$A:$D,4,FALSE()),"❌ Not Found")) | C13: =IF(A13="","",IFERROR(VLOOKUP(A13,Master_Customers!$A:$O,15,FALSE()),"")) | F13: =IF(E13="","",IF(C13="","",C13+E13))
B14: =IF(A14="","",IFERROR(VLOOKUP(A14,Master_Customers!$A:$D,4,FALSE()),"❌ Not Found")) | C14: =IF(A14="","",IFERROR(VLOOKUP(A14,Master_Customers!$A:$O,15,FALSE()),"")) | F14: =IF(E14="","",IF(C14="","",C14+E14))
B15: =IF(A15="","",IFERROR(VLOOKUP(A15,Master_Customers!$A:$D,4,FALSE()),"❌ Not Found")) | C15: =IF(A15="","",IFERROR(VLOOKUP(A15,Master_Customers!$A:$O,15,FALSE()),"")) | F15: =IF(E15="","",IF(C15="","",C15+E15))
B16: =IF(A16="","",IFERROR(VLOOKUP(A16,Master_Customers!$A:$D,4,FALSE()),"❌ Not Found")) | C16: =IF(A16="","",IFERROR(VLOOKUP(A16,Master_Customers!$A:$O,15,FALSE()),"")) | F16: =IF(E16="","",IF(C16="","",C16+E16))
B17: =IF(A17="","",IFERROR(VLOOKUP(A17,Master_Customers!$A:$D,4,FALSE()),"❌ Not Found")) | C17: =IF(A17="","",IFERROR(VLOOKUP(A17,Master_Customers!$A:$O,15,FALSE()),"")) | F17: =IF(E17="","",IF(C17="","",C17+E17))
B18: =IF(A18="","",IFERROR(VLOOKUP(A18,Master_Customers!$A:$D,4,FALSE()),"❌ Not Found")) | C18: =IF(A18="","",IFERROR(VLOOKUP(A18,Master_Customers!$A:$O,15,FALSE()),"")) | F18: =IF(E18="","",IF(C18="","",C18+E18))
B19: =IF(A19="","",IFERROR(VLOOKUP(A19,Master_Customers!$A:$D,4,FALSE()),"❌ Not Found")) | C19: =IF(A19="","",IFERROR(VLOOKUP(A19,Master_Customers!$A:$O,15,FALSE()),"")) | F19: =IF(E19="","",IF(C19="","",C19+E19))
B20: =IF(A20="","",IFERROR(VLOOKUP(A20,Master_Customers!$A:$D,4,FALSE()),"❌ Not Found")) | C20: =IF(A20="","",IFERROR(VLOOKUP(A20,Master_Customers!$A:$O,15,FALSE()),"")) | F20: =IF(E20="","",IF(C20="","",C20+E20))
B21: =IF(A21="","",IFERROR(VLOOKUP(A21,Master_Customers!$A:$D,4,FALSE()),"❌ Not Found")) | C21: =IF(A21="","",IFERROR(VLOOKUP(A21,Master_Customers!$A:$O,15,FALSE()),"")) | F21: =IF(E21="","",IF(C21="","",C21+E21))
B22: =IF(A22="","",IFERROR(VLOOKUP(A22,Master_Customers!$A:$D,4,FALSE()),"❌ Not Found")) | C22: =IF(A22="","",IFERROR(VLOOKUP(A22,Master_Customers!$A:$O,15,FALSE()),"")) | F22: =IF(E22="","",IF(C22="","",C22+E22))
... B1008: =IF(A1008="","",IFERROR(VLOOKUP(A1008,Master_Customers!$A:$D,4,FALSE()),"❌ Not Found")) | C1008: =IF(A1008="","",IFERROR(VLOOKUP(A1008,Master_Customers!$A:$O,15,FALSE()),"")) | F1008: =IF(E1008="","",IF(C1008="","",C1008+E1008))

Sheet Agent01_Withdrawals
A1: 🏧 SAMICIOUS MICROFINANCE — AGENT01 WITHDRAWALS
A2: Agent: Agent01 | Date: 2026-04-12 | Module: Withdrawal Processing
B3: Total Withdrawals | E3: Transactions Count | H3: Avg Withdrawal
B4: =SUMIF(I9:I1008,"SAVED",E9:E1008) -> 0 | E4: =COUNTIF(I9:I1008,"SAVED") -> 0 | H4: =IFERROR(B4/E4,0) -> 0
A5: ⚠️ WITHDRAWALS MODULE — Insufficient balance will be flagged automatically
A7: 📝 TRANSACTION ENTRY — Enter Account Number and Withdrawal Amount
A8: Account # | B8: Customer Name | C8: Available Balance | D8: Date | E8: Withdrawal Amount | F8: New Balance | G8: Authorised By | H8: Agent | I8: Status | J8: Saved At
B9: =IF(A9="","",IFERROR(VLOOKUP(A9,Master_Customers!$A:$D,4,FALSE()),"❌ Not Found")) | C9: =IF(A9="","",IFERROR(VLOOKUP(A9,Master_Customers!$A:$O,15,FALSE()),"")) | F9: =IF(E9="","",IF(C9="","",IF(E9>C9,"INSUFFICIENT FUNDS",C9-E9)))
B10: =IF(A10="","",IFERROR(VLOOKUP(A10,Master_Customers!$A:$D,4,FALSE()),"❌ Not Found")) | C10: =IF(A10="","",IFERROR(VLOOKUP(A10,Master_Customers!$A:$O,15,FALSE()),"")) | F10: =IF(E10="","",IF(C10="","",IF(E10>C10,"INSUFFICIENT FUNDS",C10-E10)))
B11: =IF(A11="","",IFERROR(VLOOKUP(A11,Master_Customers!$A:$D,4,FALSE()),"❌ Not Found")) | C11: =IF(A11="","",IFERROR(VLOOKUP(A11,Master_Customers!$A:$O,15,FALSE()),"")) | F11: =IF(E11="","",IF(C11="","",IF(E11>C11,"INSUFFICIENT FUNDS",C11-E11)))
B12: =IF(A12="","",IFERROR(VLOOKUP(A12,Master_Customers!$A:$D,4,FALSE()),"❌ Not Found")) | C12: =IF(A12="","",IFERROR(VLOOKUP(A12,Master_Customers!$A:$O,15,FALSE()),"")) | F12: =IF(E12="","",IF(C12="","",IF(E12>C12,"INSUFFICIENT FUNDS",C12-E12)))
B13: =IF(A13="","",IFERROR(VLOOKUP(A13,Master_Customers!$A:$D,4,FALSE()),"❌ Not Found")) | C13: =IF(A13="","",IFERROR(VLOOKUP(A13,Master_Customers!$A:$O,15,FALSE()),"")) | F13: =IF(E13="","",IF(C13="","",IF(E13>C13,"INSUFFICIENT FUNDS",C13-E13)))
B14: =IF(A14="","",IFERROR(VLOOKUP(A14,Master_Customers!$A:$D,4,FALSE()),"❌ Not Found")) | C14: =IF(A14="","",IFERROR(VLOOKUP(A14,Master_Customers!$A:$O,15,FALSE()),"")) | F14: =IF(E14="","",IF(C14="","",IF(E14>C14,"INSUFFICIENT FUNDS",C14-E14)))
B15: =IF(A15="","",IFERROR(VLOOKUP(A15,Master_Customers!$A:$D,4,FALSE()),"❌ Not Found")) | C15: =IF(A15="","",IFERROR(VLOOKUP(A15,Master_Customers!$A:$O,15,FALSE()),"")) | F15: =IF(E15="","",IF(C15="","",IF(E15>C15,"INSUFFICIENT FUNDS",C15-E15)))
B16: =IF(A16="","",IFERROR(VLOOKUP(A16,Master_Customers!$A:$D,4,FALSE()),"❌ Not Found")) | C16: =IF(A16="","",IFERROR(VLOOKUP(A16,Master_Customers!$A:$O,15,FALSE()),"")) | F16: =IF(E16="","",IF(C16="","",IF(E16>C16,"INSUFFICIENT FUNDS",C16-E16)))
B17: =IF(A17="","",IFERROR(VLOOKUP(A17,Master_Customers!$A:$D,4,FALSE()),"❌ Not Found")) | C17: =IF(A17="","",IFERROR(VLOOKUP(A17,Master_Customers!$A:$O,15,FALSE()),"")) | F17: =IF(E17="","",IF(C17="","",IF(E17>C17,"INSUFFICIENT FUNDS",C17-E17)))
B18: =IF(A18="","",IFERROR(VLOOKUP(A18,Master_Customers!$A:$D,4,FALSE()),"❌ Not Found")) | C18: =IF(A18="","",IFERROR(VLOOKUP(A18,Master_Customers!$A:$O,15,FALSE()),"")) | F18: =IF(E18="","",IF(C18="","",IF(E18>C18,"INSUFFICIENT FUNDS",C18-E18)))
B19: =IF(A19="","",IFERROR(VLOOKUP(A19,Master_Customers!$A:$D,4,FALSE()),"❌ Not Found")) | C19: =IF(A19="","",IFERROR(VLOOKUP(A19,Master_Customers!$A:$O,15,FALSE()),"")) | F19: =IF(E19="","",IF(C19="","",IF(E19>C19,"INSUFFICIENT FUNDS",C19-E19)))
B20: =IF(A20="","",IFERROR(VLOOKUP(A20,Master_Customers!$A:$D,4,FALSE()),"❌ Not Found")) | C20: =IF(A20="","",IFERROR(VLOOKUP(A20,Master_Customers!$A:$O,15,FALSE()),"")) | F20: =IF(E20="","",IF(C20="","",IF(E20>C20,"INSUFFICIENT FUNDS",C20-E20)))
... B1008: =IF(A1008="","",IFERROR(VLOOKUP(A1008,Master_Customers!$A:$D,4,FALSE()),"❌ Not Found")) | C1008: =IF(A1008="","",IFERROR(VLOOKUP(A1008,Master_Customers!$A:$O,15,FALSE()),"")) | F1008: =IF(E1008="","",IF(C1008="","",IF(E1008>C1008,"INSUFFICIENT FUNDS",C1008-E1008)))

Sheet Agent01_Loans
A1: 🏦 SAMICIOUS MICROFINANCE — AGENT01 LOAN REQUESTS
A2: Agent: Agent01 | Interest Rate: 2.5% p/m (flat) | Min: GHC 100 | Max: GHC 50,000
A4: 🔢 LOAN CALCULATOR
A5: Loan Amount (GHC):
A6: Repayment (months):
A7: Interest Rate (%/m): | B7: 2.5
A8: Total Interest (GHC): | B8: =IF(B5="","",B5*B7/100*B6)
A9: Total Repayable (GHC): | B9: =IF(B5="","",B5+B8)
A10: Monthly Installment (GHC): | B10: =IF(B5="","",B9/B6)
A12: 📋 LOAN REQUEST SUBMISSIONS — Enter details below to submit for manager approval
A13: Loan ID | B13: Account # | C13: Customer Name | D13: Request Date | E13: Loan Amount | F13: Purpose | G13: Months | H13: Rate % | I13: Total Repayable | J13: Monthly Install | K13: Status | L13: Notes
A14: LN202604120014 | B14: SAM20240100001 | C14: Kwame Asare | D14: 2026-04-12 | E14: 1110.5 | F14: Business | G14: 6 | H14: 2.5 | I14: 1277.08 | J14: 212.85 | K14: Pending
A15: LN202604120015 | B15: SAM20240100002 | C15: Ama Mensah | D15: 2026-04-12 | E15: 7875.79 | F15: Business | G15: 6 | H15: 2.5 | I15: 9057.16 | J15: 1509.53 | K15: Pending
C16: =IF(B16="","",IFERROR(VLOOKUP(B16,Master_Customers!$A:$D,4,FALSE()),"❌ Not Found")) | I16: =IF(E16="","",E16+E16*H16/100*G16) | J16: =IFERROR(I16/G16,"")
C17: =IF(B17="","",IFERROR(VLOOKUP(B17,Master_Customers!$A:$D,4,FALSE()),"❌ Not Found")) | I17: =IF(E17="","",E17+E17*H17/100*G17) | J17: =IFERROR(I17/G17,"")
C18: =IF(B18="","",IFERROR(VLOOKUP(B18,Master_Customers!$A:$D,4,FALSE()),"❌ Not Found")) | I18: =IF(E18="","",E18+E18*H18/100*G18) | J18: =IFERROR(I18/G18,"")
C19: =IF(B19="","",IFERROR(VLOOKUP(B19,Master_Customers!$A:$D,4,FALSE()),"❌ Not Found")) | I19: =IF(E19="","",E19+E19*H19/100*G19) | J19: =IFERROR(I19/G19,"")
C20: =IF(B20="","",IFERROR(VLOOKUP(B20,Master_Customers!$A:$D,4,FALSE()),"❌ Not Found")) | I20: =IF(E20="","",E20+E20*H20/100*G20) | J20: =IFERROR(I20/G20,"")
C21: =IF(B21="","",IFERROR(VLOOKUP(B21,Master_Customers!$A:$D,4,FALSE()),"❌ Not Found")) | I21: =IF(E21="","",E21+E21*H21/100*G21) | J21: =IFERROR(I21/G21,"")
C22: =IF(B22="","",IFERROR(VLOOKUP(B22,Master_Customers!$A:$D,4,FALSE()),"❌ Not Found")) | I22: =IF(E22="","",E22+E22*H22/100*G22) | J22: =IFERROR(I22/G22,"")
C23: =IF(B23="","",IFERROR(VLOOKUP(B23,Master_Customers!$A:$D,4,FALSE()),"❌ Not Found")) | I23: =IF(E23="","",E23+E23*H23/100*G23) | J23: =IFERROR(I23/G23,"")
C24: =IF(B24="","",IFERROR(VLOOKUP(B24,Master_Customers!$A:$D,4,FALSE()),"❌ Not Found")) | I24: =IF(E24="","",E24+E24*H24/100*G24) | J24: =IFERROR(I24/G24,"")
C25: =IF(B25="","",IFERROR(VLOOKUP(B25,Master_Customers!$A:$D,4,FALSE()),"❌ Not Found")) | I25: =IF(E25="","",E25+E25*H25/100*G25) | J25: =IFERROR(I25/G25,"")
C26: =IF(B26="","",IFERROR(VLOOKUP(B26,Master_Customers!$A:$D,4,FALSE()),"❌ Not Found")) | I26: =IF(E26="","",E26+E26*H26/100*G26) | J26: =IFERROR(I26/G26,"")
C27: =IF(B27="","",IFERROR(VLOOKUP(B27,Master_Customers!$A:$D,4,FALSE()),"❌ Not Found")) | I27: =IF(E27="","",E27+E27*H27/100*G27) | J27: =IFERROR(I27/G27,"")
... C213: =IF(B213="","",IFERROR(VLOOKUP(B213,Master_Customers!$A:$D,4,FALSE()),"❌ Not Found")) | I213: =IF(E213="","",E213+E213*H213/100*G213) | J213: =IFERROR(I213/G213,"")

Sheet Agent02_Savings
A1: 💰 SAMICIOUS MICROFINANCE — AGENT02 SAVINGS
A2: Agent: Agent02 | Date: 2026-04-12 | Module: Daily Savings Collection
B3: Daily Target (GHC) | E3: Total Collected | H3: Remaining
B4: 5000 | E4: =SUMIF(I9:I1008,"SAVED",E9:E1008) -> 645.87 | H4: =IF(B4-E4<0,"TARGET MET!",B4-E4) -> 4354.13
A5: =IF(B4-E4<=0,"✅ DAILY TARGET ACHIEVED! Great work Agent02!","⏳ Collection in progress — Keep going!") -> ⏳ Collection in progress — Keep going!
A7: 📝 TRANSACTION ENTRY — Enter Account Number and Amount, then click RECORD or press Ctrl+S
A8: Account # | B8: Customer Name | C8: Current Balance | D8: Date | E8: Savings Amount | F8: New Balance | G8: Receipt # | H8: Agent | I8: Status | J8: Saved At
A9: SAM20240200003 | B9: =IF(A9="","",IFERROR(VLOOKUP(A9,Master_Customers!$A:$D,4,FALSE()),"❌ Not Found")) -> Kofi Boateng | C9: =IF(A9="","",IFERROR(VLOOKUP(A9,Master_Customers!$A:$O,15,FALSE()),"")) -> 2829.41 | D9: 2026-04-12 | E9: 311.57 | F9: =IF(E9="","",IF(C9="","",C9+E9)) -> 3140.98 | H9: Agent02 | I9: SAVED | J9: 2026-04-12
A10: SAM20240200004 | B10: =IF(A10="","",IFERROR(VLOOKUP(A10,Master_Customers!$A:$D,4,FALSE()),"❌ Not Found")) -> Abena Owusu | C10: =IF(A10="","",IFERROR(VLOOKUP(A10,Master_Customers!$A:$O,15,FALSE()),"")) -> 2942.01 | D10: 2026-04-12 | E10: 334.3 | F10: =IF(E10="","",IF(C10="","",C10+E10)) -> 3276.31 | H10: Agent02 | I10: SAVED | J10: 2026-04-12
B11: =IF(A11="","",IFERROR(VLOOKUP(A11,Master_Customers!$A:$D,4,FALSE()),"❌ Not Found")) | C11: =IF(A11="","",IFERROR(VLOOKUP(A11,Master_Customers!$A:$O,15,FALSE()),"")) | F11: =IF(E11="","",IF(C11="","",C11+E11))
B12: =IF(A12="","",IFERROR(VLOOKUP(A12,Master_Customers!$A:$D,4,FALSE()),"❌ Not Found")) | C12: =IF(A12="","",IFERROR(VLOOKUP(A12,Master_Customers!$A:$O,15,FALSE()),"")) | F12: =IF(E12="","",IF(C12="","",C12+E12))
B13: =IF(A13="","",IFERROR(VLOOKUP(A13,Master_Customers!$A:$D,4,FALSE()),"❌ Not Found")) | C13: =IF(A13="","",IFERROR(VLOOKUP(A13,Master_Customers!$A:$O,15,FALSE()),"")) | F13: =IF(E13="","",IF(C13="","",C13+E13))
B14: =IF(A14="","",IFERROR(VLOOKUP(A14,Master_Customers!$A:$D,4,FALSE()),"❌ Not Found")) | C14: =IF(A14="","",IFERROR(VLOOKUP(A14,Master_Customers!$A:$O,15,FALSE()),"")) | F14: =IF(E14="","",IF(C14="","",C14+E14))
B15: =IF(A15="","",IFERROR(VLOOKUP(A15,Master_Customers!$A:$D,4,FALSE()),"❌ Not Found")) | C15: =IF(A15="","",IFERROR(VLOOKUP(A15,Master_Customers!$A:$O,15,FALSE()),"")) | F15: =IF(E15="","",IF(C15="","",C15+E15))
B16: =IF(A16="","",IFERROR(VLOOKUP(A16,Master_Customers!$A:$D,4,FALSE()),"❌ Not Found")) | C16: =IF(A16="","",IFERROR(VLOOKUP(A16,Master_Customers!$A:$O,15,FALSE()),"")) | F16: =IF(E16="","",IF(C16="","",C16+E16))
B17: =IF(A17="","",IFERROR(VLOOKUP(A17,Master_Customers!$A:$D,4,FALSE()),"❌ Not Found")) | C17: =IF(A17="","",IFERROR(VLOOKUP(A17,Master_Customers!$A:$O,15,FALSE()),"")) | F17: =IF(E17="","",IF(C17="","",C17+E17))
B18: =IF(A18="","",IFERROR(VLOOKUP(A18,Master_Customers!$A:$D,4,FALSE()),"❌ Not Found")) | C18: =IF(A18="","",IFERROR(VLOOKUP(A18,Master_Customers!$A:$O,15,FALSE()),"")) | F18: =IF(E18="","",IF(C18="","",C18+E18))
B19: =IF(A19="","",IFERROR(VLOOKUP(A19,Master_Customers!$A:$D,4,FALSE()),"❌ Not Found")) | C19: =IF(A19="","",IFERROR(VLOOKUP(A19,Master_Customers!$A:$O,15,FALSE()),"")) | F19: =IF(E19="","",IF(C19="","",C19+E19))
B20: =IF(A20="","",IFERROR(VLOOKUP(A20,Master_Customers!$A:$D,4,FALSE()),"❌ Not Found")) | C20: =IF(A20="","",IFERROR(VLOOKUP(A20,Master_Customers!$A:$O,15,FALSE()),"")) | F20: =IF(E20="","",IF(C20="","",C20+E20))
B21: =IF(A21="","",IFERROR(VLOOKUP(A21,Master_Customers!$A:$D,4,FALSE()),"❌ Not Found")) | C21: =IF(A21="","",IFERROR(VLOOKUP(A21,Master_Customers!$A:$O,15,FALSE()),"")) | F21: =IF(E21="","",IF(C21="","",C21+E21))
B22: =IF(A22="","",IFERROR(VLOOKUP(A22,Master_Customers!$A:$D,4,FALSE()),"❌ Not Found")) | C22: =IF(A22="","",IFERROR(VLOOKUP(A22,Master_Customers!$A:$O,15,FALSE()),"")) | F22: =IF(E22="","",IF(C22="","",C22+E22))
... B1008: =IF(A1008="","",IFERROR(VLOOKUP(A1008,Master_Customers!$A:$D,4,FALSE()),"❌ Not Found")) | C1008: =IF(A1008="","",IFERROR(VLOOKUP(A1008,Master_Customers!$A:$O,15,FALSE()),"")) | F1008: =IF(E1008="","",IF(C1008="","",C1008+E1008))

Sheet Agent02_Withdrawals
A1: 🏧 SAMICIOUS MICROFINANCE — AGENT02 WITHDRAWALS
A2: Agent: Agent02 | Date: 2026-04-12 | Module: Withdrawal Processing
B3: Total Withdrawals | E3: Transactions Count | H3: Avg Withdrawal
B4: =SUMIF(I9:I1008,"SAVED",E9:E1008) -> 0 | E4: =COUNTIF(I9:I1008,"SAVED") -> 0 | H4: =IFERROR(B4/E4,0) -> 0
A5: ⚠️ WITHDRAWALS MODULE — Insufficient balance will be flagged automatically
A7: 📝 TRANSACTION ENTRY — Enter Account Number and Withdrawal Amount
A8: Account # | B8: Customer Name | C8: Available Balance | D8: Date | E8: Withdrawal Amount | F8: New Balance | G8: Authorised By | H8: Agent | I8: Status | J8: Saved At
B9: =IF(A9="","",IFERROR(VLOOKUP(A9,Master_Customers!$A:$D,4,FALSE()),"❌ Not Found")) | C9: =IF(A9="","",IFERROR(VLOOKUP(A9,Master_Customers!$A:$O,15,FALSE()),"")) | F9: =IF(E9="","",IF(C9="","",IF(E9>C9,"INSUFFICIENT FUNDS",C9-E9)))
B10: =IF(A10="","",IFERROR(VLOOKUP(A10,Master_Customers!$A:$D,4,FALSE()),"❌ Not Found")) | C10: =IF(A10="","",IFERROR(VLOOKUP(A10,Master_Customers!$A:$O,15,FALSE()),"")) | F10: =IF(E10="","",IF(C10="","",IF(E10>C10,"INSUFFICIENT FUNDS",C10-E10)))
B11: =IF(A11="","",IFERROR(VLOOKUP(A11,Master_Customers!$A:$D,4,FALSE()),"❌ Not Found")) | C11: =IF(A11="","",IFERROR(VLOOKUP(A11,Master_Customers!$A:$O,15,FALSE()),"")) | F11: =IF(E11="","",IF(C11="","",IF(E11>C11,"INSUFFICIENT FUNDS",C11-E11)))
B12: =IF(A12="","",IFERROR(VLOOKUP(A12,Master_Customers!$A:$D,4,FALSE()),"❌ Not Found")) | C12: =IF(A12="","",IFERROR(VLOOKUP(A12,Master_Customers!$A:$O,15,FALSE()),"")) | F12: =IF(E12="","",IF(C12="","",IF(E12>C12,"INSUFFICIENT FUNDS",C12-E12)))
B13: =IF(A13="","",IFERROR(VLOOKUP(A13,Master_Customers!$A:$D,4,FALSE()),"❌ Not Found")) | C13: =IF(A13="","",IFERROR(VLOOKUP(A13,Master_Customers!$A:$O,15,FALSE()),"")) | F13: =IF(E13="","",IF(C13="","",IF(E13>C13,"INSUFFICIENT FUNDS",C13-E13)))
B14: =IF(A14="","",IFERROR(VLOOKUP(A14,Master_Customers!$A:$D,4,FALSE()),"❌ Not Found")) | C14: =IF(A14="","",IFERROR(VLOOKUP(A14,Master_Customers!$A:$O,15,FALSE()),"")) | F14: =IF(E14="","",IF(C14="","",IF(E14>C14,"INSUFFICIENT FUNDS",C14-E14)))
B15: =IF(A15="","",IFERROR(VLOOKUP(A15,Master_Customers!$A:$D,4,FALSE()),"❌ Not Found")) | C15: =IF(A15="","",IFERROR(VLOOKUP(A15,Master_Customers!$A:$O,15,FALSE()),"")) | F15: =IF(E15="","",IF(C15="","",IF(E15>C15,"INSUFFICIENT FUNDS",C15-E15)))
B16: =IF(A16="","",IFERROR(VLOOKUP(A16,Master_Customers!$A:$D,4,FALSE()),"❌ Not Found")) | C16: =IF(A16="","",IFERROR(VLOOKUP(A16,Master_Customers!$A:$O,15,FALSE()),"")) | F16: =IF(E16="","",IF(C16="","",IF(E16>C16,"INSUFFICIENT FUNDS",C16-E16)))
B17: =IF(A17="","",IFERROR(VLOOKUP(A17,Master_Customers!$A:$D,4,FALSE()),"❌ Not Found")) | C17: =IF(A17="","",IFERROR(VLOOKUP(A17,Master_Customers!$A:$O,15,FALSE()),"")) | F17: =IF(E17="","",IF(C17="","",IF(E17>C17,"INSUFFICIENT FUNDS",C17-E17)))
B18: =IF(A18="","",IFERROR(VLOOKUP(A18,Master_Customers!$A:$D,4,FALSE()),"❌ Not Found")) | C18: =IF(A18="","",IFERROR(VLOOKUP(A18,Master_Customers!$A:$O,15,FALSE()),"")) | F18: =IF(E18="","",IF(C18="","",IF(E18>C18,"INSUFFICIENT FUNDS",C18-E18)))
B19: =IF(A19="","",IFERROR(VLOOKUP(A19,Master_Customers!$A:$D,4,FALSE()),"❌ Not Found")) | C19: =IF(A19="","",IFERROR(VLOOKUP(A19,Master_Customers!$A:$O,15,FALSE()),"")) | F19: =IF(E19="","",IF(C19="","",IF(E19>C19,"INSUFFICIENT FUNDS",C19-E19)))
B20: =IF(A20="","",IFERROR(VLOOKUP(A20,Master_Customers!$A:$D,4,FALSE()),"❌ Not Found")) | C20: =IF(A20="","",IFERROR(VLOOKUP(A20,Master_Customers!$A:$O,15,FALSE()),"")) | F20: =IF(E20="","",IF(C20="","",IF(E20>C20,"INSUFFICIENT FUNDS",C20-E20)))
... B1008: =IF(A1008="","",IFERROR(VLOOKUP(A1008,Master_Customers!$A:$D,4,FALSE()),"❌ Not Found")) | C1008: =IF(A1008="","",IFERROR(VLOOKUP(A1008,Master_Customers!$A:$O,15,FALSE()),"")) | F1008: =IF(E1008="","",IF(C1008="","",IF(E1008>C1008,"INSUFFICIENT FUNDS",C1008-E1008)))

Sheet Agent02_Loans
A1: 🏦 SAMICIOUS MICROFINANCE — AGENT02 LOAN REQUESTS
A2: Agent: Agent02 | Interest Rate: 2.5% p/m (flat) | Min: GHC 100 | Max: GHC 50,000
A4: 🔢 LOAN CALCULATOR
A5: Loan Amount (GHC):
A6: Repayment (months):
A7: Interest Rate (%/m): | B7: 2.5
A8: Total Interest (GHC): | B8: =IF(B5="","",B5*B7/100*B6)
A9: Total Repayable (GHC): | B9: =IF(B5="","",B5+B8)
A10: Monthly Installment (GHC): | B10: =IF(B5="","",B9/B6)
A12: 📋 LOAN REQUEST SUBMISSIONS — Enter details below to submit for manager approval
A13: Loan ID | B13: Account # | C13: Customer Name | D13: Request Date | E13: Loan Amount | F13: Purpose | G13: Months | H13: Rate % | I13: Total Repayable | J13: Monthly Install | K13: Status | L13: Notes
A14: LN202604120014 | B14: SAM20240200003 | C14: Kofi Boateng | D14: 2026-04-12 | E14: 9351.92 | F14: Business | G14: 6 | H14: 2.5 | I14: 10754.71 | J14: 1792.45 | K14: Pending
A15: LN202604120015 | B15: SAM20240200004 | C15: Abena Owusu | D15: 2026-04-12 | E15: 1586.39 | F15: Business | G15: 6 | H15: 2.5 | I15: 1824.35 | J15: 304.06 | K15: Pending
C16: =IF(B16="","",IFERROR(VLOOKUP(B16,Master_Customers!$A:$D,4,FALSE()),"❌ Not Found")) | I16: =IF(E16="","",E16+E16*H16/100*G16) | J16: =IFERROR(I16/G16,"")
C17: =IF(B17="","",IFERROR(VLOOKUP(B17,Master_Customers!$A:$D,4,FALSE()),"❌ Not Found")) | I17: =IF(E17="","",E17+E17*H17/100*G17) | J17: =IFERROR(I17/G17,"")
C18: =IF(B18="","",IFERROR(VLOOKUP(B18,Master_Customers!$A:$D,4,FALSE()),"❌ Not Found")) | I18: =IF(E18="","",E18+E18*H18/100*G18) | J18: =IFERROR(I18/G18,"")
C19: =IF(B19="","",IFERROR(VLOOKUP(B19,Master_Customers!$A:$D,4,FALSE()),"❌ Not Found")) | I19: =IF(E19="","",E19+E19*H19/100*G19) | J19: =IFERROR(I19/G19,"")
C20: =IF(B20="","",IFERROR(VLOOKUP(B20,Master_Customers!$A:$D,4,FALSE()),"❌ Not Found")) | I20: =IF(E20="","",E20+E20*H20/100*G20) | J20: =IFERROR(I20/G20,"")
C21: =IF(B21="","",IFERROR(VLOOKUP(B21,Master_Customers!$A:$D,4,FALSE()),"❌ Not Found")) | I21: =IF(E21="","",E21+E21*H21/100*G21) | J21: =IFERROR(I21/G21,"")
C22: =IF(B22="","",IFERROR(VLOOKUP(B22,Master_Customers!$A:$D,4,FALSE()),"❌ Not Found")) | I22: =IF(E22="","",E22+E22*H22/100*G22) | J22: =IFERROR(I22/G22,"")
C23: =IF(B23="","",IFERROR(VLOOKUP(B23,Master_Customers!$A:$D,4,FALSE()),"❌ Not Found")) | I23: =IF(E23="","",E23+E23*H23/100*G23) | J23: =IFERROR(I23/G23,"")
C24: =IF(B24="","",IFERROR(VLOOKUP(B24,Master_Customers!$A:$D,4,FALSE()),"❌ Not Found")) | I24: =IF(E24="","",E24+E24*H24/100*G24) | J24: =IFERROR(I24/G24,"")
C25: =IF(B25="","",IFERROR(VLOOKUP(B25,Master_Customers!$A:$D,4,FALSE()),"❌ Not Found")) | I25: =IF(E25="","",E25+E25*H25/100*G25) | J25: =IFERROR(I25/G25,"")
C26: =IF(B26="","",IFERROR(VLOOKUP(B26,Master_Customers!$A:$D,4,FALSE()),"❌ Not Found")) | I26: =IF(E26="","",E26+E26*H26/100*G26) | J26: =IFERROR(I26/G26,"")
C27: =IF(B27="","",IFERROR(VLOOKUP(B27,Master_Customers!$A:$D,4,FALSE()),"❌ Not Found")) | I27: =IF(E27="","",E27+E27*H27/100*G27) | J27: =IFERROR(I27/G27,"")
... C213: =IF(B213="","",IFERROR(VLOOKUP(B213,Master_Customers!$A:$D,4,FALSE()),"❌ Not Found")) | I213: =IF(E213="","",E213+E213*H213/100*G213) | J213: =IFERROR(I213/G213,"")

Sheet Agent03_Savings
A1: 💰 SAMICIOUS MICROFINANCE — AGENT03 SAVINGS
A2: Agent: Agent03 | Date: 2026-04-12 | Module: Daily Savings Collection
B3: Daily Target (GHC) | E3: Total Collected | H3: Remaining
B4: 5000 | E4: =SUMIF(I9:I1008,"SAVED",E9:E1008) -> 498.29 | H4: =IF(B4-E4<0,"TARGET MET!",B4-E4) -> 4501.71
A5: =IF(B4-E4<=0,"✅ DAILY TARGET ACHIEVED! Great work Agent03!","⏳ Collection in progress — Keep going!") -> ⏳ Collection in progress — Keep going!
A7: 📝 TRANSACTION ENTRY — Enter Account Number and Amount, then click RECORD or press Ctrl+S
A8: Account # | B8: Customer Name | C8: Current Balance | D8: Date | E8: Savings Amount | F8: New Balance | G8: Receipt # | H8: Agent | I8: Status | J8: Saved At
A9: SAM20240200005 | B9: =IF(A9="","",IFERROR(VLOOKUP(A9,Master_Customers!$A:$D,4,FALSE()),"❌ Not Found")) -> Yaw Darko | C9: =IF(A9="","",IFERROR(VLOOKUP(A9,Master_Customers!$A:$O,15,FALSE()),"")) -> 3808.17 | D9: 2026-04-12 | E9: 197.41 | F9: =IF(E9="","",IF(C9="","",C9+E9)) -> 4005.58 | H9: Agent03 | I9: SAVED | J9: 2026-04-12
A10: SAM20240300006 | B10: =IF(A10="","",IFERROR(VLOOKUP(A10,Master_Customers!$A:$D,4,FALSE()),"❌ Not Found")) -> Efua Kumi | C10: =IF(A10="","",IFERROR(VLOOKUP(A10,Master_Customers!$A:$O,15,FALSE()),"")) -> 1106.6 | D10: 2026-04-12 | E10: 300.88 | F10: =IF(E10="","",IF(C10="","",C10+E10)) -> 1407.48 | H10: Agent03 | I10: SAVED | J10: 2026-04-12
B11: =IF(A11="","",IFERROR(VLOOKUP(A11,Master_Customers!$A:$D,4,FALSE()),"❌ Not Found")) | C11: =IF(A11="","",IFERROR(VLOOKUP(A11,Master_Customers!$A:$O,15,FALSE()),"")) | F11: =IF(E11="","",IF(C11="","",C11+E11))
B12: =IF(A12="","",IFERROR(VLOOKUP(A12,Master_Customers!$A:$D,4,FALSE()),"❌ Not Found")) | C12: =IF(A12="","",IFERROR(VLOOKUP(A12,Master_Customers!$A:$O,15,FALSE()),"")) | F12: =IF(E12="","",IF(C12="","",C12+E12))
B13: =IF(A13="","",IFERROR(VLOOKUP(A13,Master_Customers!$A:$D,4,FALSE()),"❌ Not Found")) | C13: =IF(A13="","",IFERROR(VLOOKUP(A13,Master_Customers!$A:$O,15,FALSE()),"")) | F13: =IF(E13="","",IF(C13="","",C13+E13))
B14: =IF(A14="","",IFERROR(VLOOKUP(A14,Master_Customers!$A:$D,4,FALSE()),"❌ Not Found")) | C14: =IF(A14="","",IFERROR(VLOOKUP(A14,Master_Customers!$A:$O,15,FALSE()),"")) | F14: =IF(E14="","",IF(C14="","",C14+E14))
B15: =IF(A15="","",IFERROR(VLOOKUP(A15,Master_Customers!$A:$D,4,FALSE()),"❌ Not Found")) | C15: =IF(A15="","",IFERROR(VLOOKUP(A15,Master_Customers!$A:$O,15,FALSE()),"")) | F15: =IF(E15="","",IF(C15="","",C15+E15))
B16: =IF(A16="","",IFERROR(VLOOKUP(A16,Master_Customers!$A:$D,4,FALSE()),"❌ Not Found")) | C16: =IF(A16="","",IFERROR(VLOOKUP(A16,Master_Customers!$A:$O,15,FALSE()),"")) | F16: =IF(E16="","",IF(C16="","",C16+E16))
B17: =IF(A17="","",IFERROR(VLOOKUP(A17,Master_Customers!$A:$D,4,FALSE()),"❌ Not Found")) | C17: =IF(A17="","",IFERROR(VLOOKUP(A17,Master_Customers!$A:$O,15,FALSE()),"")) | F17: =IF(E17="","",IF(C17="","",C17+E17))
B18: =IF(A18="","",IFERROR(VLOOKUP(A18,Master_Customers!$A:$D,4,FALSE()),"❌ Not Found")) | C18: =IF(A18="","",IFERROR(VLOOKUP(A18,Master_Customers!$A:$O,15,FALSE()),"")) | F18: =IF(E18="","",IF(C18="","",C18+E18))
B19: =IF(A19="","",IFERROR(VLOOKUP(A19,Master_Customers!$A:$D,4,FALSE()),"❌ Not Found")) | C19: =IF(A19="","",IFERROR(VLOOKUP(A19,Master_Customers!$A:$O,15,FALSE()),"")) | F19: =IF(E19="","",IF(C19="","",C19+E19))
B20: =IF(A20="","",IFERROR(VLOOKUP(A20,Master_Customers!$A:$D,4,FALSE()),"❌ Not Found")) | C20: =IF(A20="","",IFERROR(VLOOKUP(A20,Master_Customers!$A:$O,15,FALSE()),"")) | F20: =IF(E20="","",IF(C20="","",C20+E20))
B21: =IF(A21="","",IFERROR(VLOOKUP(A21,Master_Customers!$A:$D,4,FALSE()),"❌ Not Found")) | C21: =IF(A21="","",IFERROR(VLOOKUP(A21,Master_Customers!$A:$O,15,FALSE()),"")) | F21: =IF(E21="","",IF(C21="","",C21+E21))
B22: =IF(A22="","",IFERROR(VLOOKUP(A22,Master_Customers!$A:$D,4,FALSE()),"❌ Not Found")) | C22: =IF(A22="","",IFERROR(VLOOKUP(A22,Master_Customers!$A:$O,15,FALSE()),"")) | F22: =IF(E22="","",IF(C22="","",C22+E22))
... B1008: =IF(A1008="","",IFERROR(VLOOKUP(A1008,Master_Customers!$A:$D,4,FALSE()),"❌ Not Found")) | C1008: =IF(A1008="","",IFERROR(VLOOKUP(A1008,Master_Customers!$A:$O,15,FALSE()),"")) | F1008: =IF(E1008="","",IF(C1008="","",C1008+E1008))

Sheet Agent03_Withdrawals
A1: 🏧 SAMICIOUS MICROFINANCE — AGENT03 WITHDRAWALS
A2: Agent: Agent03 | Date: 2026-04-12 | Module: Withdrawal Processing
B3: Total Withdrawals | E3: Transactions Count | H3: Avg Withdrawal
B4: =SUMIF(I9:I1008,"SAVED",E9:E1008) -> 0 | E4: =COUNTIF(I9:I1008,"SAVED") -> 0 | H4: =IFERROR(B4/E4,0) -> 0
A5: ⚠️ WITHDRAWALS MODULE — Insufficient balance will be flagged automatically
A7: 📝 TRANSACTION ENTRY — Enter Account Number and Withdrawal Amount
A8: Account # | B8: Customer Name | C8: Available Balance | D8: Date | E8: Withdrawal Amount | F8: New Balance | G8: Authorised By | H8: Agent | I8: Status | J8: Saved At
B9: =IF(A9="","",IFERROR(VLOOKUP(A9,Master_Customers!$A:$D,4,FALSE()),"❌ Not Found")) | C9: =IF(A9="","",IFERROR(VLOOKUP(A9,Master_Customers!$A:$O,15,FALSE()),"")) | F9: =IF(E9="","",IF(C9="","",IF(E9>C9,"INSUFFICIENT FUNDS",C9-E9)))
B10: =IF(A10="","",IFERROR(VLOOKUP(A10,Master_Customers!$A:$D,4,FALSE()),"❌ Not Found")) | C10: =IF(A10="","",IFERROR(VLOOKUP(A10,Master_Customers!$A:$O,15,FALSE()),"")) | F10: =IF(E10="","",IF(C10="","",IF(E10>C10,"INSUFFICIENT FUNDS",C10-E10)))
B11: =IF(A11="","",IFERROR(VLOOKUP(A11,Master_Customers!$A:$D,4,FALSE()),"❌ Not Found")) | C11: =IF(A11="","",IFERROR(VLOOKUP(A11,Master_Customers!$A:$O,15,FALSE()),"")) | F11: =IF(E11="","",IF(C11="","",IF(E11>C11,"INSUFFICIENT FUNDS",C11-E11)))
B12: =IF(A12="","",IFERROR(VLOOKUP(A12,Master_Customers!$A:$D,4,FALSE()),"❌ Not Found")) | C12: =IF(A12="","",IFERROR(VLOOKUP(A12,Master_Customers!$A:$O,15,FALSE()),"")) | F12: =IF(E12="","",IF(C12="","",IF(E12>C12,"INSUFFICIENT FUNDS",C12-E12)))
B13: =IF(A13="","",IFERROR(VLOOKUP(A13,Master_Customers!$A:$D,4,FALSE()),"❌ Not Found")) | C13: =IF(A13="","",IFERROR(VLOOKUP(A13,Master_Customers!$A:$O,15,FALSE()),"")) | F13: =IF(E13="","",IF(C13="","",IF(E13>C13,"INSUFFICIENT FUNDS",C13-E13)))
B14: =IF(A14="","",IFERROR(VLOOKUP(A14,Master_Customers!$A:$D,4,FALSE()),"❌ Not Found")) | C14: =IF(A14="","",IFERROR(VLOOKUP(A14,Master_Customers!$A:$O,15,FALSE()),"")) | F14: =IF(E14="","",IF(C14="","",IF(E14>C14,"INSUFFICIENT FUNDS",C14-E14)))
B15: =IF(A15="","",IFERROR(VLOOKUP(A15,Master_Customers!$A:$D,4,FALSE()),"❌ Not Found")) | C15: =IF(A15="","",IFERROR(VLOOKUP(A15,Master_Customers!$A:$O,15,FALSE()),"")) | F15: =IF(E15="","",IF(C15="","",IF(E15>C15,"INSUFFICIENT FUNDS",C15-E15)))
B16: =IF(A16="","",IFERROR(VLOOKUP(A16,Master_Customers!$A:$D,4,FALSE()),"❌ Not Found")) | C16: =IF(A16="","",IFERROR(VLOOKUP(A16,Master_Customers!$A:$O,15,FALSE()),"")) | F16: =IF(E16="","",IF(C16="","",IF(E16>C16,"INSUFFICIENT FUNDS",C16-E16)))
B17: =IF(A17="","",IFERROR(VLOOKUP(A17,Master_Customers!$A:$D,4,FALSE()),"❌ Not Found")) | C17: =IF(A17="","",IFERROR(VLOOKUP(A17,Master_Customers!$A:$O,15,FALSE()),"")) | F17: =IF(E17="","",IF(C17="","",IF(E17>C17,"INSUFFICIENT FUNDS",C17-E17)))
B18: =IF(A18="","",IFERROR(VLOOKUP(A18,Master_Customers!$A:$D,4,FALSE()),"❌ Not Found")) | C18: =IF(A18="","",IFERROR(VLOOKUP(A18,Master_Customers!$A:$O,15,FALSE()),"")) | F18: =IF(E18="","",IF(C18="","",IF(E18>C18,"INSUFFICIENT FUNDS",C18-E18)))
B19: =IF(A19="","",IFERROR(VLOOKUP(A19,Master_Customers!$A:$D,4,FALSE()),"❌ Not Found")) | C19: =IF(A19="","",IFERROR(VLOOKUP(A19,Master_Customers!$A:$O,15,FALSE()),"")) | F19: =IF(E19="","",IF(C19="","",IF(E19>C19,"INSUFFICIENT FUNDS",C19-E19)))
B20: =IF(A20="","",IFERROR(VLOOKUP(A20,Master_Customers!$A:$D,4,FALSE()),"❌ Not Found")) | C20: =IF(A20="","",IFERROR(VLOOKUP(A20,Master_Customers!$A:$O,15,FALSE()),"")) | F20: =IF(E20="","",IF(C20="","",IF(E20>C20,"INSUFFICIENT FUNDS",C20-E20)))
... B1008: =IF(A1008="","",IFERROR(VLOOKUP(A1008,Master_Customers!$A:$D,4,FALSE()),"❌ Not Found")) | C1008: =IF(A1008="","",IFERROR(VLOOKUP(A1008,Master_Customers!$A:$O,15,FALSE()),"")) | F1008: =IF(E1008="","",IF(C1008="","",IF(E1008>C1008,"INSUFFICIENT FUNDS",C1008-E1008)))

Sheet Agent03_Loans
A1: 🏦 SAMICIOUS MICROFINANCE — AGENT03 LOAN REQUESTS
A2: Agent: Agent03 | Interest Rate: 2.5% p/m (flat) | Min: GHC 100 | Max: GHC 50,000
A4: 🔢 LOAN CALCULATOR
A5: Loan Amount (GHC):
A6: Repayment (months):
A7: Interest Rate (%/m): | B7: 2.5
A8: Total Interest (GHC): | B8: =IF(B5="","",B5*B7/100*B6)
A9: Total Repayable (GHC): | B9: =IF(B5="","",B5+B8)
A10: Monthly Installment (GHC): | B10: =IF(B5="","",B9/B6)
A12: 📋 LOAN REQUEST SUBMISSIONS — Enter details below to submit for manager approval
A13: Loan ID | B13: Account # | C13: Customer Name | D13: Request Date | E13: Loan Amount | F13: Purpose | G13: Months | H13: Rate % | I13: Total Repayable | J13: Monthly Install | K13: Status | L13: Notes
A14: LN202604120014 | B14: SAM20240200005 | C14: Yaw Darko | D14: 2026-04-12 | E14: 9211.09 | F14: Business | G14: 9 | H14: 2.5 | I14: 11283.59 | J14: 1253.73 | K14: Pending
A15: LN202604120015 | B15: SAM20240300006 | C15: Efua Kumi | D15: 2026-04-12 | E15: 9280.02 | F15: Business | G15: 12 | H15: 2.5 | I15: 12064.03 | J15: 1005.34 | K15: Pending
C16: =IF(B16="","",IFERROR(VLOOKUP(B16,Master_Customers!$A:$D,4,FALSE()),"❌ Not Found")) | I16: =IF(E16="","",E16+E16*H16/100*G16) | J16: =IFERROR(I16/G16,"")
C17: =IF(B17="","",IFERROR(VLOOKUP(B17,Master_Customers!$A:$D,4,FALSE()),"❌ Not Found")) | I17: =IF(E17="","",E17+E17*H17/100*G17) | J17: =IFERROR(I17/G17,"")
C18: =IF(B18="","",IFERROR(VLOOKUP(B18,Master_Customers!$A:$D,4,FALSE()),"❌ Not Found")) | I18: =IF(E18="","",E18+E18*H18/100*G18) | J18: =IFERROR(I18/G18,"")
C19: =IF(B19="","",IFERROR(VLOOKUP(B19,Master_Customers!$A:$D,4,FALSE()),"❌ Not Found")) | I19: =IF(E19="","",E19+E19*H19/100*G19) | J19: =IFERROR(I19/G19,"")
C20: =IF(B20="","",IFERROR(VLOOKUP(B20,Master_Customers!$A:$D,4,FALSE()),"❌ Not Found")) | I20: =IF(E20="","",E20+E20*H20/100*G20) | J20: =IFERROR(I20/G20,"")
C21: =IF(B21="","",IFERROR(VLOOKUP(B21,Master_Customers!$A:$D,4,FALSE()),"❌ Not Found")) | I21: =IF(E21="","",E21+E21*H21/100*G21) | J21: =IFERROR(I21/G21,"")
C22: =IF(B22="","",IFERROR(VLOOKUP(B22,Master_Customers!$A:$D,4,FALSE()),"❌ Not Found")) | I22: =IF(E22="","",E22+E22*H22/100*G22) | J22: =IFERROR(I22/G22,"")
C23: =IF(B23="","",IFERROR(VLOOKUP(B23,Master_Customers!$A:$D,4,FALSE()),"❌ Not Found")) | I23: =IF(E23="","",E23+E23*H23/100*G23) | J23: =IFERROR(I23/G23,"")
C24: =IF(B24="","",IFERROR(VLOOKUP(B24,Master_Customers!$A:$D,4,FALSE()),"❌ Not Found")) | I24: =IF(E24="","",E24+E24*H24/100*G24) | J24: =IFERROR(I24/G24,"")
C25: =IF(B25="","",IFERROR(VLOOKUP(B25,Master_Customers!$A:$D,4,FALSE()),"❌ Not Found")) | I25: =IF(E25="","",E25+E25*H25/100*G25) | J25: =IFERROR(I25/G25,"")
C26: =IF(B26="","",IFERROR(VLOOKUP(B26,Master_Customers!$A:$D,4,FALSE()),"❌ Not Found")) | I26: =IF(E26="","",E26+E26*H26/100*G26) | J26: =IFERROR(I26/G26,"")
C27: =IF(B27="","",IFERROR(VLOOKUP(B27,Master_Customers!$A:$D,4,FALSE()),"❌ Not Found")) | I27: =IF(E27="","",E27+E27*H27/100*G27) | J27: =IFERROR(I27/G27,"")
... C213: =IF(B213="","",IFERROR(VLOOKUP(B213,Master_Customers!$A:$D,4,FALSE()),"❌ Not Found")) | I213: =IF(E213="","",E213+E213*H213/100*G213) | J213: =IFERROR(I213/G213,"")

Sheet Agent04_Savings
A1: 💰 SAMICIOUS MICROFINANCE — AGENT04 SAVINGS
A2: Agent: Agent04 | Date: 2026-04-12 | Module: Daily Savings Collection
B3: Daily Target (GHC) | E3: Total Collected | H3: Remaining
B4: 5000 | E4: =SUMIF(I9:I1008,"SAVED",E9:E1008) -> 872.99 | H4: =IF(B4-E4<0,"TARGET MET!",B4-E4) -> 4127.01
A5: =IF(B4-E4<=0,"✅ DAILY TARGET ACHIEVED! Great work Agent04!","⏳ Collection in progress — Keep going!") -> ⏳ Collection in progress — Keep going!
A7: 📝 TRANSACTION ENTRY — Enter Account Number and Amount, then click RECORD or press Ctrl+S
A8: Account # | B8: Customer Name | C8: Current Balance | D8: Date | E8: Savings Amount | F8: New Balance | G8: Receipt # | H8: Agent | I8: Status | J8: Saved At
A9: SAM20240300007 | B9: =IF(A9="","",IFERROR(VLOOKUP(A9,Master_Customers!$A:$D,4,FALSE()),"❌ Not Found")) -> Kojo Amponsah | C9: =IF(A9="","",IFERROR(VLOOKUP(A9,Master_Customers!$A:$O,15,FALSE()),"")) -> 1701.52 | D9: 2026-04-12 | E9: 396.67 | F9: =IF(E9="","",IF(C9="","",C9+E9)) -> 2098.19 | H9: Agent04 | I9: SAVED | J9: 2026-04-12
A10: SAM20240300008 | B10: =IF(A10="","",IFERROR(VLOOKUP(A10,Master_Customers!$A:$D,4,FALSE()),"❌ Not Found")) -> Akosua Frimpong | C10: =IF(A10="","",IFERROR(VLOOKUP(A10,Master_Customers!$A:$O,15,FALSE()),"")) -> 2739.85 | D10: 2026-04-12 | E10: 476.32 | F10: =IF(E10="","",IF(C10="","",C10+E10)) -> 3216.17 | H10: Agent04 | I10: SAVED | J10: 2026-04-12
B11: =IF(A11="","",IFERROR(VLOOKUP(A11,Master_Customers!$A:$D,4,FALSE()),"❌ Not Found")) | C11: =IF(A11="","",IFERROR(VLOOKUP(A11,Master_Customers!$A:$O,15,FALSE()),"")) | F11: =IF(E11="","",IF(C11="","",C11+E11))
B12: =IF(A12="","",IFERROR(VLOOKUP(A12,Master_Customers!$A:$D,4,FALSE()),"❌ Not Found")) | C12: =IF(A12="","",IFERROR(VLOOKUP(A12,Master_Customers!$A:$O,15,FALSE()),"")) | F12: =IF(E12="","",IF(C12="","",C12+E12))
B13: =IF(A13="","",IFERROR(VLOOKUP(A13,Master_Customers!$A:$D,4,FALSE()),"❌ Not Found")) | C13: =IF(A13="","",IFERROR(VLOOKUP(A13,Master_Customers!$A:$O,15,FALSE()),"")) | F13: =IF(E13="","",IF(C13="","",C13+E13))
B14: =IF(A14="","",IFERROR(VLOOKUP(A14,Master_Customers!$A:$D,4,FALSE()),"❌ Not Found")) | C14: =IF(A14="","",IFERROR(VLOOKUP(A14,Master_Customers!$A:$O,15,FALSE()),"")) | F14: =IF(E14="","",IF(C14="","",C14+E14))
B15: =IF(A15="","",IFERROR(VLOOKUP(A15,Master_Customers!$A:$D,4,FALSE()),"❌ Not Found")) | C15: =IF(A15="","",IFERROR(VLOOKUP(A15,Master_Customers!$A:$O,15,FALSE()),"")) | F15: =IF(E15="","",IF(C15="","",C15+E15))
B16: =IF(A16="","",IFERROR(VLOOKUP(A16,Master_Customers!$A:$D,4,FALSE()),"❌ Not Found")) | C16: =IF(A16="","",IFERROR(VLOOKUP(A16,Master_Customers!$A:$O,15,FALSE()),"")) | F16: =IF(E16="","",IF(C16="","",C16+E16))
B17: =IF(A17="","",IFERROR(VLOOKUP(A17,Master_Customers!$A:$D,4,FALSE()),"❌ Not Found")) | C17: =IF(A17="","",IFERROR(VLOOKUP(A17,Master_Customers!$A:$O,15,FALSE()),"")) | F17: =IF(E17="","",IF(C17="","",C17+E17))
B18: =IF(A18="","",IFERROR(VLOOKUP(A18,Master_Customers!$A:$D,4,FALSE()),"❌ Not Found")) | C18: =IF(A18="","",IFERROR(VLOOKUP(A18,Master_Customers!$A:$O,15,FALSE()),"")) | F18: =IF(E18="","",IF(C18="","",C18+E18))
B19: =IF(A19="","",IFERROR(VLOOKUP(A19,Master_Customers!$A:$D,4,FALSE()),"❌ Not Found")) | C19: =IF(A19="","",IFERROR(VLOOKUP(A19,Master_Customers!$A:$O,15,FALSE()),"")) | F19: =IF(E19="","",IF(C19="","",C19+E19))
B20: =IF(A20="","",IFERROR(VLOOKUP(A20,Master_Customers!$A:$D,4,FALSE()),"❌ Not Found")) | C20: =IF(A20="","",IFERROR(VLOOKUP(A20,Master_Customers!$A:$O,15,FALSE()),"")) | F20: =IF(E20="","",IF(C20="","",C20+E20))
B21: =IF(A21="","",IFERROR(VLOOKUP(A21,Master_Customers!$A:$D,4,FALSE()),"❌ Not Found")) | C21: =IF(A21="","",IFERROR(VLOOKUP(A21,Master_Customers!$A:$O,15,FALSE()),"")) | F21: =IF(E21="","",IF(C21="","",C21+E21))
B22: =IF(A22="","",IFERROR(VLOOKUP(A22,Master_Customers!$A:$D,4,FALSE()),"❌ Not Found")) | C22: =IF(A22="","",IFERROR(VLOOKUP(A22,Master_Customers!$A:$O,15,FALSE()),"")) | F22: =IF(E22="","",IF(C22="","",C22+E22))
... B1008: =IF(A1008="","",IFERROR(VLOOKUP(A1008,Master_Customers!$A:$D,4,FALSE()),"❌ Not Found")) | C1008: =IF(A1008="","",IFERROR(VLOOKUP(A1008,Master_Customers!$A:$O,15,FALSE()),"")) | F1008: =IF(E1008="","",IF(C1008="","",C1008+E1008))

Sheet Agent04_Withdrawals
A1: 🏧 SAMICIOUS MICROFINANCE — AGENT04 WITHDRAWALS
A2: Agent: Agent04 | Date: 2026-04-12 | Module: Withdrawal Processing
B3: Total Withdrawals | E3: Transactions Count | H3: Avg Withdrawal
B4: =SUMIF(I9:I1008,"SAVED",E9:E1008) -> 0 | E4: =COUNTIF(I9:I1008,"SAVED") -> 0 | H4: =IFERROR(B4/E4,0) -> 0
A5: ⚠️ WITHDRAWALS MODULE — Insufficient balance will be flagged automatically
A7: 📝 TRANSACTION ENTRY — Enter Account Number and Withdrawal Amount
A8: Account # | B8: Customer Name | C8: Available Balance | D8: Date | E8: Withdrawal Amount | F8: New Balance | G8: Authorised By | H8: Agent | I8: Status | J8: Saved At
B9: =IF(A9="","",IFERROR(VLOOKUP(A9,Master_Customers!$A:$D,4,FALSE()),"❌ Not Found")) | C9: =IF(A9="","",IFERROR(VLOOKUP(A9,Master_Customers!$A:$O,15,FALSE()),"")) | F9: =IF(E9="","",IF(C9="","",IF(E9>C9,"INSUFFICIENT FUNDS",C9-E9)))
B10: =IF(A10="","",IFERROR(VLOOKUP(A10,Master_Customers!$A:$D,4,FALSE()),"❌ Not Found")) | C10: =IF(A10="","",IFERROR(VLOOKUP(A10,Master_Customers!$A:$O,15,FALSE()),"")) | F10: =IF(E10="","",IF(C10="","",IF(E10>C10,"INSUFFICIENT FUNDS",C10-E10)))
B11: =IF(A11="","",IFERROR(VLOOKUP(A11,Master_Customers!$A:$D,4,FALSE()),"❌ Not Found")) | C11: =IF(A11="","",IFERROR(VLOOKUP(A11,Master_Customers!$A:$O,15,FALSE()),"")) | F11: =IF(E11="","",IF(C11="","",IF(E11>C11,"INSUFFICIENT FUNDS",C11-E11)))
B12: =IF(A12="","",IFERROR(VLOOKUP(A12,Master_Customers!$A:$D,4,FALSE()),"❌ Not Found")) | C12: =IF(A12="","",IFERROR(VLOOKUP(A12,Master_Customers!$A:$O,15,FALSE()),"")) | F12: =IF(E12="","",IF(C12="","",IF(E12>C12,"INSUFFICIENT FUNDS",C12-E12)))
B13: =IF(A13="","",IFERROR(VLOOKUP(A13,Master_Customers!$A:$D,4,FALSE()),"❌ Not Found")) | C13: =IF(A13="","",IFERROR(VLOOKUP(A13,Master_Customers!$A:$O,15,FALSE()),"")) | F13: =IF(E13="","",IF(C13="","",IF(E13>C13,"INSUFFICIENT FUNDS",C13-E13)))
B14: =IF(A14="","",IFERROR(VLOOKUP(A14,Master_Customers!$A:$D,4,FALSE()),"❌ Not Found")) | C14: =IF(A14="","",IFERROR(VLOOKUP(A14,Master_Customers!$A:$O,15,FALSE()),"")) | F14: =IF(E14="","",IF(C14="","",IF(E14>C14,"INSUFFICIENT FUNDS",C14-E14)))
B15: =IF(A15="","",IFERROR(VLOOKUP(A15,Master_Customers!$A:$D,4,FALSE()),"❌ Not Found")) | C15: =IF(A15="","",IFERROR(VLOOKUP(A15,Master_Customers!$A:$O,15,FALSE()),"")) | F15: =IF(E15="","",IF(C15="","",IF(E15>C15,"INSUFFICIENT FUNDS",C15-E15)))
B16: =IF(A16="","",IFERROR(VLOOKUP(A16,Master_Customers!$A:$D,4,FALSE()),"❌ Not Found")) | C16: =IF(A16="","",IFERROR(VLOOKUP(A16,Master_Customers!$A:$O,15,FALSE()),"")) | F16: =IF(E16="","",IF(C16="","",IF(E16>C16,"INSUFFICIENT FUNDS",C16-E16)))
B17: =IF(A17="","",IFERROR(VLOOKUP(A17,Master_Customers!$A:$D,4,FALSE()),"❌ Not Found")) | C17: =IF(A17="","",IFERROR(VLOOKUP(A17,Master_Customers!$A:$O,15,FALSE()),"")) | F17: =IF(E17="","",IF(C17="","",IF(E17>C17,"INSUFFICIENT FUNDS",C17-E17)))
B18: =IF(A18="","",IFERROR(VLOOKUP(A18,Master_Customers!$A:$D,4,FALSE()),"❌ Not Found")) | C18: =IF(A18="","",IFERROR(VLOOKUP(A18,Master_Customers!$A:$O,15,FALSE()),"")) | F18: =IF(E18="","",IF(C18="","",IF(E18>C18,"INSUFFICIENT FUNDS",C18-E18)))
B19: =IF(A19="","",IFERROR(VLOOKUP(A19,Master_Customers!$A:$D,4,FALSE()),"❌ Not Found")) | C19: =IF(A19="","",IFERROR(VLOOKUP(A19,Master_Customers!$A:$O,15,FALSE()),"")) | F19: =IF(E19="","",IF(C19="","",IF(E19>C19,"INSUFFICIENT FUNDS",C19-E19)))
B20: =IF(A20="","",IFERROR(VLOOKUP(A20,Master_Customers!$A:$D,4,FALSE()),"❌ Not Found")) | C20: =IF(A20="","",IFERROR(VLOOKUP(A20,Master_Customers!$A:$O,15,FALSE()),"")) | F20: =IF(E20="","",IF(C20="","",IF(E20>C20,"INSUFFICIENT FUNDS",C20-E20)))
... B1008: =IF(A1008="","",IFERROR(VLOOKUP(A1008,Master_Customers!$A:$D,4,FALSE()),"❌ Not Found")) | C1008: =IF(A1008="","",IFERROR(VLOOKUP(A1008,Master_Customers!$A:$O,15,FALSE()),"")) | F1008: =IF(E1008="","",IF(C1008="","",IF(E1008>C1008,"INSUFFICIENT FUNDS",C1008-E1008)))

Sheet Agent04_Loans
A1: 🏦 SAMICIOUS MICROFINANCE — AGENT04 LOAN REQUESTS
A2: Agent: Agent04 | Interest Rate: 2.5% p/m (flat) | Min: GHC 100 | Max: GHC 50,000
A4: 🔢 LOAN CALCULATOR
A5: Loan Amount (GHC):
A6: Repayment (months):
A7: Interest Rate (%/m): | B7: 2.5
A8: Total Interest (GHC): | B8: =IF(B5="","",B5*B7/100*B6)
A9: Total Repayable (GHC): | B9: =IF(B5="","",B5+B8)
A10: Monthly Installment (GHC): | B10: =IF(B5="","",B9/B6)
A12: 📋 LOAN REQUEST SUBMISSIONS — Enter details below to submit for manager approval
A13: Loan ID | B13: Account # | C13: Customer Name | D13: Request Date | E13: Loan Amount | F13: Purpose | G13: Months | H13: Rate % | I13: Total Repayable | J13: Monthly Install | K13: Status | L13: Notes
A14: LN202604120014 | B14: SAM20240300007 | C14: Kojo Amponsah | D14: 2026-04-12 | E14: 9647.03 | F14: Business | G14: 12 | H14: 2.5 | I14: 12541.14 | J14: 1045.09 | K14: Pending
A15: LN202604120015 | B15: SAM20240300008 | C15: Akosua Frimpong | D15: 2026-04-12 | E15: 1051.63 | F15: Business | G15: 6 | H15: 2.5 | I15: 1209.37 | J15: 201.56 | K15: Pending
C16: =IF(B16="","",IFERROR(VLOOKUP(B16,Master_Customers!$A:$D,4,FALSE()),"❌ Not Found")) | I16: =IF(E16="","",E16+E16*H16/100*G16) | J16: =IFERROR(I16/G16,"")
C17: =IF(B17="","",IFERROR(VLOOKUP(B17,Master_Customers!$A:$D,4,FALSE()),"❌ Not Found")) | I17: =IF(E17="","",E17+E17*H17/100*G17) | J17: =IFERROR(I17/G17,"")
C18: =IF(B18="","",IFERROR(VLOOKUP(B18,Master_Customers!$A:$D,4,FALSE()),"❌ Not Found")) | I18: =IF(E18="","",E18+E18*H18/100*G18) | J18: =IFERROR(I18/G18,"")
C19: =IF(B19="","",IFERROR(VLOOKUP(B19,Master_Customers!$A:$D,4,FALSE()),"❌ Not Found")) | I19: =IF(E19="","",E19+E19*H19/100*G19) | J19: =IFERROR(I19/G19,"")
C20: =IF(B20="","",IFERROR(VLOOKUP(B20,Master_Customers!$A:$D,4,FALSE()),"❌ Not Found")) | I20: =IF(E20="","",E20+E20*H20/100*G20) | J20: =IFERROR(I20/G20,"")
C21: =IF(B21="","",IFERROR(VLOOKUP(B21,Master_Customers!$A:$D,4,FALSE()),"❌ Not Found")) | I21: =IF(E21="","",E21+E21*H21/100*G21) | J21: =IFERROR(I21/G21,"")
C22: =IF(B22="","",IFERROR(VLOOKUP(B22,Master_Customers!$A:$D,4,FALSE()),"❌ Not Found")) | I22: =IF(E22="","",E22+E22*H22/100*G22) | J22: =IFERROR(I22/G22,"")
C23: =IF(B23="","",IFERROR(VLOOKUP(B23,Master_Customers!$A:$D,4,FALSE()),"❌ Not Found")) | I23: =IF(E23="","",E23+E23*H23/100*G23) | J23: =IFERROR(I23/G23,"")
C24: =IF(B24="","",IFERROR(VLOOKUP(B24,Master_Customers!$A:$D,4,FALSE()),"❌ Not Found")) | I24: =IF(E24="","",E24+E24*H24/100*G24) | J24: =IFERROR(I24/G24,"")
C25: =IF(B25="","",IFERROR(VLOOKUP(B25,Master_Customers!$A:$D,4,FALSE()),"❌ Not Found")) | I25: =IF(E25="","",E25+E25*H25/100*G25) | J25: =IFERROR(I25/G25,"")
C26: =IF(B26="","",IFERROR(VLOOKUP(B26,Master_Customers!$A:$D,4,FALSE()),"❌ Not Found")) | I26: =IF(E26="","",E26+E26*H26/100*G26) | J26: =IFERROR(I26/G26,"")
C27: =IF(B27="","",IFERROR(VLOOKUP(B27,Master_Customers!$A:$D,4,FALSE()),"❌ Not Found")) | I27: =IF(E27="","",E27+E27*H27/100*G27) | J27: =IFERROR(I27/G27,"")
... C213: =IF(B213="","",IFERROR(VLOOKUP(B213,Master_Customers!$A:$D,4,FALSE()),"❌ Not Found")) | I213: =IF(E213="","",E213+E213*H213/100*G213) | J213: =IFERROR(I213/G213,"")

Sheet Agent05_Savings
A1: 💰 SAMICIOUS MICROFINANCE — AGENT05 SAVINGS
A2: Agent: Agent05 | Date: 2026-04-12 | Module: Daily Savings Collection
B3: Daily Target (GHC) | E3: Total Collected | H3: Remaining
B4: 5000 | E4: =SUMIF(I9:I1008,"SAVED",E9:E1008) -> 525.86 | H4: =IF(B4-E4<0,"TARGET MET!",B4-E4) -> 4474.14
A5: =IF(B4-E4<=0,"✅ DAILY TARGET ACHIEVED! Great work Agent05!","⏳ Collection in progress — Keep going!") -> ⏳ Collection in progress — Keep going!
A7: 📝 TRANSACTION ENTRY — Enter Account Number and Amount, then click RECORD or press Ctrl+S
A8: Account # | B8: Customer Name | C8: Current Balance | D8: Date | E8: Savings Amount | F8: New Balance | G8: Receipt # | H8: Agent | I8: Status | J8: Saved At
A9: SAM20240400009 | B9: =IF(A9="","",IFERROR(VLOOKUP(A9,Master_Customers!$A:$D,4,FALSE()),"❌ Not Found")) -> Kwabena Asante | C9: =IF(A9="","",IFERROR(VLOOKUP(A9,Master_Customers!$A:$O,15,FALSE()),"")) -> 3507.75 | D9: 2026-04-12 | E9: 179.84 | F9: =IF(E9="","",IF(C9="","",C9+E9)) -> 3687.59 | H9: Agent05 | I9: SAVED | J9: 2026-04-12
A10: SAM20240400010 | B10: =IF(A10="","",IFERROR(VLOOKUP(A10,Master_Customers!$A:$D,4,FALSE()),"❌ Not Found")) -> Adjoa Tetteh | C10: =IF(A10="","",IFERROR(VLOOKUP(A10,Master_Customers!$A:$O,15,FALSE()),"")) -> 3164.79 | D10: 2026-04-12 | E10: 346.02 | F10: =IF(E10="","",IF(C10="","",C10+E10)) -> 3510.81 | H10: Agent05 | I10: SAVED | J10: 2026-04-12
B11: =IF(A11="","",IFERROR(VLOOKUP(A11,Master_Customers!$A:$D,4,FALSE()),"❌ Not Found")) | C11: =IF(A11="","",IFERROR(VLOOKUP(A11,Master_Customers!$A:$O,15,FALSE()),"")) | F11: =IF(E11="","",IF(C11="","",C11+E11))
B12: =IF(A12="","",IFERROR(VLOOKUP(A12,Master_Customers!$A:$D,4,FALSE()),"❌ Not Found")) | C12: =IF(A12="","",IFERROR(VLOOKUP(A12,Master_Customers!$A:$O,15,FALSE()),"")) | F12: =IF(E12="","",IF(C12="","",C12+E12))
B13: =IF(A13="","",IFERROR(VLOOKUP(A13,Master_Customers!$A:$D,4,FALSE()),"❌ Not Found")) | C13: =IF(A13="","",IFERROR(VLOOKUP(A13,Master_Customers!$A:$O,15,FALSE()),"")) | F13: =IF(E13="","",IF(C13="","",C13+E13))
B14: =IF(A14="","",IFERROR(VLOOKUP(A14,Master_Customers!$A:$D,4,FALSE()),"❌ Not Found")) | C14: =IF(A14="","",IFERROR(VLOOKUP(A14,Master_Customers!$A:$O,15,FALSE()),"")) | F14: =IF(E14="","",IF(C14="","",C14+E14))
B15: =IF(A15="","",IFERROR(VLOOKUP(A15,Master_Customers!$A:$D,4,FALSE()),"❌ Not Found")) | C15: =IF(A15="","",IFERROR(VLOOKUP(A15,Master_Customers!$A:$O,15,FALSE()),"")) | F15: =IF(E15="","",IF(C15="","",C15+E15))
B16: =IF(A16="","",IFERROR(VLOOKUP(A16,Master_Customers!$A:$D,4,FALSE()),"❌ Not Found")) | C16: =IF(A16="","",IFERROR(VLOOKUP(A16,Master_Customers!$A:$O,15,FALSE()),"")) | F16: =IF(E16="","",IF(C16="","",C16+E16))
B17: =IF(A17="","",IFERROR(VLOOKUP(A17,Master_Customers!$A:$D,4,FALSE()),"❌ Not Found")) | C17: =IF(A17="","",IFERROR(VLOOKUP(A17,Master_Customers!$A:$O,15,FALSE()),"")) | F17: =IF(E17="","",IF(C17="","",C17+E17))
B18: =IF(A18="","",IFERROR(VLOOKUP(A18,Master_Customers!$A:$D,4,FALSE()),"❌ Not Found")) | C18: =IF(A18="","",IFERROR(VLOOKUP(A18,Master_Customers!$A:$O,15,FALSE()),"")) | F18: =IF(E18="","",IF(C18="","",C18+E18))
B19: =IF(A19="","",IFERROR(VLOOKUP(A19,Master_Customers!$A:$D,4,FALSE()),"❌ Not Found")) | C19: =IF(A19="","",IFERROR(VLOOKUP(A19,Master_Customers!$A:$O,15,FALSE()),"")) | F19: =IF(E19="","",IF(C19="","",C19+E19))
B20: =IF(A20="","",IFERROR(VLOOKUP(A20,Master_Customers!$A:$D,4,FALSE()),"❌ Not Found")) | C20: =IF(A20="","",IFERROR(VLOOKUP(A20,Master_Customers!$A:$O,15,FALSE()),"")) | F20: =IF(E20="","",IF(C20="","",C20+E20))
B21: =IF(A21="","",IFERROR(VLOOKUP(A21,Master_Customers!$A:$D,4,FALSE()),"❌ Not Found")) | C21: =IF(A21="","",IFERROR(VLOOKUP(A21,Master_Customers!$A:$O,15,FALSE()),"")) | F21: =IF(E21="","",IF(C21="","",C21+E21))
B22: =IF(A22="","",IFERROR(VLOOKUP(A22,Master_Customers!$A:$D,4,FALSE()),"❌ Not Found")) | C22: =IF(A22="","",IFERROR(VLOOKUP(A22,Master_Customers!$A:$O,15,FALSE()),"")) | F22: =IF(E22="","",IF(C22="","",C22+E22))
... B1008: =IF(A1008="","",IFERROR(VLOOKUP(A1008,Master_Customers!$A:$D,4,FALSE()),"❌ Not Found")) | C1008: =IF(A1008="","",IFERROR(VLOOKUP(A1008,Master_Customers!$A:$O,15,FALSE()),"")) | F1008: =IF(E1008="","",IF(C1008="","",C1008+E1008))

Sheet Agent05_Withdrawals
A1: 🏧 SAMICIOUS MICROFINANCE — AGENT05 WITHDRAWALS
A2: Agent: Agent05 | Date: 2026-04-12 | Module: Withdrawal Processing
B3: Total Withdrawals | E3: Transactions Count | H3: Avg Withdrawal
B4: =SUMIF(I9:I1008,"SAVED",E9:E1008) -> 0 | E4: =COUNTIF(I9:I1008,"SAVED") -> 0 | H4: =IFERROR(B4/E4,0) -> 0
A5: ⚠️ WITHDRAWALS MODULE — Insufficient balance will be flagged automatically
A7: 📝 TRANSACTION ENTRY — Enter Account Number and Withdrawal Amount
A8: Account # | B8: Customer Name | C8: Available Balance | D8: Date | E8: Withdrawal Amount | F8: New Balance | G8: Authorised By | H8: Agent | I8: Status | J8: Saved At
B9: =IF(A9="","",IFERROR(VLOOKUP(A9,Master_Customers!$A:$D,4,FALSE()),"❌ Not Found")) | C9: =IF(A9="","",IFERROR(VLOOKUP(A9,Master_Customers!$A:$O,15,FALSE()),"")) | F9: =IF(E9="","",IF(C9="","",IF(E9>C9,"INSUFFICIENT FUNDS",C9-E9)))
B10: =IF(A10="","",IFERROR(VLOOKUP(A10,Master_Customers!$A:$D,4,FALSE()),"❌ Not Found")) | C10: =IF(A10="","",IFERROR(VLOOKUP(A10,Master_Customers!$A:$O,15,FALSE()),"")) | F10: =IF(E10="","",IF(C10="","",IF(E10>C10,"INSUFFICIENT FUNDS",C10-E10)))
B11: =IF(A11="","",IFERROR(VLOOKUP(A11,Master_Customers!$A:$D,4,FALSE()),"❌ Not Found")) | C11: =IF(A11="","",IFERROR(VLOOKUP(A11,Master_Customers!$A:$O,15,FALSE()),"")) | F11: =IF(E11="","",IF(C11="","",IF(E11>C11,"INSUFFICIENT FUNDS",C11-E11)))
B12: =IF(A12="","",IFERROR(VLOOKUP(A12,Master_Customers!$A:$D,4,FALSE()),"❌ Not Found")) | C12: =IF(A12="","",IFERROR(VLOOKUP(A12,Master_Customers!$A:$O,15,FALSE()),"")) | F12: =IF(E12="","",IF(C12="","",IF(E12>C12,"INSUFFICIENT FUNDS",C12-E12)))
B13: =IF(A13="","",IFERROR(VLOOKUP(A13,Master_Customers!$A:$D,4,FALSE()),"❌ Not Found")) | C13: =IF(A13="","",IFERROR(VLOOKUP(A13,Master_Customers!$A:$O,15,FALSE()),"")) | F13: =IF(E13="","",IF(C13="","",IF(E13>C13,"INSUFFICIENT FUNDS",C13-E13)))
B14: =IF(A14="","",IFERROR(VLOOKUP(A14,Master_Customers!$A:$D,4,FALSE()),"❌ Not Found")) | C14: =IF(A14="","",IFERROR(VLOOKUP(A14,Master_Customers!$A:$O,15,FALSE()),"")) | F14: =IF(E14="","",IF(C14="","",IF(E14>C14,"INSUFFICIENT FUNDS",C14-E14)))
B15: =IF(A15="","",IFERROR(VLOOKUP(A15,Master_Customers!$A:$D,4,FALSE()),"❌ Not Found")) | C15: =IF(A15="","",IFERROR(VLOOKUP(A15,Master_Customers!$A:$O,15,FALSE()),"")) | F15: =IF(E15="","",IF(C15="","",IF(E15>C15,"INSUFFICIENT FUNDS",C15-E15)))
B16: =IF(A16="","",IFERROR(VLOOKUP(A16,Master_Customers!$A:$D,4,FALSE()),"❌ Not Found")) | C16: =IF(A16="","",IFERROR(VLOOKUP(A16,Master_Customers!$A:$O,15,FALSE()),"")) | F16: =IF(E16="","",IF(C16="","",IF(E16>C16,"INSUFFICIENT FUNDS",C16-E16)))
B17: =IF(A17="","",IFERROR(VLOOKUP(A17,Master_Customers!$A:$D,4,FALSE()),"❌ Not Found")) | C17: =IF(A17="","",IFERROR(VLOOKUP(A17,Master_Customers!$A:$O,15,FALSE()),"")) | F17: =IF(E17="","",IF(C17="","",IF(E17>C17,"INSUFFICIENT FUNDS",C17-E17)))
B18: =IF(A18="","",IFERROR(VLOOKUP(A18,Master_Customers!$A:$D,4,FALSE()),"❌ Not Found")) | C18: =IF(A18="","",IFERROR(VLOOKUP(A18,Master_Customers!$A:$O,15,FALSE()),"")) | F18: =IF(E18="","",IF(C18="","",IF(E18>C18,"INSUFFICIENT FUNDS",C18-E18)))
B19: =IF(A19="","",IFERROR(VLOOKUP(A19,Master_Customers!$A:$D,4,FALSE()),"❌ Not Found")) | C19: =IF(A19="","",IFERROR(VLOOKUP(A19,Master_Customers!$A:$O,15,FALSE()),"")) | F19: =IF(E19="","",IF(C19="","",IF(E19>C19,"INSUFFICIENT FUNDS",C19-E19)))
B20: =IF(A20="","",IFERROR(VLOOKUP(A20,Master_Customers!$A:$D,4,FALSE()),"❌ Not Found")) | C20: =IF(A20="","",IFERROR(VLOOKUP(A20,Master_Customers!$A:$O,15,FALSE()),"")) | F20: =IF(E20="","",IF(C20="","",IF(E20>C20,"INSUFFICIENT FUNDS",C20-E20)))
... B1008: =IF(A1008="","",IFERROR(VLOOKUP(A1008,Master_Customers!$A:$D,4,FALSE()),"❌ Not Found")) | C1008: =IF(A1008="","",IFERROR(VLOOKUP(A1008,Master_Customers!$A:$O,15,FALSE()),"")) | F1008: =IF(E1008="","",IF(C1008="","",IF(E1008>C1008,"INSUFFICIENT FUNDS",C1008-E1008)))

Sheet Agent05_Loans
A1: 🏦 SAMICIOUS MICROFINANCE — AGENT05 LOAN REQUESTS
A2: Agent: Agent05 | Interest Rate: 2.5% p/m (flat) | Min: GHC 100 | Max: GHC 50,000
A4: 🔢 LOAN CALCULATOR
A5: Loan Amount (GHC):
A6: Repayment (months):
A7: Interest Rate (%/m): | B7: 2.5
A8: Total Interest (GHC): | B8: =IF(B5="","",B5*B7/100*B6)
A9: Total Repayable (GHC): | B9: =IF(B5="","",B5+B8)
A10: Monthly Installment (GHC): | B10: =IF(B5="","",B9/B6)
A12: 📋 LOAN REQUEST SUBMISSIONS — Enter details below to submit for manager approval
