Workbook

Sheet 🏠 DASHBOARD
A1: 🏦 SAMICIOUS MICROFINANCE ENTERPRISE SYSTEM v15.0
A2: =TEXT(TODAY(),"dddd, mmmm d, yyyy")&" | 10-Agent Multi-Module Formula-Driven System | No VBA Required" -> Saturday, April 25, 2026 | 10-Agent Multi-Module Formula-Driven System | No VBA Required
B4: TOTAL SAVINGS | D4: TOTAL WITHDRAWALS | F4: CUSTOMERS | H4: ACTIVE LOANS | J4: TOP-UPS
B5: =IFERROR(SUM(DB_Savings!F:F),0) -> 0 | D5: =IFERROR(SUM(DB_Withdrawals!G:G),0) -> 0 | F5: =IFERROR(COUNTA(DB_Customers!A:A)-3,0) -> 500 | H5: =IFERROR(COUNTIF(DB_Loans!K:K,"Approved"),0) -> 0 | J5: =IFERROR(COUNTA('LOAN TOPUP'!B:B)-3,0) -> -2
B7: 📋 NEW ACCOUNT | D7: 🗄️ DATABASE | F7: 🏦 MANAGER DASHBOARD | H7: 📊 REPORTS | J7: 🔗 LOAN TOP-UP
B8: 💰 AGENT SAVINGS | D8: 🏧 AGENT WITHDRAWALS | F8: 🏦 AGENT LOANS | H8: ⚙️ SYSTEM CONFIG | J8: 👥 AGENTS DB
A10: ⚡ FULLY AUTOMATED • 10 Agents • Agent Code Security • GHS 10 Min Balance Enforced • Real-Time Sync • Multi-Year Capable • Zero VBA • Pure Formula Engine

Sheet DEVELOPER
A1: 🏦 SAMICIOUS MICROFINANCE
A2: SAMICIOUS MICROFINANCE MANAGEMENT SYSTEM | Developer Information
A4: ABOUT THE DEVELOPER
A6: THIS SAMICIOUS MICROFINANCE MANAGEMENT SYSTEM WAS DESIGNED AND DEVELOPED BY
A7: FRANK ABBAN
A8: IT CONSULTANT
A10: 📞 FOR ALL ENQUIRIES, KINDLY REACH OUT USING ANY OF THE CONTACT NUMBERS BELOW:
B12: 📱 0241911273
B14: 📱 0207530771
B16: 📋 Select any phone number above → Ctrl+C to copy
A20: SAMICIOUS MICROFINANCE MANAGEMENT SYSTEM — v15.0 | Built with Excel + Formula-Driven Architecture | No VBA Required

Sheet ACKNOWLEDGEMENT
A1: 🏦 SAMICIOUS MICROFINANCE
A2: SAMICIOUS MICROFINANCE MANAGEMENT SYSTEM | Official Documentation
A4: ACKNOWLEDGEMENT
B6: I give all glory to the Almighty God for His grace, strength, and wisdom that have guided me throughout this journey. Without Him, this work would not have been possible.
B8: I sincerely appreciate Dr. Gabriel Annan, Lecturer at the University of Cape Coast (UCC), for his mentorship, guidance, and invaluable support throughout the development of this system.
B10: I am deeply grateful to Rev. Ebenezer Asibu Dadzie for his spiritual guidance, encouragement, and prayers, which strengthened me greatly.
B12: Special thanks to Mr. Addu Gyamfi, CEO of Samicious Microfinance, for his trust and confidence in my ability to serve as the IT Consultant for this project.
B14: To my beloved wife and children, your patience, sacrifices, and unwavering support have been invaluable. Your love continues to inspire me.
B16: Through your collective support, this vision has been successfully realized.
A18: 📖 BIBLICAL SUPPORT
B20: "I can do all things through Christ who strengthens me."
B22: — Philippians 4:13
A24: A M E N

Sheet 🏦 MANAGER DASHBOARD
A1: 🏦 SAMICIOUS MICROFINANCE — MANAGER COMMAND CENTER
A2: =UPPER(TEXT(TODAY(),"DDDD, DD MMMM YYYY"))&" | Live data — All 10 agents unified | v15.0 Formula Engine" -> SATURDAY, 25 APRIL 2026 | Live data — All 10 agents unified | v15.0 Formula Engine
B4: 💰 TOTAL SAVINGS | D4: 🏧 TOTAL WITHDRAWALS | F4: 📈 NET FLOW | H4: 👥 ACTIVE CUSTOMERS | J4: 🏦 LOAN PORTFOLIO | L4: ⏳ PENDING LOANS
B5: =IFERROR(SUMIF(DB_Savings!A:A,"*",DB_Savings!F:F),0) -> 0 | D5: =IFERROR(SUMIF(DB_Withdrawals!A:A,"*",DB_Withdrawals!G:G),0) -> 0 | F5: =B5-D5 -> 0 | H5: =IFERROR(COUNTA(DB_Customers!A:A)-1,0) -> 502 | J5: =IFERROR(SUMIF(DB_Loans!K:K,"Approved",DB_Loans!I:I),0) -> 0 | L5: =IFERROR(COUNTIF(DB_Loans!K:K,"Pending"),0) -> 0
A7: 📊 REAL-TIME AGENT PERFORMANCE
A8: Agent | B8: Today Savings | C8: Today Withdrawals | D8: Net Today | E8: Transactions | F8: Monthly Savings | G8: Active Customers | H8: Daily Target | I8: % of Target
A9: Agent 01 | B9: =IFERROR(SUMIFS(DB_Savings!$F:$F,DB_Savings!$G:$G,"Agent 01",DB_Savings!$E:$E,TODAY()),0) -> 0 | C9: =IFERROR(SUMIFS(DB_Withdrawals!$G:$G,DB_Withdrawals!$J:$J,"Agent 01",DB_Withdrawals!$F:$F,TODAY()),0) -> 0 | D9: =B9-C9 -> 0 | E9: =IFERROR(COUNTIFS(DB_Savings!$G:$G,"Agent 01",DB_Savings!$E:$E,TODAY())+COUNTIFS(DB_Withdrawals!$J:$J,"Agent 01",DB_Withdrawals!$F:$F,TODAY()),0) -> 0 | F9: =IFERROR(SUMIF(DB_Savings!$G:$G,"Agent 01",DB_Savings!$F:$F),0) -> 0 | G9: =IFERROR(COUNTIF(DB_Customers!$H:$H,"Agent 01"),0) -> 0 | H9: 5000 | I9: =IFERROR(B9/H9,0) -> 0
A10: Agent 02 | B10: =IFERROR(SUMIFS(DB_Savings!$F:$F,DB_Savings!$G:$G,"Agent 02",DB_Savings!$E:$E,TODAY()),0) -> 0 | C10: =IFERROR(SUMIFS(DB_Withdrawals!$G:$G,DB_Withdrawals!$J:$J,"Agent 02",DB_Withdrawals!$F:$F,TODAY()),0) -> 0 | D10: =B10-C10 -> 0 | E10: =IFERROR(COUNTIFS(DB_Savings!$G:$G,"Agent 02",DB_Savings!$E:$E,TODAY())+COUNTIFS(DB_Withdrawals!$J:$J,"Agent 02",DB_Withdrawals!$F:$F,TODAY()),0) -> 0 | F10: =IFERROR(SUMIF(DB_Savings!$G:$G,"Agent 02",DB_Savings!$F:$F),0) -> 0 | G10: =IFERROR(COUNTIF(DB_Customers!$H:$H,"Agent 02"),0) -> 0 | H10: 5000 | I10: =IFERROR(B10/H10,0) -> 0
A11: Agent 03 | B11: =IFERROR(SUMIFS(DB_Savings!$F:$F,DB_Savings!$G:$G,"Agent 03",DB_Savings!$E:$E,TODAY()),0) -> 0 | C11: =IFERROR(SUMIFS(DB_Withdrawals!$G:$G,DB_Withdrawals!$J:$J,"Agent 03",DB_Withdrawals!$F:$F,TODAY()),0) -> 0 | D11: =B11-C11 -> 0 | E11: =IFERROR(COUNTIFS(DB_Savings!$G:$G,"Agent 03",DB_Savings!$E:$E,TODAY())+COUNTIFS(DB_Withdrawals!$J:$J,"Agent 03",DB_Withdrawals!$F:$F,TODAY()),0) -> 0 | F11: =IFERROR(SUMIF(DB_Savings!$G:$G,"Agent 03",DB_Savings!$F:$F),0) -> 0 | G11: =IFERROR(COUNTIF(DB_Customers!$H:$H,"Agent 03"),0) -> 0 | H11: 5000 | I11: =IFERROR(B11/H11,0) -> 0
A12: Agent 04 | B12: =IFERROR(SUMIFS(DB_Savings!$F:$F,DB_Savings!$G:$G,"Agent 04",DB_Savings!$E:$E,TODAY()),0) -> 0 | C12: =IFERROR(SUMIFS(DB_Withdrawals!$G:$G,DB_Withdrawals!$J:$J,"Agent 04",DB_Withdrawals!$F:$F,TODAY()),0) -> 0 | D12: =B12-C12 -> 0 | E12: =IFERROR(COUNTIFS(DB_Savings!$G:$G,"Agent 04",DB_Savings!$E:$E,TODAY())+COUNTIFS(DB_Withdrawals!$J:$J,"Agent 04",DB_Withdrawals!$F:$F,TODAY()),0) -> 0 | F12: =IFERROR(SUMIF(DB_Savings!$G:$G,"Agent 04",DB_Savings!$F:$F),0) -> 0 | G12: =IFERROR(COUNTIF(DB_Customers!$H:$H,"Agent 04"),0) -> 0 | H12: 5000 | I12: =IFERROR(B12/H12,0) -> 0
A13: Agent 05 | B13: =IFERROR(SUMIFS(DB_Savings!$F:$F,DB_Savings!$G:$G,"Agent 05",DB_Savings!$E:$E,TODAY()),0) -> 0 | C13: =IFERROR(SUMIFS(DB_Withdrawals!$G:$G,DB_Withdrawals!$J:$J,"Agent 05",DB_Withdrawals!$F:$F,TODAY()),0) -> 0 | D13: =B13-C13 -> 0 | E13: =IFERROR(COUNTIFS(DB_Savings!$G:$G,"Agent 05",DB_Savings!$E:$E,TODAY())+COUNTIFS(DB_Withdrawals!$J:$J,"Agent 05",DB_Withdrawals!$F:$F,TODAY()),0) -> 0 | F13: =IFERROR(SUMIF(DB_Savings!$G:$G,"Agent 05",DB_Savings!$F:$F),0) -> 0 | G13: =IFERROR(COUNTIF(DB_Customers!$H:$H,"Agent 05"),0) -> 0 | H13: 5000 | I13: =IFERROR(B13/H13,0) -> 0
A14: Agent 06 | B14: =IFERROR(SUMIFS(DB_Savings!$F:$F,DB_Savings!$G:$G,"Agent 06",DB_Savings!$E:$E,TODAY()),0) -> 0 | C14: =IFERROR(SUMIFS(DB_Withdrawals!$G:$G,DB_Withdrawals!$J:$J,"Agent 06",DB_Withdrawals!$F:$F,TODAY()),0) -> 0 | D14: =B14-C14 -> 0 | E14: =IFERROR(COUNTIFS(DB_Savings!$G:$G,"Agent 06",DB_Savings!$E:$E,TODAY())+COUNTIFS(DB_Withdrawals!$J:$J,"Agent 06",DB_Withdrawals!$F:$F,TODAY()),0) -> 0 | F14: =IFERROR(SUMIF(DB_Savings!$G:$G,"Agent 06",DB_Savings!$F:$F),0) -> 0 | G14: =IFERROR(COUNTIF(DB_Customers!$H:$H,"Agent 06"),0) -> 0 | H14: 5000 | I14: =IFERROR(B14/H14,0) -> 0
A15: Agent 07 | B15: =IFERROR(SUMIFS(DB_Savings!$F:$F,DB_Savings!$G:$G,"Agent 07",DB_Savings!$E:$E,TODAY()),0) -> 0 | C15: =IFERROR(SUMIFS(DB_Withdrawals!$G:$G,DB_Withdrawals!$J:$J,"Agent 07",DB_Withdrawals!$F:$F,TODAY()),0) -> 0 | D15: =B15-C15 -> 0 | E15: =IFERROR(COUNTIFS(DB_Savings!$G:$G,"Agent 07",DB_Savings!$E:$E,TODAY())+COUNTIFS(DB_Withdrawals!$J:$J,"Agent 07",DB_Withdrawals!$F:$F,TODAY()),0) -> 0 | F15: =IFERROR(SUMIF(DB_Savings!$G:$G,"Agent 07",DB_Savings!$F:$F),0) -> 0 | G15: =IFERROR(COUNTIF(DB_Customers!$H:$H,"Agent 07"),0) -> 0 | H15: 5000 | I15: =IFERROR(B15/H15,0) -> 0
A16: Agent 08 | B16: =IFERROR(SUMIFS(DB_Savings!$F:$F,DB_Savings!$G:$G,"Agent 08",DB_Savings!$E:$E,TODAY()),0) -> 0 | C16: =IFERROR(SUMIFS(DB_Withdrawals!$G:$G,DB_Withdrawals!$J:$J,"Agent 08",DB_Withdrawals!$F:$F,TODAY()),0) -> 0 | D16: =B16-C16 -> 0 | E16: =IFERROR(COUNTIFS(DB_Savings!$G:$G,"Agent 08",DB_Savings!$E:$E,TODAY())+COUNTIFS(DB_Withdrawals!$J:$J,"Agent 08",DB_Withdrawals!$F:$F,TODAY()),0) -> 0 | F16: =IFERROR(SUMIF(DB_Savings!$G:$G,"Agent 08",DB_Savings!$F:$F),0) -> 0 | G16: =IFERROR(COUNTIF(DB_Customers!$H:$H,"Agent 08"),0) -> 0 | H16: 5000 | I16: =IFERROR(B16/H16,0) -> 0
A17: Agent 09 | B17: =IFERROR(SUMIFS(DB_Savings!$F:$F,DB_Savings!$G:$G,"Agent 09",DB_Savings!$E:$E,TODAY()),0) -> 0 | C17: =IFERROR(SUMIFS(DB_Withdrawals!$G:$G,DB_Withdrawals!$J:$J,"Agent 09",DB_Withdrawals!$F:$F,TODAY()),0) -> 0 | D17: =B17-C17 -> 0 | E17: =IFERROR(COUNTIFS(DB_Savings!$G:$G,"Agent 09",DB_Savings!$E:$E,TODAY())+COUNTIFS(DB_Withdrawals!$J:$J,"Agent 09",DB_Withdrawals!$F:$F,TODAY()),0) -> 0 | F17: =IFERROR(SUMIF(DB_Savings!$G:$G,"Agent 09",DB_Savings!$F:$F),0) -> 0 | G17: =IFERROR(COUNTIF(DB_Customers!$H:$H,"Agent 09"),0) -> 0 | H17: 5000 | I17: =IFERROR(B17/H17,0) -> 0
A18: Agent 10 | B18: =IFERROR(SUMIFS(DB_Savings!$F:$F,DB_Savings!$G:$G,"Agent 10",DB_Savings!$E:$E,TODAY()),0) -> 0 | C18: =IFERROR(SUMIFS(DB_Withdrawals!$G:$G,DB_Withdrawals!$J:$J,"Agent 10",DB_Withdrawals!$F:$F,TODAY()),0) -> 0 | D18: =B18-C18 -> 0 | E18: =IFERROR(COUNTIFS(DB_Savings!$G:$G,"Agent 10",DB_Savings!$E:$E,TODAY())+COUNTIFS(DB_Withdrawals!$J:$J,"Agent 10",DB_Withdrawals!$F:$F,TODAY()),0) -> 0 | F18: =IFERROR(SUMIF(DB_Savings!$G:$G,"Agent 10",DB_Savings!$F:$F),0) -> 0 | G18: =IFERROR(COUNTIF(DB_Customers!$H:$H,"Agent 10"),0) -> 0 | H18: 5000 | I18: =IFERROR(B18/H18,0) -> 0
A19: TOTALS | B19: =SUM(B9:B18) -> 0 | C19: =SUM(C9:C18) -> 0 | D19: =SUM(D9:D18) -> 0 | E19: =SUM(E9:E18) -> 0 | F19: =SUM(F9:F18) -> 0 | G19: =SUM(G9:G18) -> 0 | H19: =SUM(H9:H18) -> 50000 | I19: =IFERROR(B19/H19,0) -> 0
A21: 🔗 NAVIGATION: 📋 NEW ACCOUNT | 🗄️ DB_Customers | 💰 Agent Savings | 🏧 Agent Withdrawals | 🏦 Agent Loans | 📊 REPORTS | ⚙️ System_Config

Sheet NEW ACCOUNT
A1: 👤 NEW CUSTOMER ACCOUNT REGISTRATION
A2: ✅ FULLY AUTOMATED — Type customer details in columns B–H. Account Number (col A) auto-generates instantly. DATABASE populates in real time. No buttons, no copy-paste required.
A3: ⚠️ GHS 10.00 MINIMUM OPENING BALANCE ENFORCED | Accounts below GHS 10 will be flagged as Inactive
A4: Account Number | B4: Customer Name | C4: Date of Birth | D4: Phone Number | E4: Location | F4: Occupation | G4: Assigned Agent | H4: Opening Balance (GHS) | I4: Date Registered | J4: Status
A5: =IF(B5="","","ACC"&TEXT(ROW()-4,"0000")) -> ACC0001 | B5: FRANK ABBAN | C5: 31930 | D5: 241911273 | E5: mankessim | F5: developer | G5: 1 | H5: 400 | I5: =IF(B5="","",TEXT(TODAY(),"dd/mm/yyyy")) -> 25/04/2026 | J5: =IF(B5="","",IF(ISNUMBER(H5),IF(H5>=10,"Active","⚠️ Below Min Balance"),"Pending")) -> Active
A6: =IF(B6="","","ACC"&TEXT(ROW()-4,"0000")) | I6: =IF(B6="","",TEXT(TODAY(),"dd/mm/yyyy")) | J6: =IF(B6="","",IF(ISNUMBER(H6),IF(H6>=10,"Active","⚠️ Below Min Balance"),"Pending"))
A7: =IF(B7="","","ACC"&TEXT(ROW()-4,"0000")) | I7: =IF(B7="","",TEXT(TODAY(),"dd/mm/yyyy")) | J7: =IF(B7="","",IF(ISNUMBER(H7),IF(H7>=10,"Active","⚠️ Below Min Balance"),"Pending"))
A8: =IF(B8="","","ACC"&TEXT(ROW()-4,"0000")) | I8: =IF(B8="","",TEXT(TODAY(),"dd/mm/yyyy")) | J8: =IF(B8="","",IF(ISNUMBER(H8),IF(H8>=10,"Active","⚠️ Below Min Balance"),"Pending"))
A9: =IF(B9="","","ACC"&TEXT(ROW()-4,"0000")) | I9: =IF(B9="","",TEXT(TODAY(),"dd/mm/yyyy")) | J9: =IF(B9="","",IF(ISNUMBER(H9),IF(H9>=10,"Active","⚠️ Below Min Balance"),"Pending"))
A10: =IF(B10="","","ACC"&TEXT(ROW()-4,"0000")) | I10: =IF(B10="","",TEXT(TODAY(),"dd/mm/yyyy")) | J10: =IF(B10="","",IF(ISNUMBER(H10),IF(H10>=10,"Active","⚠️ Below Min Balance"),"Pending"))
A11: =IF(B11="","","ACC"&TEXT(ROW()-4,"0000")) | I11: =IF(B11="","",TEXT(TODAY(),"dd/mm/yyyy")) | J11: =IF(B11="","",IF(ISNUMBER(H11),IF(H11>=10,"Active","⚠️ Below Min Balance"),"Pending"))
A12: =IF(B12="","","ACC"&TEXT(ROW()-4,"0000")) | I12: =IF(B12="","",TEXT(TODAY(),"dd/mm/yyyy")) | J12: =IF(B12="","",IF(ISNUMBER(H12),IF(H12>=10,"Active","⚠️ Below Min Balance"),"Pending"))
A13: =IF(B13="","","ACC"&TEXT(ROW()-4,"0000")) | I13: =IF(B13="","",TEXT(TODAY(),"dd/mm/yyyy")) | J13: =IF(B13="","",IF(ISNUMBER(H13),IF(H13>=10,"Active","⚠️ Below Min Balance"),"Pending"))
A14: =IF(B14="","","ACC"&TEXT(ROW()-4,"0000")) | I14: =IF(B14="","",TEXT(TODAY(),"dd/mm/yyyy")) | J14: =IF(B14="","",IF(ISNUMBER(H14),IF(H14>=10,"Active","⚠️ Below Min Balance"),"Pending"))
A15: =IF(B15="","","ACC"&TEXT(ROW()-4,"0000")) | I15: =IF(B15="","",TEXT(TODAY(),"dd/mm/yyyy")) | J15: =IF(B15="","",IF(ISNUMBER(H15),IF(H15>=10,"Active","⚠️ Below Min Balance"),"Pending"))
A16: =IF(B16="","","ACC"&TEXT(ROW()-4,"0000")) | I16: =IF(B16="","",TEXT(TODAY(),"dd/mm/yyyy")) | J16: =IF(B16="","",IF(ISNUMBER(H16),IF(H16>=10,"Active","⚠️ Below Min Balance"),"Pending"))
A17: =IF(B17="","","ACC"&TEXT(ROW()-4,"0000")) | I17: =IF(B17="","",TEXT(TODAY(),"dd/mm/yyyy")) | J17: =IF(B17="","",IF(ISNUMBER(H17),IF(H17>=10,"Active","⚠️ Below Min Balance"),"Pending"))
... A504: =IF(B504="","","ACC"&TEXT(ROW()-4,"0000")) | I504: =IF(B504="","",TEXT(TODAY(),"dd/mm/yyyy")) | J504: =IF(B504="","",IF(ISNUMBER(H504),IF(H504>=10,"Active","⚠️ Below Min Balance"),"Pending"))
A506: 🔵 Blue = Auto-generated 🟡 Yellow = Enter data here

Sheet DB_Customers
A1: 🗄️ CUSTOMER ACCOUNT DATABASE — Central Source of Truth (Formula-Driven)
A2: All columns A–J mirror NEW ACCOUNT in real time. Columns K–N computed from transactions.
A3: Account No. | B3: Full Name | C3: Date of Birth | D3: Phone Number | E3: Location | F3: Occupation | G3: Assigned Agent | H3: Opening Balance (GHS) | I3: Date Registered | J3: Status | K3: Total Savings (GHS) | L3: Total Withdrawals (GHS) | M3: Current Balance (GHS) | N3: Withdrawable Balance (GHS)
A4: ='NEW ACCOUNT'!A5 -> ACC0001 | B4: =IF('NEW ACCOUNT'!A5="","",'NEW ACCOUNT'!B5) -> FRANK ABBAN | C4: =IF('NEW ACCOUNT'!A5="","",'NEW ACCOUNT'!C5) -> 31930 | D4: =IF('NEW ACCOUNT'!A5="","",'NEW ACCOUNT'!D5) -> 241911273 | E4: =IF('NEW ACCOUNT'!A5="","",'NEW ACCOUNT'!E5) -> mankessim | F4: =IF('NEW ACCOUNT'!A5="","",'NEW ACCOUNT'!F5) -> developer | G4: =IF('NEW ACCOUNT'!A5="","",'NEW ACCOUNT'!G5) -> 1 | H4: =IF('NEW ACCOUNT'!A5="","",'NEW ACCOUNT'!H5) -> 400 | I4: =IF('NEW ACCOUNT'!A5="","",'NEW ACCOUNT'!I5) -> 25/04/2026 | J4: =IF('NEW ACCOUNT'!A5="","",'NEW ACCOUNT'!J5) -> Active | K4: =IFERROR(IF(A4="","",SUMIF(DB_Savings!$A:$A,A4,DB_Savings!$F:$F)),"") -> 0 | L4: =IFERROR(IF(A4="","",SUMIF(DB_Withdrawals!$A:$A,A4,DB_Withdrawals!$G:$G)),"") -> 0 | M4: =IFERROR(IF(A4="","",IFERROR(H4,0)+IFERROR(SUMIF(DB_Savings!$A:$A,A4,DB_Savings!$F:$F),0)-IFERROR(SUMIF(DB_Withdrawals!$A:$A,A4,DB_Withdrawals!$G:$G),0)),"") -> 400 | N4: =IFERROR(IF(A4="","",MAX(0,M4-System_Config!$B$9)),"") -> 390
A5: ='NEW ACCOUNT'!A6 | B5: =IF('NEW ACCOUNT'!A6="","",'NEW ACCOUNT'!B6) | C5: =IF('NEW ACCOUNT'!A6="","",'NEW ACCOUNT'!C6) | D5: =IF('NEW ACCOUNT'!A6="","",'NEW ACCOUNT'!D6) | E5: =IF('NEW ACCOUNT'!A6="","",'NEW ACCOUNT'!E6) | F5: =IF('NEW ACCOUNT'!A6="","",'NEW ACCOUNT'!F6) | G5: =IF('NEW ACCOUNT'!A6="","",'NEW ACCOUNT'!G6) | H5: =IF('NEW ACCOUNT'!A6="","",'NEW ACCOUNT'!H6) | I5: =IF('NEW ACCOUNT'!A6="","",'NEW ACCOUNT'!I6) | J5: =IF('NEW ACCOUNT'!A6="","",'NEW ACCOUNT'!J6) | K5: =IFERROR(IF(A5="","",SUMIF(DB_Savings!$A:$A,A5,DB_Savings!$F:$F)),"") | L5: =IFERROR(IF(A5="","",SUMIF(DB_Withdrawals!$A:$A,A5,DB_Withdrawals!$G:$G)),"") | M5: =IFERROR(IF(A5="","",IFERROR(H5,0)+IFERROR(SUMIF(DB_Savings!$A:$A,A5,DB_Savings!$F:$F),0)-IFERROR(SUMIF(DB_Withdrawals!$A:$A,A5,DB_Withdrawals!$G:$G),0)),"") | N5: =IFERROR(IF(A5="","",MAX(0,M5-System_Config!$B$9)),"")
A6: ='NEW ACCOUNT'!A7 | B6: =IF('NEW ACCOUNT'!A7="","",'NEW ACCOUNT'!B7) | C6: =IF('NEW ACCOUNT'!A7="","",'NEW ACCOUNT'!C7) | D6: =IF('NEW ACCOUNT'!A7="","",'NEW ACCOUNT'!D7) | E6: =IF('NEW ACCOUNT'!A7="","",'NEW ACCOUNT'!E7) | F6: =IF('NEW ACCOUNT'!A7="","",'NEW ACCOUNT'!F7) | G6: =IF('NEW ACCOUNT'!A7="","",'NEW ACCOUNT'!G7) | H6: =IF('NEW ACCOUNT'!A7="","",'NEW ACCOUNT'!H7) | I6: =IF('NEW ACCOUNT'!A7="","",'NEW ACCOUNT'!I7) | J6: =IF('NEW ACCOUNT'!A7="","",'NEW ACCOUNT'!J7) | K6: =IFERROR(IF(A6="","",SUMIF(DB_Savings!$A:$A,A6,DB_Savings!$F:$F)),"") | L6: =IFERROR(IF(A6="","",SUMIF(DB_Withdrawals!$A:$A,A6,DB_Withdrawals!$G:$G)),"") | M6: =IFERROR(IF(A6="","",IFERROR(H6,0)+IFERROR(SUMIF(DB_Savings!$A:$A,A6,DB_Savings!$F:$F),0)-IFERROR(SUMIF(DB_Withdrawals!$A:$A,A6,DB_Withdrawals!$G:$G),0)),"") | N6: =IFERROR(IF(A6="","",MAX(0,M6-System_Config!$B$9)),"")
A7: ='NEW ACCOUNT'!A8 | B7: =IF('NEW ACCOUNT'!A8="","",'NEW ACCOUNT'!B8) | C7: =IF('NEW ACCOUNT'!A8="","",'NEW ACCOUNT'!C8) | D7: =IF('NEW ACCOUNT'!A8="","",'NEW ACCOUNT'!D8) | E7: =IF('NEW ACCOUNT'!A8="","",'NEW ACCOUNT'!E8) | F7: =IF('NEW ACCOUNT'!A8="","",'NEW ACCOUNT'!F8) | G7: =IF('NEW ACCOUNT'!A8="","",'NEW ACCOUNT'!G8) | H7: =IF('NEW ACCOUNT'!A8="","",'NEW ACCOUNT'!H8) | I7: =IF('NEW ACCOUNT'!A8="","",'NEW ACCOUNT'!I8) | J7: =IF('NEW ACCOUNT'!A8="","",'NEW ACCOUNT'!J8) | K7: =IFERROR(IF(A7="","",SUMIF(DB_Savings!$A:$A,A7,DB_Savings!$F:$F)),"") | L7: =IFERROR(IF(A7="","",SUMIF(DB_Withdrawals!$A:$A,A7,DB_Withdrawals!$G:$G)),"") | M7: =IFERROR(IF(A7="","",IFERROR(H7,0)+IFERROR(SUMIF(DB_Savings!$A:$A,A7,DB_Savings!$F:$F),0)-IFERROR(SUMIF(DB_Withdrawals!$A:$A,A7,DB_Withdrawals!$G:$G),0)),"") | N7: =IFERROR(IF(A7="","",MAX(0,M7-System_Config!$B$9)),"")
A8: ='NEW ACCOUNT'!A9 | B8: =IF('NEW ACCOUNT'!A9="","",'NEW ACCOUNT'!B9) | C8: =IF('NEW ACCOUNT'!A9="","",'NEW ACCOUNT'!C9) | D8: =IF('NEW ACCOUNT'!A9="","",'NEW ACCOUNT'!D9) | E8: =IF('NEW ACCOUNT'!A9="","",'NEW ACCOUNT'!E9) | F8: =IF('NEW ACCOUNT'!A9="","",'NEW ACCOUNT'!F9) | G8: =IF('NEW ACCOUNT'!A9="","",'NEW ACCOUNT'!G9) | H8: =IF('NEW ACCOUNT'!A9="","",'NEW ACCOUNT'!H9) | I8: =IF('NEW ACCOUNT'!A9="","",'NEW ACCOUNT'!I9) | J8: =IF('NEW ACCOUNT'!A9="","",'NEW ACCOUNT'!J9) | K8: =IFERROR(IF(A8="","",SUMIF(DB_Savings!$A:$A,A8,DB_Savings!$F:$F)),"") | L8: =IFERROR(IF(A8="","",SUMIF(DB_Withdrawals!$A:$A,A8,DB_Withdrawals!$G:$G)),"") | M8: =IFERROR(IF(A8="","",IFERROR(H8,0)+IFERROR(SUMIF(DB_Savings!$A:$A,A8,DB_Savings!$F:$F),0)-IFERROR(SUMIF(DB_Withdrawals!$A:$A,A8,DB_Withdrawals!$G:$G),0)),"") | N8: =IFERROR(IF(A8="","",MAX(0,M8-System_Config!$B$9)),"")
A9: ='NEW ACCOUNT'!A10 | B9: =IF('NEW ACCOUNT'!A10="","",'NEW ACCOUNT'!B10) | C9: =IF('NEW ACCOUNT'!A10="","",'NEW ACCOUNT'!C10) | D9: =IF('NEW ACCOUNT'!A10="","",'NEW ACCOUNT'!D10) | E9: =IF('NEW ACCOUNT'!A10="","",'NEW ACCOUNT'!E10) | F9: =IF('NEW ACCOUNT'!A10="","",'NEW ACCOUNT'!F10) | G9: =IF('NEW ACCOUNT'!A10="","",'NEW ACCOUNT'!G10) | H9: =IF('NEW ACCOUNT'!A10="","",'NEW ACCOUNT'!H10) | I9: =IF('NEW ACCOUNT'!A10="","",'NEW ACCOUNT'!I10) | J9: =IF('NEW ACCOUNT'!A10="","",'NEW ACCOUNT'!J10) | K9: =IFERROR(IF(A9="","",SUMIF(DB_Savings!$A:$A,A9,DB_Savings!$F:$F)),"") | L9: =IFERROR(IF(A9="","",SUMIF(DB_Withdrawals!$A:$A,A9,DB_Withdrawals!$G:$G)),"") | M9: =IFERROR(IF(A9="","",IFERROR(H9,0)+IFERROR(SUMIF(DB_Savings!$A:$A,A9,DB_Savings!$F:$F),0)-IFERROR(SUMIF(DB_Withdrawals!$A:$A,A9,DB_Withdrawals!$G:$G),0)),"") | N9: =IFERROR(IF(A9="","",MAX(0,M9-System_Config!$B$9)),"")
A10: ='NEW ACCOUNT'!A11 | B10: =IF('NEW ACCOUNT'!A11="","",'NEW ACCOUNT'!B11) | C10: =IF('NEW ACCOUNT'!A11="","",'NEW ACCOUNT'!C11) | D10: =IF('NEW ACCOUNT'!A11="","",'NEW ACCOUNT'!D11) | E10: =IF('NEW ACCOUNT'!A11="","",'NEW ACCOUNT'!E11) | F10: =IF('NEW ACCOUNT'!A11="","",'NEW ACCOUNT'!F11) | G10: =IF('NEW ACCOUNT'!A11="","",'NEW ACCOUNT'!G11) | H10: =IF('NEW ACCOUNT'!A11="","",'NEW ACCOUNT'!H11) | I10: =IF('NEW ACCOUNT'!A11="","",'NEW ACCOUNT'!I11) | J10: =IF('NEW ACCOUNT'!A11="","",'NEW ACCOUNT'!J11) | K10: =IFERROR(IF(A10="","",SUMIF(DB_Savings!$A:$A,A10,DB_Savings!$F:$F)),"") | L10: =IFERROR(IF(A10="","",SUMIF(DB_Withdrawals!$A:$A,A10,DB_Withdrawals!$G:$G)),"") | M10: =IFERROR(IF(A10="","",IFERROR(H10,0)+IFERROR(SUMIF(DB_Savings!$A:$A,A10,DB_Savings!$F:$F),0)-IFERROR(SUMIF(DB_Withdrawals!$A:$A,A10,DB_Withdrawals!$G:$G),0)),"") | N10: =IFERROR(IF(A10="","",MAX(0,M10-System_Config!$B$9)),"")
A11: ='NEW ACCOUNT'!A12 | B11: =IF('NEW ACCOUNT'!A12="","",'NEW ACCOUNT'!B12) | C11: =IF('NEW ACCOUNT'!A12="","",'NEW ACCOUNT'!C12) | D11: =IF('NEW ACCOUNT'!A12="","",'NEW ACCOUNT'!D12) | E11: =IF('NEW ACCOUNT'!A12="","",'NEW ACCOUNT'!E12) | F11: =IF('NEW ACCOUNT'!A12="","",'NEW ACCOUNT'!F12) | G11: =IF('NEW ACCOUNT'!A12="","",'NEW ACCOUNT'!G12) | H11: =IF('NEW ACCOUNT'!A12="","",'NEW ACCOUNT'!H12) | I11: =IF('NEW ACCOUNT'!A12="","",'NEW ACCOUNT'!I12) | J11: =IF('NEW ACCOUNT'!A12="","",'NEW ACCOUNT'!J12) | K11: =IFERROR(IF(A11="","",SUMIF(DB_Savings!$A:$A,A11,DB_Savings!$F:$F)),"") | L11: =IFERROR(IF(A11="","",SUMIF(DB_Withdrawals!$A:$A,A11,DB_Withdrawals!$G:$G)),"") | M11: =IFERROR(IF(A11="","",IFERROR(H11,0)+IFERROR(SUMIF(DB_Savings!$A:$A,A11,DB_Savings!$F:$F),0)-IFERROR(SUMIF(DB_Withdrawals!$A:$A,A11,DB_Withdrawals!$G:$G),0)),"") | N11: =IFERROR(IF(A11="","",MAX(0,M11-System_Config!$B$9)),"")
A12: ='NEW ACCOUNT'!A13 | B12: =IF('NEW ACCOUNT'!A13="","",'NEW ACCOUNT'!B13) | C12: =IF('NEW ACCOUNT'!A13="","",'NEW ACCOUNT'!C13) | D12: =IF('NEW ACCOUNT'!A13="","",'NEW ACCOUNT'!D13) | E12: =IF('NEW ACCOUNT'!A13="","",'NEW ACCOUNT'!E13) | F12: =IF('NEW ACCOUNT'!A13="","",'NEW ACCOUNT'!F13) | G12: =IF('NEW ACCOUNT'!A13="","",'NEW ACCOUNT'!G13) | H12: =IF('NEW ACCOUNT'!A13="","",'NEW ACCOUNT'!H13) | I12: =IF('NEW ACCOUNT'!A13="","",'NEW ACCOUNT'!I13) | J12: =IF('NEW ACCOUNT'!A13="","",'NEW ACCOUNT'!J13) | K12: =IFERROR(IF(A12="","",SUMIF(DB_Savings!$A:$A,A12,DB_Savings!$F:$F)),"") | L12: =IFERROR(IF(A12="","",SUMIF(DB_Withdrawals!$A:$A,A12,DB_Withdrawals!$G:$G)),"") | M12: =IFERROR(IF(A12="","",IFERROR(H12,0)+IFERROR(SUMIF(DB_Savings!$A:$A,A12,DB_Savings!$F:$F),0)-IFERROR(SUMIF(DB_Withdrawals!$A:$A,A12,DB_Withdrawals!$G:$G),0)),"") | N12: =IFERROR(IF(A12="","",MAX(0,M12-System_Config!$B$9)),"")
A13: ='NEW ACCOUNT'!A14 | B13: =IF('NEW ACCOUNT'!A14="","",'NEW ACCOUNT'!B14) | C13: =IF('NEW ACCOUNT'!A14="","",'NEW ACCOUNT'!C14) | D13: =IF('NEW ACCOUNT'!A14="","",'NEW ACCOUNT'!D14) | E13: =IF('NEW ACCOUNT'!A14="","",'NEW ACCOUNT'!E14) | F13: =IF('NEW ACCOUNT'!A14="","",'NEW ACCOUNT'!F14) | G13: =IF('NEW ACCOUNT'!A14="","",'NEW ACCOUNT'!G14) | H13: =IF('NEW ACCOUNT'!A14="","",'NEW ACCOUNT'!H14) | I13: =IF('NEW ACCOUNT'!A14="","",'NEW ACCOUNT'!I14) | J13: =IF('NEW ACCOUNT'!A14="","",'NEW ACCOUNT'!J14) | K13: =IFERROR(IF(A13="","",SUMIF(DB_Savings!$A:$A,A13,DB_Savings!$F:$F)),"") | L13: =IFERROR(IF(A13="","",SUMIF(DB_Withdrawals!$A:$A,A13,DB_Withdrawals!$G:$G)),"") | M13: =IFERROR(IF(A13="","",IFERROR(H13,0)+IFERROR(SUMIF(DB_Savings!$A:$A,A13,DB_Savings!$F:$F),0)-IFERROR(SUMIF(DB_Withdrawals!$A:$A,A13,DB_Withdrawals!$G:$G),0)),"") | N13: =IFERROR(IF(A13="","",MAX(0,M13-System_Config!$B$9)),"")
A14: ='NEW ACCOUNT'!A15 | B14: =IF('NEW ACCOUNT'!A15="","",'NEW ACCOUNT'!B15) | C14: =IF('NEW ACCOUNT'!A15="","",'NEW ACCOUNT'!C15) | D14: =IF('NEW ACCOUNT'!A15="","",'NEW ACCOUNT'!D15) | E14: =IF('NEW ACCOUNT'!A15="","",'NEW ACCOUNT'!E15) | F14: =IF('NEW ACCOUNT'!A15="","",'NEW ACCOUNT'!F15) | G14: =IF('NEW ACCOUNT'!A15="","",'NEW ACCOUNT'!G15) | H14: =IF('NEW ACCOUNT'!A15="","",'NEW ACCOUNT'!H15) | I14: =IF('NEW ACCOUNT'!A15="","",'NEW ACCOUNT'!I15) | J14: =IF('NEW ACCOUNT'!A15="","",'NEW ACCOUNT'!J15) | K14: =IFERROR(IF(A14="","",SUMIF(DB_Savings!$A:$A,A14,DB_Savings!$F:$F)),"") | L14: =IFERROR(IF(A14="","",SUMIF(DB_Withdrawals!$A:$A,A14,DB_Withdrawals!$G:$G)),"") | M14: =IFERROR(IF(A14="","",IFERROR(H14,0)+IFERROR(SUMIF(DB_Savings!$A:$A,A14,DB_Savings!$F:$F),0)-IFERROR(SUMIF(DB_Withdrawals!$A:$A,A14,DB_Withdrawals!$G:$G),0)),"") | N14: =IFERROR(IF(A14="","",MAX(0,M14-System_Config!$B$9)),"")
A15: ='NEW ACCOUNT'!A16 | B15: =IF('NEW ACCOUNT'!A16="","",'NEW ACCOUNT'!B16) | C15: =IF('NEW ACCOUNT'!A16="","",'NEW ACCOUNT'!C16) | D15: =IF('NEW ACCOUNT'!A16="","",'NEW ACCOUNT'!D16) | E15: =IF('NEW ACCOUNT'!A16="","",'NEW ACCOUNT'!E16) | F15: =IF('NEW ACCOUNT'!A16="","",'NEW ACCOUNT'!F16) | G15: =IF('NEW ACCOUNT'!A16="","",'NEW ACCOUNT'!G16) | H15: =IF('NEW ACCOUNT'!A16="","",'NEW ACCOUNT'!H16) | I15: =IF('NEW ACCOUNT'!A16="","",'NEW ACCOUNT'!I16) | J15: =IF('NEW ACCOUNT'!A16="","",'NEW ACCOUNT'!J16) | K15: =IFERROR(IF(A15="","",SUMIF(DB_Savings!$A:$A,A15,DB_Savings!$F:$F)),"") | L15: =IFERROR(IF(A15="","",SUMIF(DB_Withdrawals!$A:$A,A15,DB_Withdrawals!$G:$G)),"") | M15: =IFERROR(IF(A15="","",IFERROR(H15,0)+IFERROR(SUMIF(DB_Savings!$A:$A,A15,DB_Savings!$F:$F),0)-IFERROR(SUMIF(DB_Withdrawals!$A:$A,A15,DB_Withdrawals!$G:$G),0)),"") | N15: =IFERROR(IF(A15="","",MAX(0,M15-System_Config!$B$9)),"")
... A503: ='NEW ACCOUNT'!A504 | B503: =IF('NEW ACCOUNT'!A504="","",'NEW ACCOUNT'!B504) | C503: =IF('NEW ACCOUNT'!A504="","",'NEW ACCOUNT'!C504) | D503: =IF('NEW ACCOUNT'!A504="","",'NEW ACCOUNT'!D504) | E503: =IF('NEW ACCOUNT'!A504="","",'NEW ACCOUNT'!E504) | F503: =IF('NEW ACCOUNT'!A504="","",'NEW ACCOUNT'!F504) | G503: =IF('NEW ACCOUNT'!A504="","",'NEW ACCOUNT'!G504) | H503: =IF('NEW ACCOUNT'!A504="","",'NEW ACCOUNT'!H504) | I503: =IF('NEW ACCOUNT'!A504="","",'NEW ACCOUNT'!I504) | J503: =IF('NEW ACCOUNT'!A504="","",'NEW ACCOUNT'!J504) | K503: =IFERROR(IF(A503="","",SUMIF(DB_Savings!$A:$A,A503,DB_Savings!$F:$F)),"") | L503: =IFERROR(IF(A503="","",SUMIF(DB_Withdrawals!$A:$A,A503,DB_Withdrawals!$G:$G)),"") | M503: =IFERROR(IF(A503="","",IFERROR(H503,0)+IFERROR(SUMIF(DB_Savings!$A:$A,A503,DB_Savings!$F:$F),0)-IFERROR(SUMIF(DB_Withdrawals!$A:$A,A503,DB_Withdrawals!$G:$G),0)),"") | N503: =IFERROR(IF(A503="","",MAX(0,M503-System_Config!$B$9)),"")

Sheet DB_Savings
A1: 💰 SAVINGS TRANSACTIONS DATABASE — All Agents Combined
A2: All savings from all 10 agents are recorded here | READ-ONLY — do not edit formulas
A3: Account_No | B3: Transaction_ID | C3: Customer_Name | D3: Date | E3: Amount_GHS | F3: New_Balance | G3: Agent | H3: Status | I3: Saved_At | J3: Notes | K3: Year
K4: =IFERROR(YEAR(D4),"") -> 1900
K5: =IFERROR(YEAR(D5),"") -> 1900
K6: =IFERROR(YEAR(D6),"") -> 1900
K7: =IFERROR(YEAR(D7),"") -> 1900
K8: =IFERROR(YEAR(D8),"") -> 1900
K9: =IFERROR(YEAR(D9),"") -> 1900
K10: =IFERROR(YEAR(D10),"") -> 1900
K11: =IFERROR(YEAR(D11),"") -> 1900
K12: =IFERROR(YEAR(D12),"") -> 1900
K13: =IFERROR(YEAR(D13),"") -> 1900
K14: =IFERROR(YEAR(D14),"") -> 1900
K15: =IFERROR(YEAR(D15),"") -> 1900
... K5003: =IFERROR(YEAR(D5003),"") -> 1900

Sheet DB_Withdrawals
A1: 🏧 WITHDRAWALS TRANSACTIONS DATABASE — All Agents Combined
A2: All withdrawals from all 10 agents recorded here | Minimum balance GHS 10 enforced
A3: Account_No | B3: Transaction_ID | C3: Customer_Name | D3: Balance_Before | E3: Date | F3: Authorized_By | G3: Withdrawal_Amt_GHS | H3: New_Balance_GHS | I3: Agent | J3: Status | K3: Saved_At | L3: Min_Bal_Compliant | M3: Year
L4: =IF(G4="","",IF(D4-G4>=System_Config!$B$9,"✅ COMPLIANT","⚠️ BREACH")) | M4: =IFERROR(YEAR(E4),"") -> 1900
L5: =IF(G5="","",IF(D5-G5>=System_Config!$B$9,"✅ COMPLIANT","⚠️ BREACH")) | M5: =IFERROR(YEAR(E5),"") -> 1900
L6: =IF(G6="","",IF(D6-G6>=System_Config!$B$9,"✅ COMPLIANT","⚠️ BREACH")) | M6: =IFERROR(YEAR(E6),"") -> 1900
L7: =IF(G7="","",IF(D7-G7>=System_Config!$B$9,"✅ COMPLIANT","⚠️ BREACH")) | M7: =IFERROR(YEAR(E7),"") -> 1900
L8: =IF(G8="","",IF(D8-G8>=System_Config!$B$9,"✅ COMPLIANT","⚠️ BREACH")) | M8: =IFERROR(YEAR(E8),"") -> 1900
L9: =IF(G9="","",IF(D9-G9>=System_Config!$B$9,"✅ COMPLIANT","⚠️ BREACH")) | M9: =IFERROR(YEAR(E9),"") -> 1900
L10: =IF(G10="","",IF(D10-G10>=System_Config!$B$9,"✅ COMPLIANT","⚠️ BREACH")) | M10: =IFERROR(YEAR(E10),"") -> 1900
L11: =IF(G11="","",IF(D11-G11>=System_Config!$B$9,"✅ COMPLIANT","⚠️ BREACH")) | M11: =IFERROR(YEAR(E11),"") -> 1900
L12: =IF(G12="","",IF(D12-G12>=System_Config!$B$9,"✅ COMPLIANT","⚠️ BREACH")) | M12: =IFERROR(YEAR(E12),"") -> 1900
L13: =IF(G13="","",IF(D13-G13>=System_Config!$B$9,"✅ COMPLIANT","⚠️ BREACH")) | M13: =IFERROR(YEAR(E13),"") -> 1900
L14: =IF(G14="","",IF(D14-G14>=System_Config!$B$9,"✅ COMPLIANT","⚠️ BREACH")) | M14: =IFERROR(YEAR(E14),"") -> 1900
L15: =IF(G15="","",IF(D15-G15>=System_Config!$B$9,"✅ COMPLIANT","⚠️ BREACH")) | M15: =IFERROR(YEAR(E15),"") -> 1900
... L5003: =IF(G5003="","",IF(D5003-G5003>=System_Config!$B$9,"✅ COMPLIANT","⚠️ BREACH")) | M5003: =IFERROR(YEAR(E5003),"") -> 1900

Sheet DB_Loans
A1: 🏦 LOANS DATABASE — All Agents Combined
A3: Loan_ID | B3: Account_No | C3: Customer_Name | D3: Request_Date | E3: Loan_Amount | F3: Purpose | G3: Months | H3: Rate_% | I3: Total_Repayable | J3: Monthly_Installment | K3: Status | L3: Agent
I4: =IF(E4="","",E4+(E4*H4/100*G4)) | J4: =IFERROR(I4/G4,"")
I5: =IF(E5="","",E5+(E5*H5/100*G5)) | J5: =IFERROR(I5/G5,"")
I6: =IF(E6="","",E6+(E6*H6/100*G6)) | J6: =IFERROR(I6/G6,"")
I7: =IF(E7="","",E7+(E7*H7/100*G7)) | J7: =IFERROR(I7/G7,"")
I8: =IF(E8="","",E8+(E8*H8/100*G8)) | J8: =IFERROR(I8/G8,"")
I9: =IF(E9="","",E9+(E9*H9/100*G9)) | J9: =IFERROR(I9/G9,"")
I10: =IF(E10="","",E10+(E10*H10/100*G10)) | J10: =IFERROR(I10/G10,"")
I11: =IF(E11="","",E11+(E11*H11/100*G11)) | J11: =IFERROR(I11/G11,"")
I12: =IF(E12="","",E12+(E12*H12/100*G12)) | J12: =IFERROR(I12/G12,"")
I13: =IF(E13="","",E13+(E13*H13/100*G13)) | J13: =IFERROR(I13/G13,"")
I14: =IF(E14="","",E14+(E14*H14/100*G14)) | J14: =IFERROR(I14/G14,"")
I15: =IF(E15="","",E15+(E15*H15/100*G15)) | J15: =IFERROR(I15/G15,"")
... I2003: =IF(E2003="","",E2003+(E2003*H2003/100*G2003)) | J2003: =IFERROR(I2003/G2003,"")

Sheet LOAN TOPUP
A1: 🔗 LOAN TOP-UP REGISTER — All Agents
A2: Top-up amounts aggregate with parent loan. Unified repayment auto-calculated. Link via Account Number + Loan ID.
A3: Top-Up ID | B3: Account Number | C3: Customer Name | D3: Parent Loan ID | E3: Top-Up Amount (GHS) | F3: Date | G3: Purpose/Notes | H3: Aggregated Loan Balance (GHS) | I3: Unified Monthly Repay (GHS) | J3: Agent
A4: =IF(B4="","","TU"&TEXT(ROW()-3,"0000")) | C4: =IFERROR(IF(B4="","",VLOOKUP(B4,DB_Customers!$A:$B,2,0)),"") | F4: =IF(B4="","",TODAY()) | H4: =IFERROR(IF(OR(B4="",E4=""),"",SUMIF(DB_Loans!$B:$B,B4,DB_Loans!$E:$E)+E4),"") | I4: =IFERROR(IF(OR(B4="",E4=""),"",SUMIF(DB_Loans!$B:$B,B4,DB_Loans!$J:$J)+IFERROR(E4*2.5/100,0)),"")
A5: =IF(B5="","","TU"&TEXT(ROW()-3,"0000")) | C5: =IFERROR(IF(B5="","",VLOOKUP(B5,DB_Customers!$A:$B,2,0)),"") | F5: =IF(B5="","",TODAY()) | H5: =IFERROR(IF(OR(B5="",E5=""),"",SUMIF(DB_Loans!$B:$B,B5,DB_Loans!$E:$E)+E5),"") | I5: =IFERROR(IF(OR(B5="",E5=""),"",SUMIF(DB_Loans!$B:$B,B5,DB_Loans!$J:$J)+IFERROR(E5*2.5/100,0)),"")
A6: =IF(B6="","","TU"&TEXT(ROW()-3,"0000")) | C6: =IFERROR(IF(B6="","",VLOOKUP(B6,DB_Customers!$A:$B,2,0)),"") | F6: =IF(B6="","",TODAY()) | H6: =IFERROR(IF(OR(B6="",E6=""),"",SUMIF(DB_Loans!$B:$B,B6,DB_Loans!$E:$E)+E6),"") | I6: =IFERROR(IF(OR(B6="",E6=""),"",SUMIF(DB_Loans!$B:$B,B6,DB_Loans!$J:$J)+IFERROR(E6*2.5/100,0)),"")
A7: =IF(B7="","","TU"&TEXT(ROW()-3,"0000")) | C7: =IFERROR(IF(B7="","",VLOOKUP(B7,DB_Customers!$A:$B,2,0)),"") | F7: =IF(B7="","",TODAY()) | H7: =IFERROR(IF(OR(B7="",E7=""),"",SUMIF(DB_Loans!$B:$B,B7,DB_Loans!$E:$E)+E7),"") | I7: =IFERROR(IF(OR(B7="",E7=""),"",SUMIF(DB_Loans!$B:$B,B7,DB_Loans!$J:$J)+IFERROR(E7*2.5/100,0)),"")
A8: =IF(B8="","","TU"&TEXT(ROW()-3,"0000")) | C8: =IFERROR(IF(B8="","",VLOOKUP(B8,DB_Customers!$A:$B,2,0)),"") | F8: =IF(B8="","",TODAY()) | H8: =IFERROR(IF(OR(B8="",E8=""),"",SUMIF(DB_Loans!$B:$B,B8,DB_Loans!$E:$E)+E8),"") | I8: =IFERROR(IF(OR(B8="",E8=""),"",SUMIF(DB_Loans!$B:$B,B8,DB_Loans!$J:$J)+IFERROR(E8*2.5/100,0)),"")
A9: =IF(B9="","","TU"&TEXT(ROW()-3,"0000")) | C9: =IFERROR(IF(B9="","",VLOOKUP(B9,DB_Customers!$A:$B,2,0)),"") | F9: =IF(B9="","",TODAY()) | H9: =IFERROR(IF(OR(B9="",E9=""),"",SUMIF(DB_Loans!$B:$B,B9,DB_Loans!$E:$E)+E9),"") | I9: =IFERROR(IF(OR(B9="",E9=""),"",SUMIF(DB_Loans!$B:$B,B9,DB_Loans!$J:$J)+IFERROR(E9*2.5/100,0)),"")
A10: =IF(B10="","","TU"&TEXT(ROW()-3,"0000")) | C10: =IFERROR(IF(B10="","",VLOOKUP(B10,DB_Customers!$A:$B,2,0)),"") | F10: =IF(B10="","",TODAY()) | H10: =IFERROR(IF(OR(B10="",E10=""),"",SUMIF(DB_Loans!$B:$B,B10,DB_Loans!$E:$E)+E10),"") | I10: =IFERROR(IF(OR(B10="",E10=""),"",SUMIF(DB_Loans!$B:$B,B10,DB_Loans!$J:$J)+IFERROR(E10*2.5/100,0)),"")
A11: =IF(B11="","","TU"&TEXT(ROW()-3,"0000")) | C11: =IFERROR(IF(B11="","",VLOOKUP(B11,DB_Customers!$A:$B,2,0)),"") | F11: =IF(B11="","",TODAY()) | H11: =IFERROR(IF(OR(B11="",E11=""),"",SUMIF(DB_Loans!$B:$B,B11,DB_Loans!$E:$E)+E11),"") | I11: =IFERROR(IF(OR(B11="",E11=""),"",SUMIF(DB_Loans!$B:$B,B11,DB_Loans!$J:$J)+IFERROR(E11*2.5/100,0)),"")
A12: =IF(B12="","","TU"&TEXT(ROW()-3,"0000")) | C12: =IFERROR(IF(B12="","",VLOOKUP(B12,DB_Customers!$A:$B,2,0)),"") | F12: =IF(B12="","",TODAY()) | H12: =IFERROR(IF(OR(B12="",E12=""),"",SUMIF(DB_Loans!$B:$B,B12,DB_Loans!$E:$E)+E12),"") | I12: =IFERROR(IF(OR(B12="",E12=""),"",SUMIF(DB_Loans!$B:$B,B12,DB_Loans!$J:$J)+IFERROR(E12*2.5/100,0)),"")
A13: =IF(B13="","","TU"&TEXT(ROW()-3,"0000")) | C13: =IFERROR(IF(B13="","",VLOOKUP(B13,DB_Customers!$A:$B,2,0)),"") | F13: =IF(B13="","",TODAY()) | H13: =IFERROR(IF(OR(B13="",E13=""),"",SUMIF(DB_Loans!$B:$B,B13,DB_Loans!$E:$E)+E13),"") | I13: =IFERROR(IF(OR(B13="",E13=""),"",SUMIF(DB_Loans!$B:$B,B13,DB_Loans!$J:$J)+IFERROR(E13*2.5/100,0)),"")
A14: =IF(B14="","","TU"&TEXT(ROW()-3,"0000")) | C14: =IFERROR(IF(B14="","",VLOOKUP(B14,DB_Customers!$A:$B,2,0)),"") | F14: =IF(B14="","",TODAY()) | H14: =IFERROR(IF(OR(B14="",E14=""),"",SUMIF(DB_Loans!$B:$B,B14,DB_Loans!$E:$E)+E14),"") | I14: =IFERROR(IF(OR(B14="",E14=""),"",SUMIF(DB_Loans!$B:$B,B14,DB_Loans!$J:$J)+IFERROR(E14*2.5/100,0)),"")
A15: =IF(B15="","","TU"&TEXT(ROW()-3,"0000")) | C15: =IFERROR(IF(B15="","",VLOOKUP(B15,DB_Customers!$A:$B,2,0)),"") | F15: =IF(B15="","",TODAY()) | H15: =IFERROR(IF(OR(B15="",E15=""),"",SUMIF(DB_Loans!$B:$B,B15,DB_Loans!$E:$E)+E15),"") | I15: =IFERROR(IF(OR(B15="",E15=""),"",SUMIF(DB_Loans!$B:$B,B15,DB_Loans!$J:$J)+IFERROR(E15*2.5/100,0)),"")
... A503: =IF(B503="","","TU"&TEXT(ROW()-3,"0000")) | C503: =IFERROR(IF(B503="","",VLOOKUP(B503,DB_Customers!$A:$B,2,0)),"") | F503: =IF(B503="","",TODAY()) | H503: =IFERROR(IF(OR(B503="",E503=""),"",SUMIF(DB_Loans!$B:$B,B503,DB_Loans!$E:$E)+E503),"") | I503: =IFERROR(IF(OR(B503="",E503=""),"",SUMIF(DB_Loans!$B:$B,B503,DB_Loans!$J:$J)+IFERROR(E503*2.5/100,0)),"")

Sheet Agent01_Savings
A1: 💰 SAMICIOUS MICROFINANCE — AGENT01 SAVINGS
A2: Agent: Agent 01 | Enter Account # → All fields auto-populate | Status auto-sets to "Saved" | 🔑 Enter your 4-digit code to validate
A3: 💰 Total Collected Today | D3: 📊 Transactions Today | G3: 📅 Date
A4: =IFERROR(SUMIFS(DB_Savings!$F:$F,DB_Savings!$G:$G,"Agent 01",DB_Savings!$D:$D,TODAY()),0) -> 0 | D4: =IFERROR(COUNTIFS(DB_Savings!$G:$G,"Agent 01",DB_Savings!$D:$D,TODAY()),0) -> 0 | G4: =TEXT(TODAY(),"DDDD, DD MMMM YYYY") -> Saturday, 25 April 2026
A7: 📝 ENTRY FORM — Enter Account Number in column A. All other fields auto-populate. Enter Savings Amount in col E, then your 4-digit Agent Code in col H.
A8: Account # | B8: Customer Name | C8: Current Balance | D8: Date | E8: Savings Amount | F8: New Balance | G8: Agent | H8: 🔑 Agent Code | I8: Status | J8: Saved At | K8: Notes
B9: =IF(A9="","",IFERROR(VLOOKUP(A9,DB_Customers!$A:$B,2,0),"❌ Account Not Found")) | C9: =IF(A9="","",IFERROR(VLOOKUP(A9,DB_Customers!$A:$M,13,0),"")) | D9: =IF(A9="","",TODAY()) | F9: =IFERROR(IF(OR(A9="",E9=""),"",C9+E9),"") | G9: Agent 01 | I9: =IF(A9="","Pending",IF(H9="","⚠️ Enter Agent Code",IF(IFERROR(VLOOKUP(G9,DB_Agents!$B:$E,4,0),"")=H9,IF(AND(A9<>"",E9<>""),"✅ Saved","Pending"),"🔒 WRONG CODE"))) -> Pending | J9: =IF(I9="✅ Saved",TEXT(TODAY(),"YYYY-MM-DD")&" Auto","—") -> —
B10: =IF(A10="","",IFERROR(VLOOKUP(A10,DB_Customers!$A:$B,2,0),"❌ Account Not Found")) | C10: =IF(A10="","",IFERROR(VLOOKUP(A10,DB_Customers!$A:$M,13,0),"")) | D10: =IF(A10="","",TODAY()) | F10: =IFERROR(IF(OR(A10="",E10=""),"",C10+E10),"") | G10: Agent 01 | I10: =IF(A10="","Pending",IF(H10="","⚠️ Enter Agent Code",IF(IFERROR(VLOOKUP(G10,DB_Agents!$B:$E,4,0),"")=H10,IF(AND(A10<>"",E10<>""),"✅ Saved","Pending"),"🔒 WRONG CODE"))) -> Pending | J10: =IF(I10="✅ Saved",TEXT(TODAY(),"YYYY-MM-DD")&" Auto","—") -> —
B11: =IF(A11="","",IFERROR(VLOOKUP(A11,DB_Customers!$A:$B,2,0),"❌ Account Not Found")) | C11: =IF(A11="","",IFERROR(VLOOKUP(A11,DB_Customers!$A:$M,13,0),"")) | D11: =IF(A11="","",TODAY()) | F11: =IFERROR(IF(OR(A11="",E11=""),"",C11+E11),"") | G11: Agent 01 | I11: =IF(A11="","Pending",IF(H11="","⚠️ Enter Agent Code",IF(IFERROR(VLOOKUP(G11,DB_Agents!$B:$E,4,0),"")=H11,IF(AND(A11<>"",E11<>""),"✅ Saved","Pending"),"🔒 WRONG CODE"))) -> Pending | J11: =IF(I11="✅ Saved",TEXT(TODAY(),"YYYY-MM-DD")&" Auto","—") -> —
B12: =IF(A12="","",IFERROR(VLOOKUP(A12,DB_Customers!$A:$B,2,0),"❌ Account Not Found")) | C12: =IF(A12="","",IFERROR(VLOOKUP(A12,DB_Customers!$A:$M,13,0),"")) | D12: =IF(A12="","",TODAY()) | F12: =IFERROR(IF(OR(A12="",E12=""),"",C12+E12),"") | G12: Agent 01 | I12: =IF(A12="","Pending",IF(H12="","⚠️ Enter Agent Code",IF(IFERROR(VLOOKUP(G12,DB_Agents!$B:$E,4,0),"")=H12,IF(AND(A12<>"",E12<>""),"✅ Saved","Pending"),"🔒 WRONG CODE"))) -> Pending | J12: =IF(I12="✅ Saved",TEXT(TODAY(),"YYYY-MM-DD")&" Auto","—") -> —
B13: =IF(A13="","",IFERROR(VLOOKUP(A13,DB_Customers!$A:$B,2,0),"❌ Account Not Found")) | C13: =IF(A13="","",IFERROR(VLOOKUP(A13,DB_Customers!$A:$M,13,0),"")) | D13: =IF(A13="","",TODAY()) | F13: =IFERROR(IF(OR(A13="",E13=""),"",C13+E13),"") | G13: Agent 01 | I13: =IF(A13="","Pending",IF(H13="","⚠️ Enter Agent Code",IF(IFERROR(VLOOKUP(G13,DB_Agents!$B:$E,4,0),"")=H13,IF(AND(A13<>"",E13<>""),"✅ Saved","Pending"),"🔒 WRONG CODE"))) -> Pending | J13: =IF(I13="✅ Saved",TEXT(TODAY(),"YYYY-MM-DD")&" Auto","—") -> —
B14: =IF(A14="","",IFERROR(VLOOKUP(A14,DB_Customers!$A:$B,2,0),"❌ Account Not Found")) | C14: =IF(A14="","",IFERROR(VLOOKUP(A14,DB_Customers!$A:$M,13,0),"")) | D14: =IF(A14="","",TODAY()) | F14: =IFERROR(IF(OR(A14="",E14=""),"",C14+E14),"") | G14: Agent 01 | I14: =IF(A14="","Pending",IF(H14="","⚠️ Enter Agent Code",IF(IFERROR(VLOOKUP(G14,DB_Agents!$B:$E,4,0),"")=H14,IF(AND(A14<>"",E14<>""),"✅ Saved","Pending"),"🔒 WRONG CODE"))) -> Pending | J14: =IF(I14="✅ Saved",TEXT(TODAY(),"YYYY-MM-DD")&" Auto","—") -> —
B15: =IF(A15="","",IFERROR(VLOOKUP(A15,DB_Customers!$A:$B,2,0),"❌ Account Not Found")) | C15: =IF(A15="","",IFERROR(VLOOKUP(A15,DB_Customers!$A:$M,13,0),"")) | D15: =IF(A15="","",TODAY()) | F15: =IFERROR(IF(OR(A15="",E15=""),"",C15+E15),"") | G15: Agent 01 | I15: =IF(A15="","Pending",IF(H15="","⚠️ Enter Agent Code",IF(IFERROR(VLOOKUP(G15,DB_Agents!$B:$E,4,0),"")=H15,IF(AND(A15<>"",E15<>""),"✅ Saved","Pending"),"🔒 WRONG CODE"))) -> Pending | J15: =IF(I15="✅ Saved",TEXT(TODAY(),"YYYY-MM-DD")&" Auto","—") -> —
B16: =IF(A16="","",IFERROR(VLOOKUP(A16,DB_Customers!$A:$B,2,0),"❌ Account Not Found")) | C16: =IF(A16="","",IFERROR(VLOOKUP(A16,DB_Customers!$A:$M,13,0),"")) | D16: =IF(A16="","",TODAY()) | F16: =IFERROR(IF(OR(A16="",E16=""),"",C16+E16),"") | G16: Agent 01 | I16: =IF(A16="","Pending",IF(H16="","⚠️ Enter Agent Code",IF(IFERROR(VLOOKUP(G16,DB_Agents!$B:$E,4,0),"")=H16,IF(AND(A16<>"",E16<>""),"✅ Saved","Pending"),"🔒 WRONG CODE"))) -> Pending | J16: =IF(I16="✅ Saved",TEXT(TODAY(),"YYYY-MM-DD")&" Auto","—") -> —
B17: =IF(A17="","",IFERROR(VLOOKUP(A17,DB_Customers!$A:$B,2,0),"❌ Account Not Found")) | C17: =IF(A17="","",IFERROR(VLOOKUP(A17,DB_Customers!$A:$M,13,0),"")) | D17: =IF(A17="","",TODAY()) | F17: =IFERROR(IF(OR(A17="",E17=""),"",C17+E17),"") | G17: Agent 01 | I17: =IF(A17="","Pending",IF(H17="","⚠️ Enter Agent Code",IF(IFERROR(VLOOKUP(G17,DB_Agents!$B:$E,4,0),"")=H17,IF(AND(A17<>"",E17<>""),"✅ Saved","Pending"),"🔒 WRONG CODE"))) -> Pending | J17: =IF(I17="✅ Saved",TEXT(TODAY(),"YYYY-MM-DD")&" Auto","—") -> —
B18: =IF(A18="","",IFERROR(VLOOKUP(A18,DB_Customers!$A:$B,2,0),"❌ Account Not Found")) | C18: =IF(A18="","",IFERROR(VLOOKUP(A18,DB_Customers!$A:$M,13,0),"")) | D18: =IF(A18="","",TODAY()) | F18: =IFERROR(IF(OR(A18="",E18=""),"",C18+E18),"") | G18: Agent 01 | I18: =IF(A18="","Pending",IF(H18="","⚠️ Enter Agent Code",IF(IFERROR(VLOOKUP(G18,DB_Agents!$B:$E,4,0),"")=H18,IF(AND(A18<>"",E18<>""),"✅ Saved","Pending"),"🔒 WRONG CODE"))) -> Pending | J18: =IF(I18="✅ Saved",TEXT(TODAY(),"YYYY-MM-DD")&" Auto","—") -> —
B19: =IF(A19="","",IFERROR(VLOOKUP(A19,DB_Customers!$A:$B,2,0),"❌ Account Not Found")) | C19: =IF(A19="","",IFERROR(VLOOKUP(A19,DB_Customers!$A:$M,13,0),"")) | D19: =IF(A19="","",TODAY()) | F19: =IFERROR(IF(OR(A19="",E19=""),"",C19+E19),"") | G19: Agent 01 | I19: =IF(A19="","Pending",IF(H19="","⚠️ Enter Agent Code",IF(IFERROR(VLOOKUP(G19,DB_Agents!$B:$E,4,0),"")=H19,IF(AND(A19<>"",E19<>""),"✅ Saved","Pending"),"🔒 WRONG CODE"))) -> Pending | J19: =IF(I19="✅ Saved",TEXT(TODAY(),"YYYY-MM-DD")&" Auto","—") -> —
B20: =IF(A20="","",IFERROR(VLOOKUP(A20,DB_Customers!$A:$B,2,0),"❌ Account Not Found")) | C20: =IF(A20="","",IFERROR(VLOOKUP(A20,DB_Customers!$A:$M,13,0),"")) | D20: =IF(A20="","",TODAY()) | F20: =IFERROR(IF(OR(A20="",E20=""),"",C20+E20),"") | G20: Agent 01 | I20: =IF(A20="","Pending",IF(H20="","⚠️ Enter Agent Code",IF(IFERROR(VLOOKUP(G20,DB_Agents!$B:$E,4,0),"")=H20,IF(AND(A20<>"",E20<>""),"✅ Saved","Pending"),"🔒 WRONG CODE"))) -> Pending | J20: =IF(I20="✅ Saved",TEXT(TODAY(),"YYYY-MM-DD")&" Auto","—") -> —
... B208: =IF(A208="","",IFERROR(VLOOKUP(A208,DB_Customers!$A:$B,2,0),"❌ Account Not Found")) | C208: =IF(A208="","",IFERROR(VLOOKUP(A208,DB_Customers!$A:$M,13,0),"")) | D208: =IF(A208="","",TODAY()) | F208: =IFERROR(IF(OR(A208="",E208=""),"",C208+E208),"") | G208: Agent 01 | I208: =IF(A208="","Pending",IF(H208="","⚠️ Enter Agent Code",IF(IFERROR(VLOOKUP(G208,DB_Agents!$B:$E,4,0),"")=H208,IF(AND(A208<>"",E208<>""),"✅ Saved","Pending"),"🔒 WRONG CODE"))) -> Pending | J208: =IF(I208="✅ Saved",TEXT(TODAY(),"YYYY-MM-DD")&" Auto","—") -> —

Sheet Agent01_Withdrawals
A1: 🏧 SAMICIOUS MICROFINANCE — AGENT01 WITHDRAWALS
A2: Agent: Agent 01 | Status auto: "Successful" or "Unsuccessful" based on balance check | 🔑 Enter your 4-digit agent code to authorize | GHS 10 minimum balance enforced
A3: 🏧 Total Withdrawn Today | D3: ✅ Successful | G3: ❌ Unsuccessful | J3: 📅 Date
A4: =IFERROR(SUMIFS(DB_Withdrawals!$G:$G,DB_Withdrawals!$I:$I,"Agent 01",DB_Withdrawals!$E:$E,TODAY()),0) -> 0 | D4: =IFERROR(COUNTIFS(DB_Withdrawals!$I:$I,"Agent 01",DB_Withdrawals!$J:$J,"Successful",DB_Withdrawals!$E:$E,TODAY()),0) -> 0 | G4: =IFERROR(COUNTIFS(DB_Withdrawals!$I:$I,"Agent 01",DB_Withdrawals!$J:$J,"Unsuccessful",DB_Withdrawals!$E:$E,TODAY()),0) -> 0 | J4: =TEXT(TODAY(),"DD MMM YYYY") -> 25 Apr 2026
A6: ⚠️ WITHDRAWALS — System auto-validates balance. Insufficient funds show 'Unsuccessful'. GHS 10 minimum balance always retained.
A7: 📝 Enter Account # → Name, Balance auto-populate. Enter Withdrawal Amount & Authorized By. Enter Agent Code.
A8: Account # | B8: Customer Name | C8: Available Balance | D8: Date | E8: Withdrawal Amt | F8: Authorized By | G8: New Balance | H8: Agent | I8: 🔑 Agent Code | J8: Status | K8: Saved At | L8: Notes
B9: =IF(A9="","",IFERROR(VLOOKUP(A9,DB_Customers!$A:$B,2,0),"❌ Account Not Found")) | C9: =IF(A9="","",IFERROR(VLOOKUP(A9,DB_Customers!$A:$N,14,0),"")) | D9: =IF(A9="","",TODAY()) | G9: =IFERROR(IF(OR(A9="",E9=""),"",C9-E9),"") | H9: Agent 01 | J9: =IF(AND(A9<>"",E9<>""),IF(I9="","⚠️ Enter Code",IF(IFERROR(VLOOKUP(H9,DB_Agents!$B:$E,4,0),"")=I9,IF(C9>=E9,"Successful","Unsuccessful"),"🔒 WRONG CODE")),"Pending") -> Pending | K9: =IF(J9="Successful",TEXT(TODAY(),"YYYY-MM-DD")&" Auto","—") -> —
B10: =IF(A10="","",IFERROR(VLOOKUP(A10,DB_Customers!$A:$B,2,0),"❌ Account Not Found")) | C10: =IF(A10="","",IFERROR(VLOOKUP(A10,DB_Customers!$A:$N,14,0),"")) | D10: =IF(A10="","",TODAY()) | G10: =IFERROR(IF(OR(A10="",E10=""),"",C10-E10),"") | H10: Agent 01 | J10: =IF(AND(A10<>"",E10<>""),IF(I10="","⚠️ Enter Code",IF(IFERROR(VLOOKUP(H10,DB_Agents!$B:$E,4,0),"")=I10,IF(C10>=E10,"Successful","Unsuccessful"),"🔒 WRONG CODE")),"Pending") -> Pending | K10: =IF(J10="Successful",TEXT(TODAY(),"YYYY-MM-DD")&" Auto","—") -> —
B11: =IF(A11="","",IFERROR(VLOOKUP(A11,DB_Customers!$A:$B,2,0),"❌ Account Not Found")) | C11: =IF(A11="","",IFERROR(VLOOKUP(A11,DB_Customers!$A:$N,14,0),"")) | D11: =IF(A11="","",TODAY()) | G11: =IFERROR(IF(OR(A11="",E11=""),"",C11-E11),"") | H11: Agent 01 | J11: =IF(AND(A11<>"",E11<>""),IF(I11="","⚠️ Enter Code",IF(IFERROR(VLOOKUP(H11,DB_Agents!$B:$E,4,0),"")=I11,IF(C11>=E11,"Successful","Unsuccessful"),"🔒 WRONG CODE")),"Pending") -> Pending | K11: =IF(J11="Successful",TEXT(TODAY(),"YYYY-MM-DD")&" Auto","—") -> —
B12: =IF(A12="","",IFERROR(VLOOKUP(A12,DB_Customers!$A:$B,2,0),"❌ Account Not Found")) | C12: =IF(A12="","",IFERROR(VLOOKUP(A12,DB_Customers!$A:$N,14,0),"")) | D12: =IF(A12="","",TODAY()) | G12: =IFERROR(IF(OR(A12="",E12=""),"",C12-E12),"") | H12: Agent 01 | J12: =IF(AND(A12<>"",E12<>""),IF(I12="","⚠️ Enter Code",IF(IFERROR(VLOOKUP(H12,DB_Agents!$B:$E,4,0),"")=I12,IF(C12>=E12,"Successful","Unsuccessful"),"🔒 WRONG CODE")),"Pending") -> Pending | K12: =IF(J12="Successful",TEXT(TODAY(),"YYYY-MM-DD")&" Auto","—") -> —
B13: =IF(A13="","",IFERROR(VLOOKUP(A13,DB_Customers!$A:$B,2,0),"❌ Account Not Found")) | C13: =IF(A13="","",IFERROR(VLOOKUP(A13,DB_Customers!$A:$N,14,0),"")) | D13: =IF(A13="","",TODAY()) | G13: =IFERROR(IF(OR(A13="",E13=""),"",C13-E13),"") | H13: Agent 01 | J13: =IF(AND(A13<>"",E13<>""),IF(I13="","⚠️ Enter Code",IF(IFERROR(VLOOKUP(H13,DB_Agents!$B:$E,4,0),"")=I13,IF(C13>=E13,"Successful","Unsuccessful"),"🔒 WRONG CODE")),"Pending") -> Pending | K13: =IF(J13="Successful",TEXT(TODAY(),"YYYY-MM-DD")&" Auto","—") -> —
B14: =IF(A14="","",IFERROR(VLOOKUP(A14,DB_Customers!$A:$B,2,0),"❌ Account Not Found")) | C14: =IF(A14="","",IFERROR(VLOOKUP(A14,DB_Customers!$A:$N,14,0),"")) | D14: =IF(A14="","",TODAY()) | G14: =IFERROR(IF(OR(A14="",E14=""),"",C14-E14),"") | H14: Agent 01 | J14: =IF(AND(A14<>"",E14<>""),IF(I14="","⚠️ Enter Code",IF(IFERROR(VLOOKUP(H14,DB_Agents!$B:$E,4,0),"")=I14,IF(C14>=E14,"Successful","Unsuccessful"),"🔒 WRONG CODE")),"Pending") -> Pending | K14: =IF(J14="Successful",TEXT(TODAY(),"YYYY-MM-DD")&" Auto","—") -> —
B15: =IF(A15="","",IFERROR(VLOOKUP(A15,DB_Customers!$A:$B,2,0),"❌ Account Not Found")) | C15: =IF(A15="","",IFERROR(VLOOKUP(A15,DB_Customers!$A:$N,14,0),"")) | D15: =IF(A15="","",TODAY()) | G15: =IFERROR(IF(OR(A15="",E15=""),"",C15-E15),"") | H15: Agent 01 | J15: =IF(AND(A15<>"",E15<>""),IF(I15="","⚠️ Enter Code",IF(IFERROR(VLOOKUP(H15,DB_Agents!$B:$E,4,0),"")=I15,IF(C15>=E15,"Successful","Unsuccessful"),"🔒 WRONG CODE")),"Pending") -> Pending | K15: =IF(J15="Successful",TEXT(TODAY(),"YYYY-MM-DD")&" Auto","—") -> —
B16: =IF(A16="","",IFERROR(VLOOKUP(A16,DB_Customers!$A:$B,2,0),"❌ Account Not Found")) | C16: =IF(A16="","",IFERROR(VLOOKUP(A16,DB_Customers!$A:$N,14,0),"")) | D16: =IF(A16="","",TODAY()) | G16: =IFERROR(IF(OR(A16="",E16=""),"",C16-E16),"") | H16: Agent 01 | J16: =IF(AND(A16<>"",E16<>""),IF(I16="","⚠️ Enter Code",IF(IFERROR(VLOOKUP(H16,DB_Agents!$B:$E,4,0),"")=I16,IF(C16>=E16,"Successful","Unsuccessful"),"🔒 WRONG CODE")),"Pending") -> Pending | K16: =IF(J16="Successful",TEXT(TODAY(),"YYYY-MM-DD")&" Auto","—") -> —
B17: =IF(A17="","",IFERROR(VLOOKUP(A17,DB_Customers!$A:$B,2,0),"❌ Account Not Found")) | C17: =IF(A17="","",IFERROR(VLOOKUP(A17,DB_Customers!$A:$N,14,0),"")) | D17: =IF(A17="","",TODAY()) | G17: =IFERROR(IF(OR(A17="",E17=""),"",C17-E17),"") | H17: Agent 01 | J17: =IF(AND(A17<>"",E17<>""),IF(I17="","⚠️ Enter Code",IF(IFERROR(VLOOKUP(H17,DB_Agents!$B:$E,4,0),"")=I17,IF(C17>=E17,"Successful","Unsuccessful"),"🔒 WRONG CODE")),"Pending") -> Pending | K17: =IF(J17="Successful",TEXT(TODAY(),"YYYY-MM-DD")&" Auto","—") -> —
B18: =IF(A18="","",IFERROR(VLOOKUP(A18,DB_Customers!$A:$B,2,0),"❌ Account Not Found")) | C18: =IF(A18="","",IFERROR(VLOOKUP(A18,DB_Customers!$A:$N,14,0),"")) | D18: =IF(A18="","",TODAY()) | G18: =IFERROR(IF(OR(A18="",E18=""),"",C18-E18),"") | H18: Agent 01 | J18: =IF(AND(A18<>"",E18<>""),IF(I18="","⚠️ Enter Code",IF(IFERROR(VLOOKUP(H18,DB_Agents!$B:$E,4,0),"")=I18,IF(C18>=E18,"Successful","Unsuccessful"),"🔒 WRONG CODE")),"Pending") -> Pending | K18: =IF(J18="Successful",TEXT(TODAY(),"YYYY-MM-DD")&" Auto","—") -> —
B19: =IF(A19="","",IFERROR(VLOOKUP(A19,DB_Customers!$A:$B,2,0),"❌ Account Not Found")) | C19: =IF(A19="","",IFERROR(VLOOKUP(A19,DB_Customers!$A:$N,14,0),"")) | D19: =IF(A19="","",TODAY()) | G19: =IFERROR(IF(OR(A19="",E19=""),"",C19-E19),"") | H19: Agent 01 | J19: =IF(AND(A19<>"",E19<>""),IF(I19="","⚠️ Enter Code",IF(IFERROR(VLOOKUP(H19,DB_Agents!$B:$E,4,0),"")=I19,IF(C19>=E19,"Successful","Unsuccessful"),"🔒 WRONG CODE")),"Pending") -> Pending | K19: =IF(J19="Successful",TEXT(TODAY(),"YYYY-MM-DD")&" Auto","—") -> —
B20: =IF(A20="","",IFERROR(VLOOKUP(A20,DB_Customers!$A:$B,2,0),"❌ Account Not Found")) | C20: =IF(A20="","",IFERROR(VLOOKUP(A20,DB_Customers!$A:$N,14,0),"")) | D20: =IF(A20="","",TODAY()) | G20: =IFERROR(IF(OR(A20="",E20=""),"",C20-E20),"") | H20: Agent 01 | J20: =IF(AND(A20<>"",E20<>""),IF(I20="","⚠️ Enter Code",IF(IFERROR(VLOOKUP(H20,DB_Agents!$B:$E,4,0),"")=I20,IF(C20>=E20,"Successful","Unsuccessful"),"🔒 WRONG CODE")),"Pending") -> Pending | K20: =IF(J20="Successful",TEXT(TODAY(),"YYYY-MM-DD")&" Auto","—") -> —
... B208: =IF(A208="","",IFERROR(VLOOKUP(A208,DB_Customers!$A:$B,2,0),"❌ Account Not Found")) | C208: =IF(A208="","",IFERROR(VLOOKUP(A208,DB_Customers!$A:$N,14,0),"")) | D208: =IF(A208="","",TODAY()) | G208: =IFERROR(IF(OR(A208="",E208=""),"",C208-E208),"") | H208: Agent 01 | J208: =IF(AND(A208<>"",E208<>""),IF(I208="","⚠️ Enter Code",IF(IFERROR(VLOOKUP(H208,DB_Agents!$B:$E,4,0),"")=I208,IF(C208>=E208,"Successful","Unsuccessful"),"🔒 WRONG CODE")),"Pending") -> Pending | K208: =IF(J208="Successful",TEXT(TODAY(),"YYYY-MM-DD")&" Auto","—") -> —

Sheet Agent01_Loans
A1: 🏦 SAMICIOUS MICROFINANCE — AGENT01 LOAN REQUESTS
A2: Total Repayable = Loan Amount + (Loan Amount × Rate% × Months) | Status: Pending → Approved
A4: 🔢 INSTANT LOAN CALCULATOR
A5: Loan Amount (GHS):
A6: Duration (Months):
A7: Interest Rate (%/month): | B7: 2.5
A8: ━ Total Interest: | B8: =IF(B5="","",B5*B7/100*B6)
A9: ━ Total Repayable: | B9: =IF(B5="","",B5+(B5*B7/100*B6))
A10: ━ Monthly Payment: | B10: =IFERROR(B9/B6,"")
A13: Loan ID | B13: Account # | C13: Customer Name | D13: Request Date | E13: Loan Amount | F13: Purpose | G13: Months | H13: Rate % | I13: Total Repayable | J13: Monthly Install | K13: Status | L13: Agent | M13: 🔑 Agent Code | N13: Note
A14: =IF(B14="","",IF(C14="❌ Account Not Found","INVALID","LN"&TEXT(D14,"YYYYMMDD")&TEXT(ROW()-13,"0000"))) | C14: =IF(B14="","",IFERROR(VLOOKUP(B14,DB_Customers!$A:$B,2,0),"❌ Account Not Found")) | D14: =IF(B14="","",TODAY()) | H14: 2.5 | I14: =IF(E14="","",E14+(E14*H14/100*G14)) | J14: =IFERROR(I14/G14,"") | K14: =IF(B14="","Pending",IF(M14="","⚠️ Enter Code",IF(IFERROR(VLOOKUP(L14,DB_Agents!$B:$E,4,0),"")=M14,"Pending","🔒 BLOCKED"))) -> Pending | L14: Agent 01
A15: =IF(B15="","",IF(C15="❌ Account Not Found","INVALID","LN"&TEXT(D15,"YYYYMMDD")&TEXT(ROW()-13,"0000"))) | C15: =IF(B15="","",IFERROR(VLOOKUP(B15,DB_Customers!$A:$B,2,0),"❌ Account Not Found")) | D15: =IF(B15="","",TODAY()) | H15: 2.5 | I15: =IF(E15="","",E15+(E15*H15/100*G15)) | J15: =IFERROR(I15/G15,"") | K15: =IF(B15="","Pending",IF(M15="","⚠️ Enter Code",IF(IFERROR(VLOOKUP(L15,DB_Agents!$B:$E,4,0),"")=M15,"Pending","🔒 BLOCKED"))) -> Pending | L15: Agent 01
A16: =IF(B16="","",IF(C16="❌ Account Not Found","INVALID","LN"&TEXT(D16,"YYYYMMDD")&TEXT(ROW()-13,"0000"))) | C16: =IF(B16="","",IFERROR(VLOOKUP(B16,DB_Customers!$A:$B,2,0),"❌ Account Not Found")) | D16: =IF(B16="","",TODAY()) | H16: 2.5 | I16: =IF(E16="","",E16+(E16*H16/100*G16)) | J16: =IFERROR(I16/G16,"") | K16: =IF(B16="","Pending",IF(M16="","⚠️ Enter Code",IF(IFERROR(VLOOKUP(L16,DB_Agents!$B:$E,4,0),"")=M16,"Pending","🔒 BLOCKED"))) -> Pending | L16: Agent 01
A17: =IF(B17="","",IF(C17="❌ Account Not Found","INVALID","LN"&TEXT(D17,"YYYYMMDD")&TEXT(ROW()-13,"0000"))) | C17: =IF(B17="","",IFERROR(VLOOKUP(B17,DB_Customers!$A:$B,2,0),"❌ Account Not Found")) | D17: =IF(B17="","",TODAY()) | H17: 2.5 | I17: =IF(E17="","",E17+(E17*H17/100*G17)) | J17: =IFERROR(I17/G17,"") | K17: =IF(B17="","Pending",IF(M17="","⚠️ Enter Code",IF(IFERROR(VLOOKUP(L17,DB_Agents!$B:$E,4,0),"")=M17,"Pending","🔒 BLOCKED"))) -> Pending | L17: Agent 01
A18: =IF(B18="","",IF(C18="❌ Account Not Found","INVALID","LN"&TEXT(D18,"YYYYMMDD")&TEXT(ROW()-13,"0000"))) | C18: =IF(B18="","",IFERROR(VLOOKUP(B18,DB_Customers!$A:$B,2,0),"❌ Account Not Found")) | D18: =IF(B18="","",TODAY()) | H18: 2.5 | I18: =IF(E18="","",E18+(E18*H18/100*G18)) | J18: =IFERROR(I18/G18,"") | K18: =IF(B18="","Pending",IF(M18="","⚠️ Enter Code",IF(IFERROR(VLOOKUP(L18,DB_Agents!$B:$E,4,0),"")=M18,"Pending","🔒 BLOCKED"))) -> Pending | L18: Agent 01
A19: =IF(B19="","",IF(C19="❌ Account Not Found","INVALID","LN"&TEXT(D19,"YYYYMMDD")&TEXT(ROW()-13,"0000"))) | C19: =IF(B19="","",IFERROR(VLOOKUP(B19,DB_Customers!$A:$B,2,0),"❌ Account Not Found")) | D19: =IF(B19="","",TODAY()) | H19: 2.5 | I19: =IF(E19="","",E19+(E19*H19/100*G19)) | J19: =IFERROR(I19/G19,"") | K19: =IF(B19="","Pending",IF(M19="","⚠️ Enter Code",IF(IFERROR(VLOOKUP(L19,DB_Agents!$B:$E,4,0),"")=M19,"Pending","🔒 BLOCKED"))) -> Pending | L19: Agent 01
A20: =IF(B20="","",IF(C20="❌ Account Not Found","INVALID","LN"&TEXT(D20,"YYYYMMDD")&TEXT(ROW()-13,"0000"))) | C20: =IF(B20="","",IFERROR(VLOOKUP(B20,DB_Customers!$A:$B,2,0),"❌ Account Not Found")) | D20: =IF(B20="","",TODAY()) | H20: 2.5 | I20: =IF(E20="","",E20+(E20*H20/100*G20)) | J20: =IFERROR(I20/G20,"") | K20: =IF(B20="","Pending",IF(M20="","⚠️ Enter Code",IF(IFERROR(VLOOKUP(L20,DB_Agents!$B:$E,4,0),"")=M20,"Pending","🔒 BLOCKED"))) -> Pending | L20: Agent 01
A21: =IF(B21="","",IF(C21="❌ Account Not Found","INVALID","LN"&TEXT(D21,"YYYYMMDD")&TEXT(ROW()-13,"0000"))) | C21: =IF(B21="","",IFERROR(VLOOKUP(B21,DB_Customers!$A:$B,2,0),"❌ Account Not Found")) | D21: =IF(B21="","",TODAY()) | H21: 2.5 | I21: =IF(E21="","",E21+(E21*H21/100*G21)) | J21: =IFERROR(I21/G21,"") | K21: =IF(B21="","Pending",IF(M21="","⚠️ Enter Code",IF(IFERROR(VLOOKUP(L21,DB_Agents!$B:$E,4,0),"")=M21,"Pending","🔒 BLOCKED"))) -> Pending | L21: Agent 01
A22: =IF(B22="","",IF(C22="❌ Account Not Found","INVALID","LN"&TEXT(D22,"YYYYMMDD")&TEXT(ROW()-13,"0000"))) | C22: =IF(B22="","",IFERROR(VLOOKUP(B22,DB_Customers!$A:$B,2,0),"❌ Account Not Found")) | D22: =IF(B22="","",TODAY()) | H22: 2.5 | I22: =IF(E22="","",E22+(E22*H22/100*G22)) | J22: =IFERROR(I22/G22,"") | K22: =IF(B22="","Pending",IF(M22="","⚠️ Enter Code",IF(IFERROR(VLOOKUP(L22,DB_Agents!$B:$E,4,0),"")=M22,"Pending","🔒 BLOCKED"))) -> Pending | L22: Agent 01
A23: =IF(B23="","",IF(C23="❌ Account Not Found","INVALID","LN"&TEXT(D23,"YYYYMMDD")&TEXT(ROW()-13,"0000"))) | C23: =IF(B23="","",IFERROR(VLOOKUP(B23,DB_Customers!$A:$B,2,0),"❌ Account Not Found")) | D23: =IF(B23="","",TODAY()) | H23: 2.5 | I23: =IF(E23="","",E23+(E23*H23/100*G23)) | J23: =IFERROR(I23/G23,"") | K23: =IF(B23="","Pending",IF(M23="","⚠️ Enter Code",IF(IFERROR(VLOOKUP(L23,DB_Agents!$B:$E,4,0),"")=M23,"Pending","🔒 BLOCKED"))) -> Pending | L23: Agent 01
A24: =IF(B24="","",IF(C24="❌ Account Not Found","INVALID","LN"&TEXT(D24,"YYYYMMDD")&TEXT(ROW()-13,"0000"))) | C24: =IF(B24="","",IFERROR(VLOOKUP(B24,DB_Customers!$A:$B,2,0),"❌ Account Not Found")) | D24: =IF(B24="","",TODAY()) | H24: 2.5 | I24: =IF(E24="","",E24+(E24*H24/100*G24)) | J24: =IFERROR(I24/G24,"") | K24: =IF(B24="","Pending",IF(M24="","⚠️ Enter Code",IF(IFERROR(VLOOKUP(L24,DB_Agents!$B:$E,4,0),"")=M24,"Pending","🔒 BLOCKED"))) -> Pending | L24: Agent 01
A25: =IF(B25="","",IF(C25="❌ Account Not Found","INVALID","LN"&TEXT(D25,"YYYYMMDD")&TEXT(ROW()-13,"0000"))) | C25: =IF(B25="","",IFERROR(VLOOKUP(B25,DB_Customers!$A:$B,2,0),"❌ Account Not Found")) | D25: =IF(B25="","",TODAY()) | H25: 2.5 | I25: =IF(E25="","",E25+(E25*H25/100*G25)) | J25: =IFERROR(I25/G25,"") | K25: =IF(B25="","Pending",IF(M25="","⚠️ Enter Code",IF(IFERROR(VLOOKUP(L25,DB_Agents!$B:$E,4,0),"")=M25,"Pending","🔒 BLOCKED"))) -> Pending | L25: Agent 01
... A213: =IF(B213="","",IF(C213="❌ Account Not Found","INVALID","LN"&TEXT(D213,"YYYYMMDD")&TEXT(ROW()-13,"0000"))) | C213: =IF(B213="","",IFERROR(VLOOKUP(B213,DB_Customers!$A:$B,2,0),"❌ Account Not Found")) | D213: =IF(B213="","",TODAY()) | H213: 2.5 | I213: =IF(E213="","",E213+(E213*H213/100*G213)) | J213: =IFERROR(I213/G213,"") | K213: =IF(B213="","Pending",IF(M213="","⚠️ Enter Code",IF(IFERROR(VLOOKUP(L213,DB_Agents!$B:$E,4,0),"")=M213,"Pending","🔒 BLOCKED"))) -> Pending | L213: Agent 01

Sheet Agent02_Savings
A1: 💰 SAMICIOUS MICROFINANCE — AGENT02 SAVINGS
A2: Agent: Agent 02 | Enter Account # → All fields auto-populate | Status auto-sets to "Saved" | 🔑 Enter your 4-digit code to validate
A3: 💰 Total Collected Today | D3: 📊 Transactions Today | G3: 📅 Date
A4: =IFERROR(SUMIFS(DB_Savings!$F:$F,DB_Savings!$G:$G,"Agent 02",DB_Savings!$D:$D,TODAY()),0) -> 0 | D4: =IFERROR(COUNTIFS(DB_Savings!$G:$G,"Agent 02",DB_Savings!$D:$D,TODAY()),0) -> 0 | G4: =TEXT(TODAY(),"DDDD, DD MMMM YYYY") -> Saturday, 25 April 2026
A7: 📝 ENTRY FORM — Enter Account Number in column A. All other fields auto-populate. Enter Savings Amount in col E, then your 4-digit Agent Code in col H.
A8: Account # | B8: Customer Name | C8: Current Balance | D8: Date | E8: Savings Amount | F8: New Balance | G8: Agent | H8: 🔑 Agent Code | I8: Status | J8: Saved At | K8: Notes
B9: =IF(A9="","",IFERROR(VLOOKUP(A9,DB_Customers!$A:$B,2,0),"❌ Account Not Found")) | C9: =IF(A9="","",IFERROR(VLOOKUP(A9,DB_Customers!$A:$M,13,0),"")) | D9: =IF(A9="","",TODAY()) | F9: =IFERROR(IF(OR(A9="",E9=""),"",C9+E9),"") | G9: Agent 02 | I9: =IF(A9="","Pending",IF(H9="","⚠️ Enter Agent Code",IF(IFERROR(VLOOKUP(G9,DB_Agents!$B:$E,4,0),"")=H9,IF(AND(A9<>"",E9<>""),"✅ Saved","Pending"),"🔒 WRONG CODE"))) -> Pending | J9: =IF(I9="✅ Saved",TEXT(TODAY(),"YYYY-MM-DD")&" Auto","—") -> —
B10: =IF(A10="","",IFERROR(VLOOKUP(A10,DB_Customers!$A:$B,2,0),"❌ Account Not Found")) | C10: =IF(A10="","",IFERROR(VLOOKUP(A10,DB_Customers!$A:$M,13,0),"")) | D10: =IF(A10="","",TODAY()) | F10: =IFERROR(IF(OR(A10="",E10=""),"",C10+E10),"") | G10: Agent 02 | I10: =IF(A10="","Pending",IF(H10="","⚠️ Enter Agent Code",IF(IFERROR(VLOOKUP(G10,DB_Agents!$B:$E,4,0),"")=H10,IF(AND(A10<>"",E10<>""),"✅ Saved","Pending"),"🔒 WRONG CODE"))) -> Pending | J10: =IF(I10="✅ Saved",TEXT(TODAY(),"YYYY-MM-DD")&" Auto","—") -> —
B11: =IF(A11="","",IFERROR(VLOOKUP(A11,DB_Customers!$A:$B,2,0),"❌ Account Not Found")) | C11: =IF(A11="","",IFERROR(VLOOKUP(A11,DB_Customers!$A:$M,13,0),"")) | D11: =IF(A11="","",TODAY()) | F11: =IFERROR(IF(OR(A11="",E11=""),"",C11+E11),"") | G11: Agent 02 | I11: =IF(A11="","Pending",IF(H11="","⚠️ Enter Agent Code",IF(IFERROR(VLOOKUP(G11,DB_Agents!$B:$E,4,0),"")=H11,IF(AND(A11<>"",E11<>""),"✅ Saved","Pending"),"🔒 WRONG CODE"))) -> Pending | J11: =IF(I11="✅ Saved",TEXT(TODAY(),"YYYY-MM-DD")&" Auto","—") -> —
B12: =IF(A12="","",IFERROR(VLOOKUP(A12,DB_Customers!$A:$B,2,0),"❌ Account Not Found")) | C12: =IF(A12="","",IFERROR(VLOOKUP(A12,DB_Customers!$A:$M,13,0),"")) | D12: =IF(A12="","",TODAY()) | F12: =IFERROR(IF(OR(A12="",E12=""),"",C12+E12),"") | G12: Agent 02 | I12: =IF(A12="","Pending",IF(H12="","⚠️ Enter Agent Code",IF(IFERROR(VLOOKUP(G12,DB_Agents!$B:$E,4,0),"")=H12,IF(AND(A12<>"",E12<>""),"✅ Saved","Pending"),"🔒 WRONG CODE"))) -> Pending | J12: =IF(I12="✅ Saved",TEXT(TODAY(),"YYYY-MM-DD")&" Auto","—") -> —
B13: =IF(A13="","",IFERROR(VLOOKUP(A13,DB_Customers!$A:$B,2,0),"❌ Account Not Found")) | C13: =IF(A13="","",IFERROR(VLOOKUP(A13,DB_Customers!$A:$M,13,0),"")) | D13: =IF(A13="","",TODAY()) | F13: =IFERROR(IF(OR(A13="",E13=""),"",C13+E13),"") | G13: Agent 02 | I13: =IF(A13="","Pending",IF(H13="","⚠️ Enter Agent Code",IF(IFERROR(VLOOKUP(G13,DB_Agents!$B:$E,4,0),"")=H13,IF(AND(A13<>"",E13<>""),"✅ Saved","Pending"),"🔒 WRONG CODE"))) -> Pending | J13: =IF(I13="✅ Saved",TEXT(TODAY(),"YYYY-MM-DD")&" Auto","—") -> —
